File: Chain/Curve fitting/Data/AllSingleLoad.csv
POSN mm ,LOAD kn,STRAIN1 mm,STRESS(MPA),TIME(sec)
-54.192443,-0.000936,-0.001998,-0.011915,0
-54.192643,-0.004953,-0.002055,-0.063065,0.14
-54.19589,-0.008368,-0.002815,-0.106551,0.28
-54.19678,-0.008065,-0.003797,-0.102681,0.42
-54.199619,-0.006688,-0.004766,-0.08515,0.56
-54.198761,-0.000566,-0.005295,-0.00721,0.7
-54.200859,0.000429,-0.006153,0.005464,0.84
-54.202444,0.000811,-0.007695,0.010321,0.98
-54.203066,-0.001425,-0.00998,-0.018138,1.12
-54.20407,-0.002557,-0.011092,-0.032557,1.26
-54.20729,-0.006741,-0.012268,-0.085833,1.4
-54.206891,-0.008404,-0.013713,-0.107006,1.54
-54.209757,-0.007117,-0.015978,-0.090614,1.68
-54.210356,-0.002956,-0.01704,-0.037642,1.82
-54.211664,-0.000155,-0.018923,-0.001973,1.96
-54.213118,-0.003088,-0.019676,-0.039312,2.1
-54.214276,-0.004733,-0.021266,-0.060257,2.24
-54.215357,-0.0081,-0.022966,-0.103136,2.38
-54.216433,-0.014746,-0.024163,-0.187754,2.52
-54.221902,-0.018042,-0.025694,-0.229722,2.66
-54.221275,-0.019079,-0.026701,-0.242927,2.8
-54.222596,-0.021064,-0.028266,-0.268199,2.94
-54.223182,-0.021434,-0.029688,-0.272904,3.08
-54.222583,-0.02259,-0.031014,-0.287627,3.22
-54.224599,-0.026852,-0.031716,-0.341889,3.36
-54.227402,-0.038916,-0.033322,-0.495492,3.5
-54.227733,-0.048834,-0.035287,-0.621775,3.64
-54.230104,-0.044245,-0.035896,-0.563339,3.78
-54.23223,-0.050825,-0.037699,-0.647122,3.92
-54.231866,-0.047123,-0.038835,-0.599994,4.06
-54.232157,-0.051671,-0.040434,-0.657899,4.2
-54.235023,-0.057715,-0.041308,-0.734852,4.34
-54.235913,-0.070459,-0.042915,-0.897107,4.48
-54.237476,-0.080943,-0.044583,-1.0306,4.62
-54.240823,-0.094557,-0.045851,-1.203935,4.76
-54.240723,-0.100476,-0.047079,-1.279294,4.9
-54.243244,-0.103521,-0.048434,-1.318075,5.04
-54.245238,-0.118637,-0.049983,-1.510534,5.18
-54.245878,-0.127918,-0.051231,-1.628697,5.32
-54.246173,-0.147235,-0.053191,-1.874659,5.46
-54.247118,-0.157607,-0.054127,-2.00671,5.6
-54.249789,-0.177866,-0.055607,-2.264663,5.74
-54.252264,-0.184262,-0.05637,-2.346094,5.88
-54.252741,-0.20842,-0.058,-2.65368,6.02
-54.253168,-0.215673,-0.058988,-2.74604,6.16
-54.254535,-0.234163,-0.060676,-2.981453,6.3
-54.256483,-0.24814,-0.06153,-3.159418,6.44
-54.257887,-0.272208,-0.063104,-3.465866,6.58
-54.257814,-0.284433,-0.064314,-3.621518,6.72
-54.259586,-0.313497,-0.065583,-3.991563,6.86
-54.263451,-0.328577,-0.066877,-4.183567,7
-54.264945,-0.349784,-0.06809,-4.453587,7.14
-54.266389,-0.368243,-0.069423,-4.688621,7.28
-54.264037,-0.38113,-0.070375,-4.852698,7.42
-54.268079,-0.397158,-0.071539,-5.056768,7.56
-54.267275,-0.429529,-0.073057,-5.468932,7.7
-54.270136,-0.45532,-0.074383,-5.797313,7.84
-54.271099,-0.476027,-0.07557,-6.060958,7.98
-54.272984,-0.49988,-0.076731,-6.364674,8.12
-54.274719,-0.517839,-0.077978,-6.593333,8.26
-54.275932,-0.535488,-0.079036,-6.818047,8.4
-54.277004,-0.556535,-0.080523,-7.086018,8.54
-54.278203,-0.573939,-0.08124,-7.307619,8.68
-54.280946,-0.608647,-0.082981,-7.749533,8.82
-54.282259,-0.633121,-0.083978,-8.061141,8.96
-54.283671,-0.654584,-0.085185,-8.334424,9.1
-54.285547,-0.685215,-0.086729,-8.724428,9.24
-54.285815,-0.70675,-0.087951,-8.998622,9.38
-54.287713,-0.725549,-0.088926,-9.237983,9.52
-54.2869,-0.748622,-0.089997,-9.531757,9.66
-54.290202,-0.790119,-0.092037,-10.06011,9.8
-54.291592,-0.820774,-0.093227,-10.450417,9.94
-54.293886,-0.835782,-0.094441,-10.641511,10.08
-54.294949,-0.867176,-0.09555,-11.041228,10.22
-54.295948,-0.879496,-0.096607,-11.198095,10.36
-54.298119,-0.903171,-0.097667,-11.499534,10.5
-54.297229,-0.924128,-0.098789,-11.766367,10.64
-54.300385,-0.956142,-0.100283,-12.173977,10.78
-54.300199,-0.989825,-0.101317,-12.602837,10.92
-54.30475,-1.012629,-0.102739,-12.893196,11.06
-54.303474,-1.036227,-0.103756,-13.193649,11.2
-54.302951,-1.04534,-0.104732,-13.309686,11.34
-54.305032,-1.081461,-0.106127,-13.769585,11.48
-54.308306,-1.121414,-0.107723,-14.278283,11.62
-54.310486,-1.153064,-0.109252,-14.681264,11.76
-54.312167,-1.176906,-0.110124,-14.984828,11.9
-54.314842,-1.212806,-0.111668,-15.441919,12.04
-54.313339,-1.224673,-0.112639,-15.593018,12.18
-54.315042,-1.251954,-0.113806,-15.940371,12.32
-54.316981,-1.268417,-0.114511,-16.149982,12.46
-54.316741,-1.304132,-0.115972,-16.604721,12.6
-54.317272,-1.324916,-0.116893,-16.869353,12.74
-54.321555,-1.353389,-0.118232,-17.231884,12.88
-54.324067,-1.383638,-0.119824,-17.617031,13.02
-54.323649,-1.414412,-0.120998,-18.008856,13.16
-54.324389,-1.442069,-0.122299,-18.36099,13.3
-54.325298,-1.465529,-0.123269,-18.659697,13.44
-54.328949,-1.49644,-0.124628,-19.053268,13.58
-54.330562,-1.532668,-0.125858,-19.514533,13.72
-54.332015,-1.544189,-0.126971,-19.661231,13.86
-54.331788,-1.576078,-0.127956,-20.067248,14
-54.335385,-1.594293,-0.12917,-20.29917,14.14
-54.333468,-1.626045,-0.130271,-20.703442,14.28
-54.335399,-1.646787,-0.131445,-20.967542,14.42
-54.337552,-1.690543,-0.133007,-21.524658,14.56
-54.338737,-1.719415,-0.133999,-21.892274,14.7
-54.342679,-1.738942,-0.135366,-22.140893,14.84
-54.341471,-1.764095,-0.136703,-22.461153,14.98
-54.343461,-1.7941,-0.138121,-22.843188,15.12
-54.344037,-1.814508,-0.138866,-23.103039,15.26
-54.345622,-1.852214,-0.140514,-23.583125,15.4
-54.347503,-1.88514,-0.141741,-24.002347,15.54
-54.348566,-1.910764,-0.142604,-24.328603,15.68
-54.351527,-1.936096,-0.144147,-24.651139,15.82
-54.352422,-1.96346,-0.145143,-24.999555,15.96
-54.354134,-1.980126,-0.146267,-25.211746,16.1
-54.353425,-2.006382,-0.1473,-25.546046,16.24
-54.354992,-2.036202,-0.148574,-25.925728,16.38
-54.356882,-2.067858,-0.149856,-26.328786,16.52
-54.35868,-2.09502,-0.150836,-26.674621,16.66
-54.3624,-2.123696,-0.152306,-27.039732,16.8
-54.361369,-2.129692,-0.152885,-27.116079,16.94
-54.362727,-2.159488,-0.15419,-27.495458,17.08
-54.363299,-2.192599,-0.155912,-27.917032,17.22
-54.364576,-2.227527,-0.156926,-28.361753,17.36
-54.36642,-2.252579,-0.158431,-28.680723,17.5
-54.369377,-2.294546,-0.16006,-29.215072,17.64
-54.370639,-2.308404,-0.160604,-29.391518,17.78
-54.372715,-2.33562,-0.162262,-29.738037,17.92
-54.372347,-2.380592,-0.163446,-30.310634,18.06
-54.372688,-2.38173,-0.164423,-30.325129,18.2
-54.374877,-2.426773,-0.165864,-30.898637,18.34
-54.377933,-2.442104,-0.166752,-31.093829,18.48
-54.379273,-2.47367,-0.168041,-31.495748,18.62
-54.38055,-2.500939,-0.169138,-31.842949,18.76
-54.380386,-2.492243,-0.170099,-31.732224,18.9
-54.379069,-2.484292,-0.17015,-31.630986,19.04
-54.378656,-2.483076,-0.170225,-31.615504,19.18
-54.380627,-2.479827,-0.170242,-31.574143,19.32
-54.381917,-2.474022,-0.17028,-31.500225,19.46
-54.38089,-2.45927,-0.170148,-31.312395,19.6
-54.379941,-2.451861,-0.170061,-31.218063,19.74
-54.378914,-2.456868,-0.170247,-31.281811,19.88
-54.378301,-2.452528,-0.170128,-31.226562,20.02
-54.378633,-2.461064,-0.170287,-31.335238,20.16
-54.380972,-2.459133,-0.170146,-31.31065,20.3
-54.379459,-2.457988,-0.170279,-31.296079,20.44
-54.378755,-2.441579,-0.17018,-31.087151,20.58
-54.378447,-2.445608,-0.170123,-31.138453,20.72
-54.37901,-2.446979,-0.170151,-31.155908,20.86
-54.380204,-2.455592,-0.170285,-31.26557,21
-54.378996,-2.453941,-0.170425,-31.244549,21.14
-54.380336,-2.455634,-0.170379,-31.266102,21.28
-54.379991,-2.447879,-0.170232,-31.167367,21.42
-54.378029,-2.439195,-0.170204,-31.056794,21.56
-54.378746,-2.440578,-0.170308,-31.074401,21.7
-54.38005,-2.444941,-0.170264,-31.129953,21.84
-54.381031,-2.449918,-0.170425,-31.193322,21.98
-54.379319,-2.44354,-0.17037,-31.112119,22.12
-54.380436,-2.43808,-0.170288,-31.042603,22.26
-54.379023,-2.43879,-0.170422,-31.051634,22.4
-54.37866,-2.444416,-0.170317,-31.123275,22.54
-54.378533,-2.44742,-0.170486,-31.161524,22.68
-54.380722,-2.45263,-0.170462,-31.227853,22.82
-54.380954,-2.444935,-0.17048,-31.129877,22.96
-54.379823,-2.438426,-0.170379,-31.047004,23.1
-54.378442,-2.437091,-0.170451,-31.030005,23.24
-54.377352,-2.467471,-0.171823,-31.416821,0.07
-54.378061,-2.437621,-0.171623,-31.036759,0.21
-54.375354,-2.377164,-0.170958,-30.266997,0.35
-54.373351,-2.323586,-0.170657,-29.584813,0.49
-54.374968,-2.288204,-0.170232,-29.134324,0.63
-54.369744,-2.237976,-0.169633,-28.49479,0.77
-54.369263,-2.203971,-0.169355,-28.061832,0.91
-54.369145,-2.148968,-0.168744,-27.36151,1.05
-54.366152,-2.08059,-0.168045,-26.490889,1.19
-54.366897,-2.010858,-0.167408,-25.60304,1.33
-54.366833,-1.933056,-0.166619,-24.612435,1.47
-54.361528,-1.823986,-0.16546,-23.223706,1.61
-54.361733,-1.72022,-0.164211,-21.902519,1.75
-54.361024,-1.672834,-0.163531,-21.299186,1.89
-54.357668,-1.562947,-0.162273,-19.90006,2.03
-54.358494,-1.507109,-0.161754,-19.189113,2.17
-54.356073,-1.421863,-0.160681,-18.10372,2.31
-54.354266,-1.33673,-0.15965,-17.019769,2.45
-54.353312,-1.272744,-0.158769,-16.205079,2.59
-54.350391,-1.194239,-0.157883,-15.205519,2.73
-54.35095,-1.128733,-0.156897,-14.371477,2.87
-54.348425,-1.05533,-0.155881,-13.436879,3.01
-54.346962,-0.968099,-0.154746,-12.326215,3.15
-54.347335,-0.915289,-0.153961,-11.653821,3.29
-54.344205,-0.839114,-0.15284,-10.683934,3.43
-54.344469,-0.77762,-0.151845,-9.900966,3.57
-54.341744,-0.713116,-0.150768,-9.079674,3.71
-54.34009,-0.650656,-0.149828,-8.284412,3.85
-54.340604,-0.59346,-0.148758,-7.556162,3.99
-54.337038,-0.524265,-0.147588,-6.675144,4.13
-54.336475,-0.479996,-0.146689,-6.111501,4.27
-54.334922,-0.428343,-0.145641,-5.45383,4.41
-54.335026,-0.378376,-0.144725,-4.817636,4.55
-54.332533,-0.346613,-0.143703,-4.413213,4.69
-54.330539,-0.288332,-0.142406,-3.671151,4.83
-54.328418,-0.243759,-0.141192,-3.103638,4.97
-54.329322,-0.226784,-0.14044,-2.8875,5.11
-54.325561,-0.175858,-0.138948,-2.239088,5.25
-54.326011,-0.152892,-0.138148,-1.94668,5.39
-54.325352,-0.133854,-0.137135,-1.704284,5.53
-54.322572,-0.102097,-0.135786,-1.299937,5.67
-54.320161,-0.086081,-0.134296,-1.096018,5.81
-54.32047,-0.0606,-0.132938,-0.771584,5.95
-54.317822,-0.038338,-0.13143,-0.488131,6.09
-54.31982,-0.035793,-0.130441,-0.455725,6.23
-54.315246,-0.011027,-0.128705,-0.140398,6.37
-54.315242,-0.009376,-0.127521,-0.119377,6.51
-54.313834,-0.007129,-0.127003,-0.090766,6.65
-54.313861,-0.004232,-0.127156,-0.053883,6.79
-54.314124,-0.012767,-0.127168,-0.162559,6.93
-54.314779,-0.005352,-0.127097,-0.06815,7.07
-54.314193,-0.006914,-0.127116,-0.088034,7.21
-54.315187,-0.009483,-0.127186,-0.120743,7.35
-54.31362,-0.003123,-0.127213,-0.039767,7.49
-54.314379,-0.015372,-0.127342,-0.195723,7.63
-54.31457,-0.002837,-0.126997,-0.036124,7.77
-54.314733,-0.010157,-0.127229,-0.129318,7.91
-54.314919,-0.009567,-0.127145,-0.121805,8.05
-54.200005,-0.067073,-0.004088,-0.854001,0.08
-54.203416,-0.07841,-0.005618,-0.998346,0.22
-54.201277,-0.082004,-0.00684,-1.044108,0.36
-54.20511,-0.096285,-0.008087,-1.225943,0.5
-54.205528,-0.09973,-0.00942,-1.269808,0.64
-54.207645,-0.110644,-0.010567,-1.408764,0.78
-54.211133,-0.130969,-0.012486,-1.667553,0.92
-54.209071,-0.138468,-0.013867,-1.763024,1.06
-54.212473,-0.165778,-0.015103,-2.110756,1.2
-54.212804,-0.165546,-0.016234,-2.107796,1.34
-54.212745,-0.192016,-0.017772,-2.444828,1.48
-54.216165,-0.205481,-0.01929,-2.616266,1.62
-54.215702,-0.221413,-0.020357,-2.819123,1.76
-54.219199,-0.243258,-0.021682,-3.097263,1.9
-54.219999,-0.251418,-0.022681,-3.201158,2.04
-54.221238,-0.288725,-0.024607,-3.67616,2.18
-54.223173,-0.286084,-0.025196,-3.64254,2.32
-54.223491,-0.318652,-0.026838,-4.057208,2.46
-54.224831,-0.327057,-0.027599,-4.164215,2.6
-54.225789,-0.350994,-0.028922,-4.468993,2.74
-54.229014,-0.378597,-0.030483,-4.820444,2.88
-54.229732,-0.3874,-0.031293,-4.932535,3.02
-54.231812,-0.421393,-0.032784,-5.365341,3.16
-54.230763,-0.433105,-0.033912,-5.514467,3.3
-54.234801,-0.469071,-0.035538,-5.972393,3.44
-54.237021,-0.494462,-0.036726,-6.295689,3.58
-54.236622,-0.515485,-0.037881,-6.563356,3.72
-54.238479,-0.534672,-0.038884,-6.80765,3.86
-54.238934,-0.547385,-0.040025,-6.969525,4
-54.242504,-0.581843,-0.041422,-7.408251,4.14
-54.242985,-0.600421,-0.042507,-7.644803,4.28
-54.24224,-0.623858,-0.043593,-7.943206,4.42
-54.245265,-0.652319,-0.045022,-8.305586,4.56
-54.24487,-0.676763,-0.046381,-8.616815,4.7
-54.248126,-0.708079,-0.047512,-9.015546,4.84
-54.248067,-0.726014,-0.048815,-9.243902,4.98
-54.252278,-0.756592,-0.049874,-9.633223,5.12
-54.251419,-0.779629,-0.051173,-9.926542,5.26
-54.253686,-0.807327,-0.052506,-10.279207,5.4
-54.257487,-0.82798,-0.05339,-10.542169,5.54
-54.255039,-0.853324,-0.054743,-10.864858,5.68
-54.257919,-0.878322,-0.055596,-11.183145,5.82
-54.257592,-0.895768,-0.056634,-11.405278,5.96
-54.260108,-0.931972,-0.058209,-11.866239,6.1
-54.261321,-0.960934,-0.059368,-12.234994,6.24
-54.262956,-0.990224,-0.060854,-12.607922,6.38
-54.265445,-1.016235,-0.061885,-12.93911,6.52
-54.265717,-1.033026,-0.062965,-13.152895,6.66
-54.268265,-1.078737,-0.064542,-13.734903,6.8
-54.27005,-1.093996,-0.065445,-13.929184,6.94
-54.269868,-1.129156,-0.066792,-14.376865,7.08
-54.271617,-1.151431,-0.067912,-14.66047,7.22
-54.27293,-1.185596,-0.06945,-15.095477,7.36
-54.274333,-1.210058,-0.070422,-15.406934,7.5
-54.273902,-1.238233,-0.071829,-15.76567,7.64
-54.278448,-1.276213,-0.073032,-16.249248,7.78
-54.279134,-1.28569,-0.073845,-16.369914,7.92
-54.280351,-1.323563,-0.075208,-16.852126,8.06
-54.281859,-1.336676,-0.076006,-17.019086,8.2
-54.282963,-1.366526,-0.077317,-17.399148,8.34
-54.283335,-1.397473,-0.078408,-17.793174,8.48
-54.284507,-1.414752,-0.079497,-18.013182,8.62
-54.288268,-1.457942,-0.081001,-18.563088,8.76
-54.287768,-1.487094,-0.082272,-18.934271,8.9
-54.289707,-1.518726,-0.083673,-19.337024,9.04
-54.289403,-1.532847,-0.084724,-19.51681,9.18
-54.291588,-1.573956,-0.086092,-20.04023,9.32
-54.295139,-1.589334,-0.086881,-20.236029,9.46
-54.293741,-1.62273,-0.088374,-20.661246,9.6
-54.298619,-1.670009,-0.089743,-21.263214,9.74
-54.298201,-1.679581,-0.09078,-21.385095,9.88
-54.301167,-1.718014,-0.092019,-21.87444,10.02
-54.301176,-1.731122,-0.092827,-22.041324,10.16
-54.302743,-1.758116,-0.094227,-22.385034,10.3
-54.305445,-1.796991,-0.095405,-22.879995,10.44
-54.304046,-1.823163,-0.096495,-23.213233,10.58
-54.306966,-1.842493,-0.097584,-23.459347,10.72
-54.307693,-1.874083,-0.099122,-23.861569,10.86
-54.311499,-1.91164,-0.100182,-24.339759,11
-54.310459,-1.944274,-0.101708,-24.755262,11.14
-54.312521,-1.974767,-0.10265,-25.14352,11.28
-54.311844,-1.979762,-0.103488,-25.207117,11.42
-54.316196,-2.020282,-0.104988,-25.723024,11.56
-54.31581,-2.045852,-0.106256,-26.048596,11.7
-54.317976,-2.073699,-0.107235,-26.403159,11.84
-54.320579,-2.101302,-0.10836,-26.75461,11.98
-54.321028,-2.125007,-0.109422,-27.056428,12.12
-54.322886,-2.16046,-0.110677,-27.507828,12.26
-54.322105,-2.180535,-0.11191,-27.763429,12.4
-54.326969,-2.22283,-0.113185,-28.301951,12.54
-54.326115,-2.244568,-0.114245,-28.578726,12.68
-54.328672,-2.274132,-0.115388,-28.955145,12.82
-54.329422,-2.302808,-0.116647,-29.320257,12.96
-54.329272,-2.325314,-0.117949,-29.606821,13.1
-54.332129,-2.350187,-0.118993,-29.923514,13.24
-54.333309,-2.389574,-0.120242,-30.425002,13.38
-54.336262,-2.401853,-0.121199,-30.581337,13.52
-54.336303,-2.440768,-0.122467,-31.076829,13.66
-54.336829,-2.460814,-0.123694,-31.332051,13.8
-54.338019,-2.489376,-0.12498,-31.695721,13.94
-54.340322,-2.527034,-0.126112,-32.1752,14.08
-54.340735,-2.563423,-0.127638,-32.638514,14.22
-54.342811,-2.583641,-0.128786,-32.895937,14.36
-54.345359,-2.600628,-0.129578,-33.112226,14.5
-54.346313,-2.64228,-0.1309,-33.642552,14.64
-54.348702,-2.661645,-0.132224,-33.889122,14.78
-54.348938,-2.678901,-0.13331,-34.108826,14.92
-54.351,-2.720398,-0.134778,-34.637179,15.06
-54.350868,-2.759105,-0.135975,-35.130016,15.2
-54.352917,-2.770156,-0.137082,-35.270717,15.34
-54.353607,-2.808422,-0.138099,-35.757938,15.48
-54.356882,-2.819294,-0.139137,-35.896363,15.62
-54.357341,-2.845442,-0.140394,-36.229297,15.76
-54.359362,-2.879274,-0.141537,-36.660054,15.9
-54.357976,-2.896661,-0.142535,-36.881428,16.04
-54.360311,-2.929825,-0.143888,-37.303685,16.18
-54.361846,-2.948225,-0.1447,-37.537961,16.32
-54.363272,-2.984011,-0.146164,-37.99361,16.46
-54.365875,-3.019542,-0.147467,-38.445996,16.6
-54.365039,-3.042608,-0.148533,-38.739695,16.74
-54.370008,-3.086507,-0.150043,-39.298632,16.88
-54.369753,-3.104794,-0.151536,-39.531465,17.02
-54.37128,-3.131878,-0.152601,-39.876314,17.16
-54.370816,-3.150576,-0.15356,-40.114384,17.3
-54.374813,-3.175777,-0.154862,-40.435251,17.44
-54.375027,-3.205884,-0.156092,-40.818577,17.58
-54.378329,-3.237092,-0.157463,-41.215942,17.72
-54.377157,-3.259283,-0.158642,-41.498484,17.86
-54.380059,-3.294271,-0.159795,-41.943964,18
-54.380536,-3.2978,-0.160473,-41.988891,18.14
-54.380627,-3.3324,-0.161681,-42.429439,18.28
-54.384288,-3.360701,-0.16303,-42.789769,18.42
-54.383788,-3.393298,-0.164332,-43.204817,18.56
-54.386945,-3.417856,-0.165461,-43.517488,18.7
-54.38629,-3.433132,-0.166889,-43.711996,18.84
-54.389506,-3.464729,-0.167834,-44.114295,18.98
-54.390505,-3.487974,-0.169121,-44.410269,19.12
-54.393131,-3.528601,-0.170668,-44.927542,19.26
-54.393049,-3.55196,-0.171575,-45.224959,19.4
-54.394157,-3.581393,-0.17281,-45.599709,19.54
-54.397781,-3.604054,-0.174052,-45.888246,19.68
-54.396564,-3.616118,-0.175021,-46.04185,19.82
-54.39904,-3.65265,-0.176422,-46.506986,19.96
-54.399675,-3.681487,-0.177702,-46.874146,20.1
-54.401274,-3.709447,-0.179027,-47.230151,20.24
-54.401787,-3.739464,-0.180061,-47.612338,20.38
-54.405698,-3.769571,-0.181313,-47.995663,20.52
-54.406452,-3.793687,-0.182815,-48.302718,20.66
-54.4091,-3.823173,-0.183733,-48.678151,20.8
-54.407805,-3.831387,-0.184904,-48.782729,20.94
-54.41173,-3.872859,-0.186124,-49.310778,21.08
-54.410808,-3.872758,-0.187144,-49.309488,21.22
-54.414773,-3.92884,-0.188768,-50.023547,21.36
-54.414187,-3.955483,-0.189966,-50.362779,21.5
-54.415136,-3.967339,-0.191158,-50.513726,21.64
-54.415086,-3.997552,-0.192192,-50.898418,21.78
-54.418878,-4.011691,-0.193547,-51.078431,21.92
-54.418442,-4.048061,-0.194649,-51.541518,22.06
-54.423339,-4.073799,-0.195904,-51.869215,22.2
-54.422812,-4.088247,-0.196645,-52.053175,22.34
-54.423102,-4.115272,-0.197915,-52.397265,22.48
-54.424274,-4.154974,-0.199191,-52.902775,22.62
-54.42541,-4.171902,-0.200649,-53.118305,22.76
-54.427154,-4.193687,-0.201493,-53.395687,22.9
-54.42709,-4.214609,-0.202776,-53.662064,23.04
-54.431441,-4.245096,-0.203799,-54.050247,23.18
-54.431469,-4.293776,-0.205244,-54.670048,23.32
-54.434017,-4.30609,-0.206331,-54.826839,23.46
-54.432572,-4.317087,-0.207448,-54.966858,23.6
-54.439617,-4.344803,-0.20872,-55.319751,23.74
-54.436928,-4.370117,-0.209648,-55.64206,23.88
-54.439512,-4.40017,-0.210751,-56.024703,24.02
-54.438599,-4.416633,-0.212202,-56.234313,24.16
-54.443028,-4.462075,-0.213428,-56.812906,24.3
-54.444626,-4.470259,-0.214759,-56.917105,24.44
-54.445126,-4.496884,-0.215944,-57.25611,24.58
-54.446997,-4.530054,-0.21717,-57.678443,24.72
-54.447869,-4.564303,-0.218793,-58.114513,24.86
-54.450331,-4.572099,-0.219509,-58.213778,25
-54.447479,-4.586428,-0.220774,-58.39622,25.14
-54.453778,-4.641068,-0.222187,-59.091913,25.28
-54.451821,-4.648948,-0.223172,-59.192241,25.42
-54.456667,-4.681242,-0.224525,-59.603418,25.56
-54.456662,-4.70646,-0.2259,-59.924513,25.7
-54.457425,-4.723835,-0.226902,-60.145735,25.84
-54.45897,-4.741532,-0.228138,-60.371055,25.98
-54.462353,-4.775679,-0.229067,-60.805835,26.12
-54.462017,-4.80929,-0.230525,-61.233784,26.26
-54.463375,-4.819709,-0.231584,-61.366442,26.4
-54.463507,-4.847866,-0.232868,-61.724951,26.54
-54.467772,-4.885143,-0.234156,-62.199573,26.68
-54.466736,-4.910117,-0.235244,-62.517556,26.82
-54.468112,-4.916692,-0.236438,-62.601264,26.96
-54.47081,-4.967016,-0.237801,-63.242012,27.1
-54.470202,-4.966211,-0.238924,-63.231766,27.24
-54.473763,-4.995137,-0.239865,-63.600065,27.38
-54.474389,-5.010706,-0.242617,-63.798293,27.52
-54.476129,-4.987484,-0.242724,-63.502621,27.66
-54.476061,-4.975456,-0.242908,-63.349473,27.8
-54.475184,-4.963517,-0.242941,-63.197464,27.94
-54.474512,-4.947436,-0.243016,-62.99271,28.08
-54.47765,-4.94594,-0.243082,-62.973661,28.22
-54.474517,-4.933709,-0.243058,-62.817933,28.36
-54.473436,-4.795486,-0.243864,-61.058021,0.08
-54.472791,-4.752201,-0.24364,-60.5069,0.22
-54.469711,-4.685831,-0.243115,-59.661854,0.36
-54.470329,-4.626966,-0.242871,-58.912355,0.5
-54.468203,-4.56031,-0.24223,-58.063666,0.64
-54.46819,-4.510671,-0.241959,-57.431646,0.78
-54.462871,-4.449683,-0.241524,-56.655129,0.92
-54.464629,-4.383886,-0.241181,-55.817368,1.06
-54.461945,-4.279238,-0.240396,-54.48495,1.2
-54.462508,-4.18008,-0.239657,-53.222428,1.34
-54.458979,-4.044557,-0.238669,-51.496894,1.48
-54.458148,-3.937906,-0.237996,-50.138977,1.62
-54.458334,-3.838336,-0.237218,-48.871218,1.76
-54.457008,-3.732467,-0.236401,-47.523242,1.9
-54.454146,-3.62463,-0.235624,-46.150222,2.04
-54.452216,-3.528225,-0.234884,-44.922761,2.18
-54.451298,-3.410053,-0.234013,-43.418147,2.32
-54.448914,-3.335327,-0.233298,-42.466701,2.46
-54.44935,-3.233981,-0.232534,-41.176327,2.6
-54.446752,-3.13552,-0.231737,-39.922683,2.74
-54.445921,-3.050429,-0.231091,-38.839264,2.88
-54.442546,-2.936357,-0.230152,-37.386862,3.02
-54.444563,-2.84903,-0.229362,-36.274983,3.16
-54.441161,-2.757978,-0.228646,-35.115672,3.3
-54.440402,-2.654397,-0.227705,-33.796838,3.44
-54.438331,-2.582151,-0.227218,-32.876964,3.58
-54.43552,-2.491862,-0.226208,-31.727367,3.72
-54.434239,-2.424544,-0.225597,-30.870254,3.86
-54.433948,-2.321881,-0.224714,-29.563108,4
-54.434212,-2.271509,-0.224139,-28.921753,4.14
-54.431432,-2.158922,-0.223115,-27.488248,4.28
-54.431319,-2.091068,-0.222438,-26.624305,4.42
-54.428226,-2.005816,-0.22168,-25.538836,4.56
-54.427472,-1.936978,-0.220856,-24.662371,4.7
-54.424429,-1.837206,-0.219797,-23.392032,4.84
-54.423956,-1.766521,-0.2191,-22.492041,4.98
-54.422725,-1.67861,-0.218134,-21.372724,5.12
-54.421535,-1.600456,-0.21729,-20.377642,5.26
-54.420891,-1.522315,-0.216425,-19.382711,5.4
-54.419165,-1.453763,-0.215656,-18.509889,5.54
-54.417025,-1.370066,-0.214688,-17.444227,5.68
-54.417793,-1.299703,-0.213881,-16.548334,5.82
-54.415,-1.227987,-0.213031,-15.635214,5.96
-54.411748,-1.158684,-0.212196,-14.752829,6.1
-54.413455,-1.113451,-0.211381,-14.176892,6.24
-54.410912,-1.023841,-0.210315,-13.035947,6.38
-54.410717,-0.967503,-0.209546,-12.318626,6.52
-54.407047,-0.904751,-0.208691,-11.519645,6.66
-54.407306,-0.833392,-0.207567,-10.611078,6.8
-54.404885,-0.785738,-0.206911,-10.00433,6.94
-54.404195,-0.70281,-0.205613,-8.948459,7.08
-54.402914,-0.638562,-0.204678,-8.13043,7.22
-54.401052,-0.5822,-0.203575,-7.412804,7.36
-54.397927,-0.531173,-0.202567,-6.763102,7.5
-54.398326,-0.474411,-0.201672,-6.040392,7.64
-54.396641,-0.432032,-0.200528,-5.500807,7.78
-54.394539,-0.365734,-0.199296,-4.656671,7.92
-54.394693,-0.340384,-0.198536,-4.333907,8.06
-54.39155,-0.289202,-0.197312,-3.682231,8.2
-54.391146,-0.244164,-0.195956,-3.108799,8.34
-54.38863,-0.216228,-0.195243,-2.753097,8.48
-54.388207,-0.18509,-0.194238,-2.356643,8.62
-54.387907,-0.142699,-0.192688,-1.816906,8.76
-54.386009,-0.120497,-0.19198,-1.534212,8.9
-54.384478,-0.103945,-0.190844,-1.323463,9.04
-54.381222,-0.07273,-0.189628,-0.926022,9.18
-54.382275,-0.058472,-0.188448,-0.744491,9.32
-54.379568,-0.032365,-0.186889,-0.412088,9.46
-54.379391,-0.026411,-0.185691,-0.336273,9.6
-54.377089,-0.010926,-0.184499,-0.139108,9.74
-54.375304,-0.006217,-0.183114,-0.079154,9.88
-54.374541,-0.003791,-0.182668,-0.048267,10.02
-54.375835,-0.003338,-0.182495,-0.042499,10.16
-54.376562,-0.010508,-0.182569,-0.133796,10.3
-54.374345,0.000036,-0.182448,0.000455,10.44
-54.375531,-0.010437,-0.182645,-0.132885,10.58
-54.374513,-0.005329,-0.182487,-0.067847,10.72
-54.375381,-0.005859,-0.182532,-0.074601,10.86
-54.376326,-0.008476,-0.182419,-0.107917,11
-54.376693,-0.002867,-0.182385,-0.036504,11.14
-54.375008,-0.007176,-0.18237,-0.091373,11.28
-54.373932,-0.002033,-0.18231,-0.025879,11.42
-54.264355,-0.007027,0.002606,-0.089475,0.11
-54.266603,-0.000238,0.00179,-0.003036,0.25
-54.26668,-0.006783,0.00102,-0.086364,0.39
-54.26901,-0.012589,-0.000019,-0.160282,0.53
-54.27074,-0.014019,-0.00042,-0.178496,0.67
-54.27025,-0.013453,-0.001366,-0.171286,0.81
-54.272312,-0.019133,-0.002104,-0.24361,0.95
-54.27476,-0.027841,-0.002906,-0.354487,1.09
-54.275764,-0.03252,-0.003798,-0.414061,1.23
-54.275709,-0.030851,-0.004362,-0.392812,1.37
-54.278593,-0.052541,-0.00611,-0.668979,1.51
-54.280342,-0.07242,-0.007698,-0.922076,1.65
-54.282213,-0.074083,-0.008647,-0.943249,1.79
-54.281414,-0.079608,-0.009875,-1.0136,1.93
-54.28234,-0.100994,-0.011555,-1.285897,2.07
-54.285956,-0.116771,-0.013043,-1.48678,2.21
-54.286542,-0.11937,-0.013984,-1.519869,2.35
-54.28666,-0.131118,-0.015209,-1.66945,2.49
-54.289067,-0.15341,-0.016789,-1.953282,2.63
-54.290602,-0.164044,-0.018084,-2.088672,2.77
-54.289507,-0.175655,-0.01927,-2.236507,2.91
-54.292605,-0.192004,-0.020816,-2.444676,3.05
-54.295407,-0.213903,-0.022081,-2.7235,3.19
-54.297683,-0.22791,-0.02311,-2.901844,3.33
-54.29677,-0.238132,-0.024517,-3.031997,3.47
-54.298941,-0.261992,-0.02579,-3.335788,3.61
-54.301657,-0.279325,-0.026928,-3.55648,3.75
-54.302052,-0.293642,-0.028054,-3.73877,3.89
-54.302783,-0.305468,-0.029026,-3.889337,4.03
-54.303465,-0.336349,-0.030583,-4.282529,4.17
-54.307988,-0.35041,-0.031557,-4.461555,4.31
-54.307961,-0.368297,-0.032819,-4.689304,4.45
-54.30951,-0.388604,-0.03419,-4.947865,4.59
-54.310069,-0.4197,-0.035698,-5.343788,4.73
-54.312312,-0.437844,-0.036727,-5.5748,4.87
-54.313012,-0.458074,-0.038143,-5.832374,5.01
-54.316014,-0.480437,-0.039322,-6.117117,5.15
-54.317485,-0.506777,-0.040774,-6.45248,5.29
-54.318403,-0.517732,-0.041487,-6.591967,5.43
-54.318639,-0.537914,-0.042897,-6.848934,5.57
-54.318962,-0.565219,-0.044241,-7.196591,5.71
-54.322055,-0.597727,-0.045679,-7.6105,5.85
-54.322082,-0.600111,-0.046308,-7.640857,5.99
-54.323658,-0.630689,-0.047887,-8.030178,6.13
-54.325302,-0.656533,-0.048815,-8.359241,6.27
-54.3277,-0.682563,-0.050284,-8.690657,6.41
-54.327968,-0.695294,-0.051184,-8.85276,6.55
-54.329004,-0.722533,-0.052594,-9.199582,6.69
-54.333119,-0.757569,-0.053984,-9.645669,6.83
-54.333864,-0.77436,-0.055128,-9.859454,6.97
-54.333882,-0.79025,-0.056146,-10.061779,7.11
-54.334985,-0.827229,-0.057468,-10.532607,7.25
-54.339128,-0.844115,-0.058336,-10.747606,7.39
-54.338946,-0.872195,-0.05974,-11.105129,7.53
-54.340458,-0.895643,-0.061097,-11.403684,7.67
-54.338455,-0.920337,-0.062204,-11.7181,7.81
-54.343215,-0.952452,-0.063655,-12.127001,7.95
-54.344632,-0.967413,-0.064656,-12.317487,8.09
-54.345909,-0.99479,-0.066024,-12.666055,8.23
-54.347112,-1.021832,-0.067004,-13.010372,8.37
-54.347212,-1.055962,-0.06843,-13.444924,8.51
-54.348416,-1.072675,-0.069487,-13.657722,8.65
-54.350428,-1.092756,-0.070331,-13.913399,8.79
-54.353216,-1.120162,-0.071802,-14.262346,8.93
-54.354579,-1.144719,-0.073031,-14.575017,9.07
-54.355796,-1.166701,-0.07409,-14.854903,9.21
-54.358004,-1.187909,-0.075086,-15.124923,9.35
-54.358676,-1.219088,-0.076288,-15.521908,9.49
-54.359675,-1.236433,-0.077322,-15.742751,9.63
-54.36042,-1.263094,-0.078678,-16.082212,9.77
-54.360624,-1.29711,-0.079916,-16.515322,9.91
-54.364221,-1.321006,-0.08092,-16.819569,10.05
-54.365825,-1.351869,-0.08235,-17.212532,10.19
-54.366833,-1.375806,-0.083514,-17.51731,10.33
-54.368159,-1.401556,-0.084652,-17.845159,10.47
-54.369872,-1.445293,-0.0862,-18.402047,10.61
-54.370417,-1.457441,-0.087053,-18.556713,10.75
-54.37187,-1.47953,-0.088497,-18.837965,10.89
-54.374209,-1.523799,-0.089943,-19.401608,11.03
-54.375685,-1.553339,-0.090962,-19.777723,11.17
-54.377992,-1.57057,-0.0921,-19.997124,11.31
-54.375385,-1.600122,-0.093554,-20.373392,11.45
-54.37985,-1.631027,-0.094739,-20.766887,11.59
-54.380877,-1.667166,-0.095774,-21.227014,11.73
-54.381521,-1.674855,-0.096618,-21.324913,11.87
-54.382916,-1.7048,-0.097913,-21.706189,12.01
-54.384637,-1.74551,-0.099216,-22.224525,12.15
-54.386286,-1.779687,-0.100445,-22.659684,12.29
-54.386985,-1.785761,-0.10153,-22.737017,12.43
-54.389034,-1.82842,-0.10283,-23.280169,12.57
-54.39219,-1.846766,-0.103678,-23.513761,12.71
-54.391586,-1.874423,-0.104851,-23.865895,12.85
-54.392477,-1.900101,-0.106207,-24.192834,12.99
-54.393521,-1.927334,-0.107088,-24.53958,13.13
-54.396746,-1.957953,-0.108231,-24.929432,13.27
-54.396828,-1.986617,-0.109556,-25.294391,13.41
-54.398613,-2.022213,-0.11103,-25.747612,13.55
-54.398722,-2.044052,-0.112196,-26.025677,13.69
-54.401601,-2.090704,-0.113834,-26.619676,13.83
-54.403754,-2.112913,-0.114686,-26.902446,13.97
-54.404231,-2.117527,-0.115537,-26.961185,14.11
-54.405098,-2.158028,-0.117093,-27.476864,14.25
-54.406693,-2.194589,-0.11828,-27.94238,14.39
-54.410276,-2.211666,-0.119327,-28.159807,14.53
-54.409985,-2.233124,-0.120247,-28.433015,14.67
-54.410876,-2.263433,-0.121434,-28.818921,14.81
-54.413819,-2.298337,-0.122962,-29.263338,14.95
-54.415345,-2.329826,-0.123915,-29.66427,15.09
-54.414355,-2.342951,-0.125013,-29.831382,15.23
-54.414868,-2.384049,-0.126511,-30.354651,15.37
-54.418656,-2.412635,-0.127433,-30.718624,15.51
-54.421622,-2.449626,-0.12878,-31.189603,15.65
-54.420936,-2.459586,-0.129592,-31.316417,15.79
-54.422753,-2.495569,-0.131223,-31.774571,15.93
-54.423152,-2.515942,-0.132181,-32.033967,16.07
-54.424211,-2.555019,-0.133558,-32.531508,16.21
-54.426668,-2.589554,-0.134889,-32.97122,16.35
-54.426827,-2.61218,-0.135897,-33.259303,16.49
-54.428421,-2.630478,-0.136871,-33.492288,16.63
-54.430792,-2.664924,-0.138392,-33.930862,16.77
-54.432018,-2.691793,-0.139308,-34.272979,16.91
-54.431718,-2.718306,-0.140386,-34.610542,17.05
-54.435179,-2.746063,-0.141522,-34.963966,17.19
-54.436337,-2.766258,-0.142975,-35.221085,17.33
-54.437355,-2.803081,-0.144125,-35.689939,17.47
-54.43949,-2.818877,-0.145043,-35.89105,17.61
-54.439776,-2.854413,-0.146498,-36.343512,17.75
-54.442424,-2.891505,-0.147443,-36.815782,17.89
-54.444354,-2.901298,-0.14855,-36.940471,18.03
-54.444031,-2.943057,-0.14981,-37.472163,18.17
-54.44538,-2.965903,-0.151137,-37.763053,18.31
-54.446788,-3.004611,-0.152705,-38.25589,18.45
-54.449314,-3.028852,-0.153557,-38.564538,18.59
-54.449454,-3.056413,-0.154898,-38.915458,18.73
-54.449677,-3.076994,-0.155953,-39.17751,18.87
-54.454655,-3.117639,-0.157411,-39.69501,19.01
-54.454678,-3.136122,-0.158242,-39.930348,19.15
-54.456013,-3.156573,-0.159447,-40.19073,19.29
-54.45723,-3.188449,-0.160803,-40.596595,19.43
-54.459774,-3.204739,-0.161723,-40.804005,19.57
-54.460032,-3.250819,-0.162899,-41.390719,19.71
-54.460582,-3.260428,-0.163862,-41.513055,19.85
-54.460791,-3.286111,-0.165299,-41.840069,19.99
-54.464311,-3.332627,-0.16656,-42.432323,20.13
-54.464565,-3.352892,-0.167634,-42.690352,20.27
-54.467222,-3.366154,-0.168642,-42.859209,20.41
-54.467313,-3.400087,-0.170024,-43.291257,20.55
-54.470029,-3.438866,-0.171206,-43.785004,20.69
-54.471505,-3.453827,-0.172374,-43.97549,20.83
-54.473922,-3.479487,-0.173129,-44.302201,20.97
-54.473563,-3.503603,-0.174458,-44.609256,21.11
-54.47592,-3.535682,-0.175752,-45.017701,21.25
-54.4782,-3.563529,-0.176918,-45.372264,21.39
-54.478504,-3.584039,-0.17817,-45.633405,21.53
-54.479045,-3.61771,-0.17951,-46.062113,21.67
-54.481207,-3.658456,-0.180903,-46.580904,21.81
-54.483841,-3.690988,-0.182031,-46.995117,21.95
-54.482578,-3.705573,-0.183203,-47.180822,22.09
-54.48603,-3.742069,-0.184347,-47.645502,22.23
-54.487806,-3.768092,-0.185663,-47.976842,22.37
-54.489909,-3.781122,-0.186831,-48.14274,22.51
-54.488292,-3.797841,-0.187831,-48.355614,22.65
-54.491848,-3.838146,-0.189257,-48.868789,22.79
-54.491444,-3.872418,-0.190211,-49.305162,22.93
-54.494891,-3.882802,-0.191254,-49.437365,23.07
-54.495677,-3.911602,-0.19239,-49.80407,23.21
-54.496872,-3.9446,-0.193561,-50.224202,23.35
-54.498693,-3.973824,-0.194594,-50.596296,23.49
-54.499456,-3.998345,-0.195884,-50.908511,23.63
-54.50115,-4.01839,-0.197078,-51.163733,23.77
-54.500301,-4.065794,-0.198405,-51.767294,23.91
-54.504084,-4.096985,-0.200076,-52.164431,24.05
-54.504588,-4.115206,-0.201175,-52.39643,24.19
-54.50656,-4.150677,-0.202176,-52.848057,24.33
-54.508104,-4.179627,-0.203585,-53.21666,24.47
-54.510302,-4.190761,-0.204414,-53.358424,24.61
-54.510625,-4.207933,-0.205405,-53.577066,24.75
-54.512105,-4.247117,-0.20662,-54.075974,24.89
-54.513413,-4.250234,-0.207726,-54.115665,25.03
-54.51682,-4.289681,-0.208884,-54.617911,25.17
-54.516702,-4.334682,-0.209963,-55.190888,25.31
-54.514608,-4.338527,-0.211073,-55.239838,25.45
-54.519372,-4.365408,-0.212498,-55.582106,25.59
-54.520817,-4.40529,-0.213389,-56.089893,25.73
-54.520689,-4.414862,-0.214825,-56.211774,25.87
-54.521439,-4.456228,-0.215732,-56.738457,26.01
-54.524436,-4.479271,-0.21719,-57.031852,26.15
-54.525177,-4.507762,-0.218543,-57.394611,26.29
-54.52713,-4.544771,-0.219659,-57.865818,26.43
-54.527997,-4.546881,-0.220842,-57.892683,26.57
-54.529464,-4.589838,-0.221909,-58.43963,26.71
-54.531735,-4.605347,-0.222966,-58.637098,26.85
-54.532857,-4.629171,-0.224252,-58.940434,26.99
-54.533747,-4.658937,-0.22543,-59.319434,27.13
-54.536259,-4.686445,-0.226679,-59.669671,27.27
-54.538221,-4.714072,-0.227807,-60.021426,27.41
-54.53659,-4.742122,-0.228813,-60.378569,27.55
-54.538484,-4.769009,-0.230032,-60.720913,27.69
-54.541768,-4.795259,-0.23132,-61.055137,27.83
-54.543499,-4.818285,-0.232672,-61.348304,27.97
-54.54358,-4.850113,-0.233848,-61.753562,28.11
-54.544312,-4.866105,-0.234909,-61.957177,28.25
-54.548063,-4.901963,-0.236228,-62.413737,28.39
-54.549185,-4.912502,-0.237,-62.547913,28.53
-54.550221,-4.953939,-0.238455,-63.075507,28.67
-54.551565,-4.978627,-0.23965,-63.389847,28.81
-54.553977,-4.999965,-0.240715,-63.661537,28.95
-54.553096,-5.033189,-0.24197,-64.084553,29.09
-54.554654,-5.054653,-0.243249,-64.357837,29.23
-54.556643,-5.093503,-0.2446,-64.852494,29.37
-54.559486,-5.115354,-0.245985,-65.130711,29.51
-54.560962,-5.148035,-0.247172,-65.546821,29.65
-54.561594,-5.163461,-0.248194,-65.743227,29.79
-54.561693,-5.186385,-0.249617,-66.035104,29.93
-54.565649,-5.223072,-0.25079,-66.502213,30.07
-54.566417,-5.246031,-0.251829,-66.794545,30.21
-54.568665,-5.250853,-0.252688,-66.855941,30.35
-54.566385,-5.28388,-0.254091,-67.276453,30.49
-54.568261,-5.310285,-0.255325,-67.61265,30.63
-54.573784,-5.33815,-0.256455,-67.96744,30.77
-54.570886,-5.35785,-0.257661,-68.21826,30.91
-54.572321,-5.382389,-0.258818,-68.530703,31.05
-54.574138,-5.411094,-0.259949,-68.896194,31.19
-54.575592,-5.436563,-0.261063,-69.220476,31.33
-54.57704,-5.464709,-0.262188,-69.578834,31.47
-54.577917,-5.471975,-0.263338,-69.671345,31.61
-54.580038,-5.500656,-0.2645,-70.036532,31.75
-54.581696,-5.550778,-0.266222,-70.674699,31.89
-54.5826,-5.562711,-0.26705,-70.826633,32.03
-54.582568,-5.599254,-0.268414,-71.291921,32.17
-54.585938,-5.61105,-0.269687,-71.442109,32.31
-54.5878,-5.652511,-0.270956,-71.970007,32.45
-54.589013,-5.667245,-0.27191,-72.157609,32.59
-54.587664,-5.703443,-0.273109,-72.618495,32.73
-54.592047,-5.707371,-0.274324,-72.668508,32.87
-54.594068,-5.746686,-0.275418,-73.169085,33.01
-54.595549,-5.785191,-0.276571,-73.65934,33.15
-54.594082,-5.792153,-0.277838,-73.747981,33.29
-54.597134,-5.821198,-0.27912,-74.117798,33.43
-54.597379,-5.850238,-0.280387,-74.487539,33.57
-54.601558,-5.863976,-0.281232,-74.662467,33.71
-54.600458,-5.893129,-0.28264,-75.03365,33.85
-54.603093,-5.929244,-0.284145,-75.493474,33.99
-54.605268,-5.949861,-0.285121,-75.755981,34.13
-54.606558,-5.971181,-0.286568,-76.027443,34.27
-54.605459,-5.997187,-0.287799,-76.358555,34.41
-54.607108,-6.035995,-0.288944,-76.852681,34.55
-54.610246,-6.036246,-0.290184,-76.855869,34.69
-54.612903,-6.088662,-0.291351,-77.523254,34.83
-54.613439,-6.098557,-0.29224,-77.649233,34.97
-54.612876,-6.112754,-0.293281,-77.830006,35.11
-54.614893,-6.147152,-0.294446,-78.267973,35.25
-54.617032,-6.170362,-0.29574,-78.563492,35.39
-54.619148,-6.188947,-0.296896,-78.80012,35.53
-54.619811,-6.227022,-0.298179,-79.284912,35.67
-54.620329,-6.245655,-0.299572,-79.522147,35.81
-54.622482,-6.278807,-0.300696,-79.944253,35.95
-54.625416,-6.310397,-0.301902,-80.346475,36.09
-54.624031,-6.315786,-0.303149,-80.41508,36.23
-54.625834,-6.340951,-0.304231,-80.735492,36.37
-54.628336,-6.372851,-0.305611,-81.141661,36.51
-54.629695,-6.406999,-0.306774,-81.57644,36.65
-54.629445,-6.399029,-0.307644,-81.474974,36.79
-54.630676,-6.452394,-0.309251,-82.154426,36.93
-54.633973,-6.46947,-0.310339,-82.371854,37.07
-54.63504,-6.493062,-0.311501,-82.67223,37.21
-54.636625,-6.524253,-0.312798,-83.069368,37.35
-54.634018,-6.527472,-0.313978,-83.110349,37.49
-54.638787,-6.570625,-0.314974,-83.6598,37.63
-54.640813,-6.61037,-0.316564,-84.165841,37.77
-54.64372,-6.61729,-0.317515,-84.25395,37.91
-54.641281,-6.637388,-0.318569,-84.509855,38.05
-54.644587,-6.653291,-0.319677,-84.712332,38.19
-54.646568,-6.688541,-0.320802,-85.161151,38.33
-54.647839,-6.714261,-0.322048,-85.488621,38.47
-54.647708,-6.735575,-0.323185,-85.760007,38.61
-54.650569,-6.765473,-0.324593,-86.140676,38.75
-54.651477,-6.774467,-0.325446,-86.255196,38.89
-54.654071,-6.813264,-0.326606,-86.74917,39.03
-54.654284,-6.810766,-0.327791,-86.717372,39.17
-54.655697,-6.848395,-0.32895,-87.196472,39.31
-54.658149,-6.879073,-0.330366,-87.587083,39.45
-54.659494,-6.918108,-0.331726,-88.084093,39.59
-54.658831,-6.922978,-0.3329,-88.146096,39.73
-54.661556,-6.959009,-0.334054,-88.604857,39.87
-54.661933,-6.980622,-0.335362,-88.880037,40.01
-54.664004,-7.006234,-0.33662,-89.206141,40.15
-54.666774,-7.006997,-0.337432,-89.215855,40.29
-54.665435,-7.036006,-0.338424,-89.585216,40.43
-54.666897,-7.07593,-0.339965,-90.093534,40.57
-54.670076,-7.110602,-0.341335,-90.534992,40.71
-54.673079,-7.118315,-0.342337,-90.633195,40.85
-54.672783,-7.136661,-0.343407,-90.866788,40.99
-54.671889,-7.152325,-0.344433,-91.066229,41.13
-54.676212,-7.187259,-0.345915,-91.511026,41.27
-54.677997,-7.217866,-0.347068,-91.900727,41.41
-54.678869,-7.237262,-0.348234,-92.147676,41.55
-54.677475,-7.249689,-0.349585,-92.305909,41.69
-54.680736,-7.307553,-0.350882,-93.042658,41.83
-54.683502,-7.309526,-0.352046,-93.067778,41.97
-54.683988,-7.341391,-0.353393,-93.473491,42.11
-54.685101,-7.358843,-0.354522,-93.6957,42.25
-54.684588,-7.384819,-0.355672,-94.026433,42.39
-54.688557,-7.405037,-0.357066,-94.283855,42.53
-54.691064,-7.436711,-0.358296,-94.68714,42.67
-54.690406,-7.439011,-0.359496,-94.716434,42.81
-54.690869,-7.49144,-0.360727,-95.383971,42.95
-54.693226,-7.503349,-0.361978,-95.535601,43.09
-54.69537,-7.533044,-0.362976,-95.91369,43.23
-54.698159,-7.568139,-0.364425,-96.360536,43.37
-54.69721,-7.580477,-0.365503,-96.517631,43.51
-54.699521,-7.59958,-0.367023,-96.760861,43.65
-54.700843,-7.616723,-0.367801,-96.979124,43.79
-54.702624,-7.640755,-0.369,-97.285116,43.93
-54.704613,-7.675475,-0.370412,-97.727181,44.07
-54.703845,-7.678294,-0.371333,-97.763078,44.21
-54.706575,-7.708681,-0.372471,-98.14997,44.35
-54.709123,-7.733959,-0.373613,-98.471824,44.49
-54.707125,-7.763374,-0.374861,-98.846346,44.63
-54.708782,-7.784289,-0.376249,-99.112647,44.77
-54.711653,-7.829863,-0.37764,-99.69291,44.91
-54.71381,-7.833064,-0.379006,-99.733663,45.05
-54.716204,-7.868177,-0.380088,-100.180737,45.19
-54.715859,-7.861656,-0.381211,-100.097712,45.33
-54.716458,-7.921129,-0.382624,-100.854953,45.47
-54.719197,-7.944059,-0.383923,-101.146905,45.61
-54.7211,-7.953888,-0.384835,-101.27205,45.75
-54.721,-7.975209,-0.385983,-101.543512,45.89
-54.721236,-7.993501,-0.387393,-101.776421,46.03
-54.723166,-8.021909,-0.388508,-102.138118,46.17
-54.725978,-8.035254,-0.389623,-102.308038,46.31
-54.727068,-8.061862,-0.390831,-102.646815,46.45
-54.728371,-8.090013,-0.392164,-103.005248,46.59
-54.72982,-8.122319,-0.393743,-103.416577,46.73
-54.731901,-8.125913,-0.394655,-103.46234,46.87
-54.732455,-8.156383,-0.395772,-103.850294,47.01
-54.733281,-8.178967,-0.397056,-104.137845,47.15
-54.734721,-8.210933,-0.398144,-104.544849,47.29
-54.737419,-8.24939,-0.399639,-105.034497,47.43
-54.738545,-8.255315,-0.400781,-105.109933,47.57
-54.739962,-8.279055,-0.402057,-105.412207,47.71
-54.739999,-8.295971,-0.403161,-105.627585,47.85
-54.743096,-8.316189,-0.404361,-105.885008,47.99
-54.745953,-8.330071,-0.405387,-106.061758,48.13
-54.744908,-8.364052,-0.406802,-106.494412,48.27
-54.745994,-8.37642,-0.407692,-106.651886,48.41
-54.748179,-8.417153,-0.409128,-107.170525,48.55
-54.75054,-8.422887,-0.410213,-107.243532,48.69
-54.750372,-8.472252,-0.411422,-107.872061,48.83
-54.751544,-8.467227,-0.412524,-107.808085,48.97
-54.752929,-8.480006,-0.413574,-107.970796,49.11
-54.756309,-8.533388,-0.414934,-108.650475,49.25
-54.756263,-8.536118,-0.415988,-108.685233,49.39
-54.756663,-8.573967,-0.417272,-109.167141,49.53
-54.759629,-8.595377,-0.418833,-109.439742,49.67
-54.762367,-8.605558,-0.4199,-109.569363,49.81
-54.761868,-8.646226,-0.421026,-110.087168,49.95
-54.764071,-8.653033,-0.422333,-110.173835,50.09
-54.76467,-8.688879,-0.423592,-110.630244,50.23
-54.767209,-8.695233,-0.424707,-110.711143,50.37
-54.769049,-8.726716,-0.426011,-111.112,50.51
-54.766778,-8.718896,-0.426736,-111.012431,50.65
-54.769367,-8.760953,-0.4281,-111.547917,50.79
-54.770634,-8.782977,-0.429209,-111.828335,50.93
-54.771892,-8.814245,-0.43048,-112.226459,51.07
-54.772877,-8.833748,-0.431695,-112.474774,51.21
-54.77513,-8.859247,-0.432902,-112.799436,51.35
-54.777229,-8.873087,-0.434296,-112.975655,51.49
-54.779886,-8.898562,-0.43532,-113.300013,51.63
-54.78088,-8.905274,-0.436313,-113.385466,51.77
-54.781289,-8.947468,-0.43762,-113.922698,51.91
-54.78351,-8.961082,-0.438995,-114.096033,52.05
-54.785304,-8.985347,-0.439941,-114.404986,52.19
-54.787502,-9.001368,-0.441058,-114.608981,52.33
-54.786439,-9.030497,-0.442345,-114.97986,52.47
-54.789837,-9.047014,-0.44349,-115.190154,52.61
-54.790082,-9.083837,-0.445011,-115.659008,52.75
-54.791009,-9.107208,-0.446276,-115.956577,52.89
-54.794951,-9.106332,-0.447497,-115.945421,53.03
-54.793007,-9.125602,-0.448789,-116.190776,53.17
-54.796264,-9.181404,-0.450067,-116.901268,53.31
-54.797045,-9.19826,-0.451149,-117.115888,53.45
-54.798525,-9.203482,-0.452331,-117.182368,53.59
-54.80021,-9.229237,-0.453636,-117.510293,53.73
-54.802336,-9.254831,-0.454829,-117.836169,53.87
-54.803403,-9.257185,-0.455852,-117.866146,54.01
-54.803917,-9.296292,-0.457348,-118.364067,54.15
-54.803817,-9.307635,-0.458251,-118.508487,54.29
-54.807909,-9.334391,-0.459513,-118.849162,54.43
-54.809362,-9.353042,-0.460486,-119.086625,54.57
-54.810375,-9.377778,-0.46142,-119.401573,54.71
-54.809889,-9.412932,-0.462808,-119.849178,54.85
-54.813759,-9.431589,-0.46422,-120.086716,54.99
-54.815226,-9.455532,-0.465467,-120.39157,55.13
-54.814958,-9.448504,-0.466481,-120.302095,55.27
-54.817606,-9.488875,-0.467814,-120.816105,55.41
-54.817656,-9.546554,-0.469215,-121.550502,55.55
-54.820812,-9.53005,-0.470318,-121.34036,55.69
-54.820195,-9.563315,-0.471414,-121.763907,55.83
-54.820885,-9.573376,-0.472614,-121.892011,55.97
-54.823665,-9.610432,-0.473857,-122.363826,56.11
-54.826876,-9.633589,-0.474989,-122.658662,56.25
-54.826208,-9.634405,-0.476058,-122.669059,56.39
-54.827766,-9.645957,-0.477234,-122.816136,56.53
-54.830214,-9.692186,-0.478473,-123.404746,56.67
-54.830055,-9.694707,-0.479428,-123.436848,56.81
-54.83149,-9.716165,-0.480573,-123.710056,56.95
-54.833275,-9.760582,-0.481968,-124.275596,57.09
-54.833997,-9.794128,-0.483549,-124.70271,57.23
-54.835801,-9.809637,-0.485007,-124.900178,57.37
-54.836904,-9.821838,-0.485986,-125.055527,57.51
-54.838603,-9.843779,-0.487249,-125.334882,57.65
-54.839825,-9.87137,-0.488451,-125.686181,57.79
-54.843844,-9.899145,-0.489774,-126.039833,57.93
-54.842977,-9.911406,-0.49097,-126.195941,58.07
-54.843222,-9.936559,-0.492048,-126.516201,58.21
-54.845484,-9.945482,-0.493192,-126.62981,58.35
-54.845797,-9.973723,-0.494501,-126.989381,58.49
-54.849572,-9.993309,-0.495644,-127.238759,58.63
-54.850898,-10.002553,-0.497687,-127.356466,58.77
-54.850139,-9.94556,-0.497983,-126.630797,58.91
-54.850466,-9.917098,-0.49808,-126.268417,59.05
-54.849481,-9.890985,-0.498307,-125.935939,59.19
-54.849113,-9.874421,-0.49845,-125.725038,59.33
-54.85137,-9.870321,-0.498437,-125.672825,59.47
-54.850989,-9.857857,-0.498471,-125.514136,59.61
-54.850993,-9.845847,-0.498436,-125.361216,59.75
-54.849994,-9.829551,-0.498518,-125.15373,59.89
-54.849213,-9.347183,-0.496271,-119.012024,0.12
-54.847019,-9.274393,-0.495969,-118.085243,0.26
-54.844489,-9.223521,-0.495841,-117.437514,0.4
-54.842859,-9.147042,-0.495566,-116.463756,0.54
-54.844085,-9.033185,-0.495083,-115.014087,0.68
-54.842123,-8.872646,-0.494327,-112.970039,0.82
-54.839507,-8.675808,-0.493505,-110.463815,0.96
-54.836777,-8.55214,-0.493076,-108.889228,1.1
-54.83799,-8.429468,-0.492497,-107.327316,1.24
-54.836636,-8.272642,-0.491767,-105.330548,1.38
-54.835941,-8.102864,-0.491075,-103.168869,1.52
-54.833866,-7.967383,-0.490415,-101.443867,1.66
-54.832485,-7.842666,-0.489911,-99.855924,1.8
-54.830051,-7.702881,-0.489277,-98.076128,1.94
-54.829565,-7.598031,-0.488799,-96.74113,2.08
-54.829179,-7.498378,-0.488339,-95.472308,2.22
-54.82421,-7.346433,-0.487527,-93.537695,2.36
-54.82346,-7.210916,-0.486936,-91.812238,2.5
-54.823211,-7.103169,-0.486481,-90.440356,2.64
-54.822761,-6.997645,-0.48605,-89.096782,2.78
-54.822997,-6.881028,-0.485424,-87.611975,2.92
-54.819186,-6.77346,-0.484876,-86.24237,3.06
-54.816543,-6.65251,-0.48427,-84.70239,3.2
-54.816797,-6.53823,-0.483803,-83.247332,3.34
-54.815657,-6.381637,-0.48298,-81.253524,3.48
-54.814781,-6.281316,-0.482508,-79.976203,3.62
-54.811865,-6.134629,-0.481767,-78.108526,3.76
-54.809626,-6.042528,-0.481341,-76.935858,3.9
-54.808368,-5.930561,-0.480918,-75.510246,4.04
-54.810421,-5.837649,-0.48032,-74.327257,4.18
-54.807814,-5.705696,-0.479517,-72.647182,4.32
-54.804612,-5.588484,-0.479007,-71.154786,4.46
-54.801618,-5.437207,-0.478217,-69.228672,4.6
-54.800497,-5.369335,-0.477939,-68.364502,4.74
-54.800042,-5.24084,-0.477166,-66.728444,4.88
-54.798752,-5.140752,-0.476681,-65.454082,5.02
-54.797531,-5.016476,-0.476001,-63.871755,5.16
-54.795414,-4.90647,-0.475344,-62.471111,5.3
-54.794865,-4.764915,-0.47459,-60.668776,5.44
-54.795573,-4.675519,-0.474164,-59.530563,5.58
-54.793325,-4.565376,-0.473343,-58.128173,5.72
-54.791349,-4.445112,-0.47275,-56.596921,5.86
-54.790854,-4.341054,-0.472179,-55.272016,6
-54.787797,-4.209203,-0.471403,-53.593231,6.14
-54.786839,-4.108012,-0.470723,-52.30483,6.28
-54.785531,-4.012954,-0.470022,-51.09452,6.42
-54.784037,-3.918689,-0.469601,-49.894304,6.56
-54.78281,-3.818029,-0.468843,-48.612657,6.7
-54.781966,-3.723246,-0.468307,-47.405839,6.84
-54.779931,-3.614467,-0.467622,-46.020828,6.98
-54.778441,-3.507638,-0.466903,-44.660634,7.12
-54.779449,-3.406429,-0.466186,-43.372005,7.26
-54.775398,-3.294021,-0.465502,-41.940777,7.4
-54.77335,-3.19221,-0.46473,-40.644483,7.54
-54.772101,-3.105986,-0.464233,-39.546644,7.68
-54.770361,-3.023487,-0.463648,-38.496236,7.82
-54.769112,-2.91484,-0.462786,-37.112895,7.96
-54.767622,-2.80754,-0.462063,-35.746706,8.1
-54.765565,-2.698797,-0.461301,-34.36215,8.24
-54.764479,-2.624041,-0.460704,-33.410326,8.38
-54.764716,-2.522969,-0.459943,-32.123442,8.52
-54.763362,-2.387488,-0.459026,-30.39844,8.66
-54.761023,-2.308589,-0.458351,-29.393871,8.8
-54.758689,-2.229398,-0.457738,-28.385583,8.94
-54.757467,-2.150863,-0.457121,-27.385643,9.08
-54.75783,-2.069414,-0.456482,-26.348593,9.22
-54.755159,-1.958722,-0.455494,-24.939221,9.36
-54.755178,-1.866788,-0.454719,-23.768679,9.5
-54.753901,-1.801473,-0.454138,-22.937065,9.64
-54.750586,-1.696658,-0.45334,-21.602522,9.78
-54.749855,-1.605576,-0.452569,-20.442832,9.92
-54.750518,-1.521254,-0.451727,-19.369202,10.06
-54.747552,-1.438141,-0.451023,-18.310978,10.2
-54.745158,-1.355213,-0.450116,-17.255107,10.34
-54.742701,-1.281315,-0.449341,-16.31421,10.48
-54.74113,-1.189417,-0.448506,-15.144123,10.62
-54.742819,-1.132149,-0.447992,-14.414962,10.76
-54.74212,-1.0741,-0.44708,-13.67586,10.9
-54.739953,-0.977057,-0.446142,-12.440279,11.04
-54.737492,-0.89922,-0.445272,-11.449218,11.18
-54.734957,-0.826669,-0.444369,-10.525473,11.32
-54.735207,-0.764155,-0.44347,-9.729529,11.46
-54.733004,-0.706691,-0.442757,-8.997864,11.6
-54.732877,-0.637901,-0.441576,-8.122006,11.74
-54.732273,-0.56805,-0.440614,-7.232639,11.88
-54.728185,-0.499153,-0.439434,-6.355415,12.02
-54.725224,-0.443894,-0.438415,-5.65183,12.16
-54.726432,-0.407672,-0.437769,-5.19064,12.3
-54.725387,-0.365824,-0.436687,-4.65781,12.44
-54.725846,-0.310773,-0.435711,-3.95688,12.58
-54.721695,-0.263554,-0.434488,-3.355672,12.72
-54.719842,-0.217533,-0.433345,-2.769718,12.86
-54.71922,-0.184679,-0.432359,-2.351406,13
-54.718575,-0.165445,-0.431652,-2.106506,13.14
-54.718116,-0.141519,-0.430739,-1.80188,13.28
-54.717226,-0.104195,-0.429152,-1.32665,13.42
-54.714042,-0.070786,-0.427184,-0.901281,13.56
-54.712775,-0.051057,-0.426227,-0.650082,13.7
-54.710417,-0.040507,-0.424696,-0.515755,13.84
-54.709377,-0.024539,-0.423099,-0.312443,13.98
-54.709768,-0.016278,-0.421655,-0.207258,14.12
-54.708487,-0.005347,-0.420541,-0.068074,14.26
-54.706148,-0.001901,-0.420584,-0.024209,14.4
-54.705226,-0.001651,-0.420551,-0.021022,14.54
-54.706779,-0.006151,-0.420587,-0.07832,14.68
-54.708578,-0.011706,-0.420723,-0.14905,14.82
-54.708632,-0.012225,-0.420972,-0.155652,14.96
-54.708274,-0.005448,-0.420762,-0.069364,15.07