File: Chain/Curve fitting/Data/Dall.csv
POSN mm ,LOAD kn,STRAIN1 mm,STRESS(MPA),TIME(sec)
-54.272871,-0.004822,0.00655,-0.061396,0
-54.270899,-0.005054,0.005435,-0.064356,0.09
-54.273248,0.005019,0.005066,0.0639,0.18
-54.276718,-0.005841,0.004612,-0.074373,0.27
-54.274537,0.00056,0.004423,0.007134,0.36
-54.273956,0.000036,0.003888,0.000455,0.45
-54.278434,-0.010514,0.003299,-0.133872,0.54
-54.277299,-0.000143,0.002599,-0.001821,0.63
-54.279197,-0.000918,0.001866,-0.011687,0.72
-54.282536,-0.007081,0.000979,-0.090158,0.81
-54.281655,-0.001478,-0.000085,-0.018821,0.9
-54.283517,0.000787,-0.001328,0.010018,0.99
-54.283658,-0.011051,-0.002301,-0.140702,1.08
-54.285111,0.00273,-0.003338,0.034758,1.17
-54.28572,-0.005269,-0.004174,-0.067088,1.26
-54.286024,-0.00993,-0.005083,-0.126434,1.35
-54.286728,-0.005925,-0.005866,-0.075436,1.44
-54.289076,-0.017238,-0.006897,-0.219477,1.53
-54.287659,-0.019461,-0.007711,-0.247784,1.62
-54.289666,-0.02113,-0.008555,-0.269034,1.71
-54.293082,-0.034177,-0.009587,-0.435159,1.8
-54.291379,-0.033337,-0.009955,-0.424458,1.89
-54.2929,-0.042164,-0.011048,-0.536853,1.98
-54.294849,-0.057757,-0.011683,-0.735384,2.07
-54.293059,-0.057501,-0.012406,-0.73212,2.16
-54.295948,-0.070125,-0.013292,-0.892858,2.25
-54.297015,-0.082237,-0.014254,-1.047068,2.34
-54.29563,-0.078225,-0.014769,-0.995993,2.43
-54.297342,-0.091159,-0.015537,-1.160677,2.52
-54.299459,-0.100499,-0.016405,-1.279598,2.61
-54.299945,-0.101751,-0.017167,-1.295535,2.7
-54.300185,-0.11934,-0.018047,-1.519489,2.79
-54.302747,-0.124335,-0.01876,-1.583086,2.88
-54.304028,-0.135738,-0.019734,-1.728266,2.97
-54.30356,-0.147766,-0.020596,-1.881414,3.06
-54.302833,-0.153387,-0.021369,-1.952979,3.15
-54.305263,-0.15862,-0.021946,-2.019611,3.24
-54.307734,-0.180751,-0.023,-2.301394,3.33
-54.306853,-0.186342,-0.023879,-2.37258,3.42
-54.310382,-0.205892,-0.024813,-2.621502,3.51
-54.308742,-0.210029,-0.02529,-2.674171,3.6
-54.308697,-0.218499,-0.026181,-2.782012,3.69
-54.311272,-0.235099,-0.027024,-2.993368,3.78
-54.312144,-0.241578,-0.027882,-3.075862,3.87
-54.312435,-0.248522,-0.028516,-3.164275,3.96
-54.312589,-0.271493,-0.029412,-3.456759,4.05
-54.313153,-0.277925,-0.030342,-3.538645,4.14
-54.315419,-0.288737,-0.030812,-3.676311,4.23
-54.317872,-0.306004,-0.031722,-3.896168,4.32
-54.31625,-0.311989,-0.0326,-3.972362,4.41
-54.317654,-0.328493,-0.033263,-4.182504,4.5
-54.318571,-0.346124,-0.034331,-4.40699,4.59
-54.319416,-0.350231,-0.034799,-4.459279,4.68
-54.319607,-0.37207,-0.035749,-4.737343,4.77
-54.319747,-0.387532,-0.036581,-4.934205,4.86
-54.32205,-0.388467,-0.03743,-4.946119,4.95
-54.322018,-0.406617,-0.037895,-5.177207,5.04
-54.323744,-0.428557,-0.039188,-5.456562,5.13
-54.324612,-0.438541,-0.039804,-5.58368,5.22
-54.326515,-0.463003,-0.040891,-5.895136,5.31
-54.325784,-0.466031,-0.041482,-5.933689,5.4
-54.328463,-0.484306,-0.042122,-6.166371,5.49
-54.328109,-0.501889,-0.043049,-6.390249,5.58
-54.328609,-0.508845,-0.0439,-6.478814,5.67
-54.330789,-0.524211,-0.044406,-6.674461,5.76
-54.330948,-0.540483,-0.045321,-6.881643,5.85
-54.332392,-0.551677,-0.046034,-7.024167,5.94
-54.334413,-0.56774,-0.04662,-7.228693,6.03
-54.333768,-0.587785,-0.047623,-7.483914,6.12
-54.334454,-0.586957,-0.048254,-7.473365,6.21
-54.336984,-0.615829,-0.049193,-7.840981,6.3
-54.334186,-0.61897,-0.049582,-7.880976,6.39
-54.337075,-0.632709,-0.050475,-8.055905,6.48
-54.338106,-0.652218,-0.051229,-8.304296,6.57
-54.339209,-0.66765,-0.052028,-8.500778,6.66
-54.340349,-0.677627,-0.052848,-8.627819,6.75
-54.340763,-0.707155,-0.053731,-9.003783,6.84
-54.341294,-0.703597,-0.054306,-8.958476,6.93
-54.342757,-0.727826,-0.055303,-9.266973,7.02
-54.343324,-0.734836,-0.055726,-9.356221,7.11
-54.344033,-0.751507,-0.056673,-9.568488,7.2
-54.346031,-0.766927,-0.057393,-9.764818,7.29
-54.347326,-0.785297,-0.058137,-9.998714,7.38
-54.347162,-0.796074,-0.059159,-10.135925,7.47
-54.348779,-0.809473,-0.059611,-10.306528,7.56
-54.349987,-0.838667,-0.06075,-10.678242,7.65
-54.349924,-0.837642,-0.061229,-10.665189,7.74
-54.35284,-0.866091,-0.062152,-11.027416,7.83
-54.351386,-0.873524,-0.062717,-11.122052,7.92
-54.351504,-0.889695,-0.063724,-11.327945,8.01
-54.3564,-0.910622,-0.064423,-11.594398,8.1
-54.35536,-0.92864,-0.06519,-11.823816,8.19
-54.35402,-0.94372,-0.066068,-12.015821,8.28
-54.357736,-0.968492,-0.067119,-12.331224,8.37
-54.355724,-0.977582,-0.067711,-12.446957,8.46
-54.359493,-0.992423,-0.068374,-12.635926,8.55
-54.36037,-1.014602,-0.069167,-12.918316,8.64
-54.357304,-1.022387,-0.069796,-13.01743,8.73
-54.36101,-1.037824,-0.070289,-13.213988,8.82
-54.363222,-1.063985,-0.071248,-13.547073,8.91
-54.362169,-1.067162,-0.071896,-13.587523,9
-54.365007,-1.096398,-0.072882,-13.959768,9.09
-54.364885,-1.10873,-0.073579,-14.116787,9.18
-54.364762,-1.121598,-0.07435,-14.280635,9.27
-54.367437,-1.141328,-0.075144,-14.531835,9.36
-54.366806,-1.161355,-0.076114,-14.786828,9.45
-54.367678,-1.169074,-0.076602,-14.885107,9.54
-54.369158,-1.202059,-0.077534,-15.305088,9.63
-54.368595,-1.213616,-0.078341,-15.452241,9.72
-54.370476,-1.221061,-0.078937,-15.547028,9.81
-54.371956,-1.255918,-0.079895,-15.990839,9.9
-54.372728,-1.250756,-0.080286,-15.925117,9.99
-54.376153,-1.283985,-0.081466,-16.34821,10.08
-54.374327,-1.293486,-0.081982,-16.46918,10.17
-54.37475,-1.301265,-0.082632,-16.568218,10.26
-54.377457,-1.328576,-0.083413,-16.91595,10.35
-54.377052,-1.347685,-0.084174,-17.159257,10.44
-54.376557,-1.362038,-0.085105,-17.342002,10.53
-54.381045,-1.374876,-0.085409,-17.505471,10.62
-54.377516,-1.403171,-0.086618,-17.865726,10.71
-54.380445,-1.40357,-0.087196,-17.870811,10.8
-54.381712,-1.433104,-0.087967,-18.24685,10.89
-54.381045,-1.449865,-0.088828,-18.460256,10.98
-54.383152,-1.458365,-0.089279,-18.568476,11.07
-54.382998,-1.485503,-0.090207,-18.914008,11.16
-54.386313,-1.501298,-0.091344,-19.115119,11.25
-54.386127,-1.503587,-0.091622,-19.144261,11.34
-54.385228,-1.492506,-0.091521,-19.00318,11.43
-54.384896,-1.482564,-0.091395,-18.876594,11.52
-54.385477,-1.486951,-0.091645,-18.93245,11.61
-54.38501,-1.481563,-0.091522,-18.863844,11.7
-54.385541,-1.478899,-0.091591,-18.829921,11.79
-54.386708,-1.487404,-0.091723,-18.938217,11.88
-54.38421,-1.466334,-0.091481,-18.669943,11.97
-54.387272,-1.47292,-0.091668,-18.753802,12.06
-54.3854,-1.468807,-0.091591,-18.701437,12.15
-54.383434,-1.460552,-0.091603,-18.596328,12.24
-54.388952,-1.301825,-0.091739,-16.575351,0.05
-54.385441,-1.295465,-0.09176,-16.494376,0.14
-54.387399,-1.268291,-0.09138,-16.148389,0.23
-54.385973,-1.247931,-0.091048,-15.889145,0.32
-54.381512,-1.208311,-0.090641,-15.384698,0.41
-54.386218,-1.19828,-0.09048,-15.256973,0.5
-54.382416,-1.165062,-0.090041,-14.834033,0.59
-54.383275,-1.132107,-0.08965,-14.414431,0.68
-54.380822,-1.11621,-0.089455,-14.21203,0.77
-54.380336,-1.083636,-0.089141,-13.797286,0.86
-54.379355,-1.06082,-0.088836,-13.506775,0.95
-54.376739,-1.027298,-0.088491,-13.079964,1.04
-54.377874,-0.977087,-0.087811,-12.440658,1.13
-54.37385,-0.927848,-0.087198,-11.813723,1.22
-54.375917,-0.865096,-0.086383,-11.014743,1.31
-54.374023,-0.804979,-0.085507,-10.249306,1.4
-54.373728,-0.781858,-0.085289,-9.954925,1.49
-54.373855,-0.735766,-0.084516,-9.36806,1.58
-54.369699,-0.68211,-0.08387,-8.684889,1.67
-54.371275,-0.649911,-0.083076,-8.274926,1.76
-54.369367,-0.615609,-0.082705,-7.838173,1.85
-54.36904,-0.573504,-0.081996,-7.302079,1.94
-54.369994,-0.543743,-0.081405,-6.923156,2.03
-54.366738,-0.495899,-0.08072,-6.313979,2.12
-54.36691,-0.456107,-0.079904,-5.80733,2.21
-54.365062,-0.413519,-0.079185,-5.265089,2.3
-54.3631,-0.381666,-0.078567,-4.859528,2.39
-54.36503,-0.352097,-0.078,-4.483033,2.48
-54.363072,-0.315124,-0.077196,-4.012281,2.57
-54.363041,-0.276732,-0.076451,-3.523467,2.66
-54.359843,-0.247931,-0.075666,-3.156762,2.75
-54.359802,-0.221533,-0.075007,-2.82064,2.84
-54.360156,-0.204062,-0.074444,-2.598204,2.93
-54.356655,-0.167084,-0.073697,-2.127376,3.02
-54.357627,-0.149095,-0.072796,-1.898337,3.11
-54.357059,-0.12216,-0.072132,-1.555386,3.2
-54.3567,-0.100642,-0.071287,-1.281419,3.29
-54.356709,-0.106376,-0.071233,-1.354427,3.38
-54.35511,-0.098646,-0.071132,-1.255996,3.47
-54.357404,-0.10891,-0.071195,-1.38668,3.56
-54.355383,-0.10578,-0.071168,-1.346837,3.65
-54.356282,-0.10249,-0.071142,-1.304946,3.74
-54.355215,-0.106376,-0.071119,-1.354427,3.83
-54.354497,-0.100797,-0.07114,-1.283393,3.92
-54.355923,-0.107902,-0.071203,-1.373855,4.01
-54.354974,-0.10528,-0.071249,-1.340463,4.1
-54.356173,-0.100499,-0.070979,-1.279598,4.19
-54.356677,-0.108057,-0.071107,-1.375828,4.28
-54.35467,-0.101048,-0.071064,-1.28658,4.37
-54.357045,-0.090253,-0.070276,-1.149141,0.01
-54.359452,-0.122273,-0.071313,-1.556828,0.1
-54.360429,-0.13355,-0.071484,-1.700414,0.19
-54.359621,-0.142175,-0.071727,-1.810228,0.28
-54.358344,-0.15319,-0.072174,-1.950474,0.37
-54.36067,-0.177294,-0.07276,-2.257378,0.46
-54.363985,-0.207269,-0.073279,-2.639033,0.55
-54.363377,-0.229269,-0.073982,-2.919147,0.64
-54.364939,-0.270832,-0.074738,-3.448335,0.73
-54.365975,-0.324953,-0.075949,-4.137425,0.82
-54.366184,-0.346911,-0.076523,-4.417007,0.91
-54.36969,-0.393403,-0.077266,-5.008957,1
-54.370058,-0.427645,-0.077864,-5.444951,1.09
-54.370417,-0.469804,-0.078618,-5.981728,1.18
-54.373046,-0.496399,-0.07909,-6.320353,1.27
-54.371311,-0.541925,-0.079842,-6.900009,1.36
-54.371443,-0.570238,-0.080371,-7.260491,1.45
-54.372828,-0.605112,-0.080941,-7.704529,1.54
-54.375031,-0.649619,-0.081676,-8.271207,1.63
-54.374968,-0.677145,-0.082096,-8.621672,1.72
-54.377761,-0.731874,-0.082822,-9.318503,1.81
-54.376389,-0.768107,-0.083604,-9.779844,1.9
-54.376535,-0.80778,-0.08406,-10.284975,1.99
-54.379251,-0.843906,-0.084568,-10.74495,2.08
-54.379251,-0.881356,-0.085098,-11.221773,2.17
-54.382289,-0.930518,-0.085809,-11.847722,2.26
-54.38243,-0.967264,-0.086445,-12.31559,2.35
-54.381558,-1.01639,-0.087028,-12.941084,2.44
-54.38322,-1.05617,-0.08751,-13.44758,2.53
-54.384569,-1.087892,-0.088052,-13.851472,2.62
-54.385051,-1.140243,-0.088701,-14.518022,2.71
-54.384506,-1.177961,-0.089206,-14.998261,2.8
-54.387094,-1.231873,-0.089935,-15.684695,2.89
-54.388884,-1.267856,-0.090468,-16.142849,2.98
-54.386985,-1.300919,-0.091014,-16.563816,3.07
-54.390256,-1.347917,-0.091619,-17.162216,3.16
-54.390306,-1.396215,-0.092359,-17.777161,3.25
-54.390147,-1.408583,-0.092708,-17.934635,3.34
-54.393408,-1.462924,-0.093339,-18.626533,3.43
-54.39428,-1.507467,-0.094155,-19.193666,3.52
-54.39249,-1.516855,-0.094314,-19.313195,3.61
-54.39517,-1.555502,-0.095434,-19.805272,3.7
-54.396364,-1.577002,-0.09622,-20.079011,3.79
-54.396501,-1.586205,-0.096731,-20.196186,3.88
-54.396105,-1.597345,-0.097289,-20.338027,3.97
-54.399212,-1.636291,-0.098387,-20.833898,4.06
-54.3979,-1.639813,-0.098899,-20.87875,4.15
-54.400284,-1.654023,-0.099507,-21.059674,4.24
-54.402573,-1.695633,-0.100823,-21.589469,4.33
-54.401987,-1.693094,-0.101387,-21.557139,4.42
-54.402441,-1.715565,-0.102039,-21.843249,4.51
-54.404939,-1.748782,-0.103051,-22.266189,4.6
-54.404195,-1.760226,-0.103748,-22.4119,4.69
-54.406497,-1.768345,-0.104282,-22.515263,4.78
-54.407792,-1.799375,-0.105426,-22.910352,4.87
-54.407165,-1.806891,-0.10599,-23.00605,4.96
-54.407819,-1.81666,-0.10655,-23.130436,5.05
-54.410085,-1.857352,-0.107825,-23.648543,5.14
-54.409463,-1.860249,-0.108293,-23.685426,5.23
-54.409595,-1.893455,-0.109135,-24.108215,5.32
-54.412706,-1.897728,-0.109771,-24.162629,5.41
-54.411412,-1.912916,-0.110265,-24.355999,5.5
-54.413319,-1.932102,-0.111156,-24.600292,5.59
-54.415577,-1.949209,-0.111878,-24.818099,5.68
-54.416162,-1.958966,-0.112366,-24.942333,5.77
-54.41629,-1.98406,-0.1134,-25.261834,5.86
-54.417212,-2.020139,-0.114275,-25.721202,5.95
-54.418115,-2.021557,-0.114903,-25.739264,6.04
-54.418697,-2.045965,-0.115673,-26.050038,6.13
-54.421436,-2.059823,-0.116258,-26.226484,6.22
-54.419832,-2.077937,-0.117155,-26.457117,6.31
-54.421408,-2.098519,-0.118125,-26.719169,6.4
-54.424956,-2.119213,-0.1187,-26.982662,6.49
-54.423602,-2.13387,-0.119326,-27.169278,6.58
-54.42441,-2.151144,-0.120111,-27.38921,6.67
-54.425078,-2.182496,-0.120981,-27.788397,6.76
-54.425083,-2.188408,-0.121761,-27.863681,6.85
-54.427081,-2.209657,-0.122861,-28.134232,6.94
-54.429447,-2.231425,-0.123427,-28.411386,7.03
-54.428144,-2.239263,-0.124016,-28.511183,7.12
-54.429438,-2.271444,-0.125047,-28.920918,7.21
-54.43225,-2.295333,-0.125872,-29.225089,7.3
-54.43021,-2.301431,-0.126476,-29.302726,7.39
-54.431587,-2.31998,-0.12737,-29.538899,7.48
-54.434607,-2.343822,-0.128143,-29.842463,7.57
-54.433431,-2.360815,-0.128799,-30.058828,7.66
-54.434493,-2.372563,-0.129525,-30.208409,7.75
-54.436124,-2.396929,-0.13024,-30.518651,7.84
-54.436537,-2.414846,-0.130879,-30.74678,7.93
-54.437795,-2.418429,-0.131604,-30.79239,8.02
-54.437432,-2.453679,-0.132501,-31.241209,8.11
-54.439994,-2.462751,-0.133139,-31.356715,8.2
-54.439662,-2.487123,-0.133912,-31.667034,8.29
-54.443028,-2.475965,-0.13432,-31.524966,8.38
-54.440834,-2.465582,-0.134361,-31.392764,8.47
-54.441061,-2.453506,-0.134349,-31.239009,8.56
-54.441661,-2.463269,-0.134413,-31.363318,8.65
-54.441947,-2.460438,-0.134517,-31.32727,8.74
-54.439199,-2.451545,-0.134358,-31.21404,8.83
-54.442197,-2.446663,-0.134328,-31.151886,8.92
-54.440262,-2.453148,-0.13456,-31.234455,9.01
-54.441415,-2.443069,-0.134493,-31.106123,9.1
-54.441888,-2.444589,-0.134445,-31.125476,9.19
-54.441047,-2.445376,-0.134444,-31.135493,9.28
-54.44117,-2.435112,-0.134522,-31.004809,9.37
-54.442051,-2.436191,-0.134327,-31.018545,9.46
-54.441506,-2.446765,-0.134616,-31.153176,9.55
-54.440207,-2.438104,-0.134513,-31.042906,9.64
-54.441779,-2.433252,-0.134486,-30.981131,9.73
-54.44186,-2.443838,-0.134602,-31.115913,9.82
-54.439758,-2.437073,-0.134648,-31.029777,9.91
-54.441992,-2.434605,-0.134442,-30.998358,10
-54.440035,-2.440923,-0.134579,-31.078803,10.09
-54.440262,-2.433044,-0.134613,-30.978475,10.18
-54.440643,-2.428168,-0.134467,-30.916396,10.27
-54.444658,-2.427918,-0.136042,-30.913209,0.08
-54.442642,-2.41487,-0.136033,-30.747083,0.17
-54.440779,-2.377009,-0.135597,-30.265024,0.26
-54.440025,-2.344793,-0.135331,-29.854833,0.35
-54.438518,-2.30369,-0.134997,-29.331488,0.44
-54.439508,-2.290767,-0.134847,-29.166957,0.53
-54.436883,-2.24607,-0.134518,-28.59785,0.62
-54.436674,-2.218246,-0.134317,-28.243591,0.71
-54.437446,-2.190566,-0.133825,-27.891153,0.8
-54.43438,-2.168739,-0.133789,-27.613241,0.89
-54.431637,-2.129841,-0.133507,-27.117976,0.98
-54.431464,-2.089816,-0.133075,-26.608368,1.07
-54.433531,-2.056235,-0.132706,-26.180798,1.16
-54.431968,-1.995921,-0.132176,-25.412857,1.25
-54.429974,-1.900733,-0.131278,-24.200878,1.34
-54.428089,-1.832265,-0.130587,-23.329118,1.43
-54.428802,-1.78988,-0.130157,-22.789457,1.52
-54.427086,-1.738101,-0.129775,-22.130192,1.61
-54.42531,-1.658136,-0.128868,-21.112039,1.7
-54.424965,-1.601362,-0.128291,-20.389177,1.79
-54.423607,-1.561081,-0.128012,-19.876306,1.88
-54.423684,-1.508039,-0.127423,-19.200952,1.97
-54.420759,-1.44397,-0.126805,-18.3852,2.06
-54.421286,-1.378661,-0.125899,-17.553662,2.15
-54.421863,-1.335573,-0.125643,-17.005046,2.24
-54.417911,-1.292402,-0.125087,-16.455368,2.33
-54.417398,-1.233816,-0.124514,-15.709435,2.42
-54.41757,-1.18674,-0.123859,-15.110048,2.51
-54.416621,-1.148021,-0.123341,-14.61706,2.6
-54.416058,-1.088738,-0.122744,-13.862248,2.69
-54.41579,-1.053071,-0.122368,-13.408117,2.78
-54.415767,-1.023775,-0.121962,-13.035112,2.87
-54.413551,-0.955588,-0.121209,-12.16692,2.96
-54.411884,-0.910395,-0.120637,-11.591514,3.05
-54.411462,-0.872988,-0.12016,-11.115222,3.14
-54.410621,-0.827867,-0.119387,-10.540727,3.23
-54.410694,-0.791544,-0.118962,-10.078248,3.32
-54.409218,-0.750387,-0.118326,-9.55422,3.41
-54.406997,-0.70585,-0.117739,-8.987163,3.5
-54.40781,-0.666422,-0.117106,-8.485144,3.59
-54.408596,-0.622338,-0.116425,-7.923854,3.68
-54.404694,-0.576681,-0.115733,-7.342529,3.77
-54.403127,-0.528663,-0.115049,-6.731151,3.86
-54.403123,-0.512701,-0.114585,-6.527915,3.95
-54.40265,-0.469762,-0.113873,-5.981197,4.04
-54.400316,-0.414962,-0.112971,-5.283455,4.13
-54.399889,-0.391442,-0.112513,-4.983989,4.22
-54.40191,-0.361717,-0.111956,-4.605521,4.31
-54.399308,-0.327998,-0.111331,-4.176205,4.4
-54.396046,-0.296736,-0.110688,-3.778157,4.49
-54.396878,-0.26316,-0.110005,-3.350663,4.58
-54.396746,-0.252533,-0.109552,-3.215349,4.67
-54.396323,-0.217903,-0.108727,-2.774423,4.76
-54.39329,-0.186503,-0.108012,-2.374629,4.85
-54.392976,-0.15862,-0.107192,-2.019611,4.94
-54.392776,-0.144839,-0.106554,-1.844151,5.03
-54.392086,-0.127387,-0.105861,-1.621942,5.12
-54.391069,-0.093406,-0.104753,-1.189288,5.21
-54.390151,-0.088155,-0.104553,-1.122428,5.3
-54.391786,-0.097787,-0.104633,-1.245068,5.39
-54.391632,-0.097483,-0.104586,-1.241197,5.48
-54.390346,-0.093746,-0.104536,-1.193614,5.57
-54.389924,-0.090688,-0.104475,-1.154681,5.66
-54.390905,-0.097996,-0.104509,-1.247724,5.75
-54.391677,-0.100815,-0.104528,-1.28362,5.84
-54.388375,-0.093156,-0.104481,-1.1861,5.93
-54.389547,-0.110704,-0.104844,-1.409523,0.08
-54.39046,-0.119478,-0.104999,-1.521235,0.17
-54.392249,-0.143892,-0.105603,-1.832084,0.26
-54.391918,-0.155091,-0.105954,-1.974684,0.35
-54.392922,-0.168502,-0.106273,-2.145438,0.44
-54.395088,-0.189954,-0.106793,-2.41857,0.53
-54.395769,-0.209981,-0.107193,-2.673564,0.62
-54.396351,-0.231206,-0.107667,-2.943812,0.71
-54.397314,-0.244635,-0.107986,-3.114794,0.8
-54.397591,-0.260186,-0.10833,-3.312794,0.89
-54.39864,-0.293279,-0.108883,-3.73414,0.98
-54.401624,-0.344425,-0.109852,-4.385361,1.07
-54.400806,-0.395179,-0.110769,-5.031573,1.16
-54.401669,-0.432658,-0.11135,-5.508775,1.25
-54.403958,-0.473255,-0.112065,-6.025669,1.34
-54.402673,-0.506371,-0.112601,-6.447319,1.43
-54.40573,-0.575733,-0.113573,-7.330463,1.52
-54.407324,-0.607502,-0.114144,-7.734962,1.61
-54.407869,-0.646907,-0.114641,-8.236677,1.7
-54.408028,-0.685412,-0.115258,-8.726933,1.79
-54.407365,-0.748456,-0.116112,-9.529632,1.88
-54.410308,-0.774002,-0.11655,-9.8549,1.97
-54.410939,-0.821078,-0.117107,-10.454288,2.06
-54.410767,-0.871235,-0.117725,-11.09291,2.15
-54.412606,-0.925654,-0.118503,-11.785795,2.24
-54.412352,-0.938576,-0.118829,-11.950327,2.33
-54.412524,-0.976992,-0.119239,-12.439444,2.42
-54.41718,-1.044095,-0.11994,-13.293825,2.51
-54.415899,-1.081669,-0.120389,-13.772242,2.6
-54.416989,-1.122916,-0.120992,-14.297407,2.69
-54.417125,-1.171815,-0.121601,-14.920017,2.78
-54.418406,-1.217353,-0.122099,-15.499824,2.87
-54.418456,-1.26065,-0.122529,-16.051096,2.96
-54.421208,-1.305997,-0.123127,-16.628475,3.05
-54.421004,-1.360035,-0.123725,-17.316503,3.14
-54.420323,-1.418149,-0.124481,-18.05644,3.23
-54.421495,-1.441365,-0.12474,-18.352035,3.32
-54.423816,-1.510948,-0.125533,-19.237987,3.41
-54.426255,-1.559907,-0.125876,-19.861355,3.5
-54.425283,-1.613086,-0.126571,-20.538455,3.59
-54.426073,-1.667309,-0.12723,-21.228835,3.68
-54.425442,-1.694626,-0.127532,-21.576643,3.77
-54.428108,-1.766717,-0.128281,-22.494545,3.86
-54.428444,-1.800036,-0.128644,-22.918776,3.95
-54.430624,-1.860422,-0.129273,-23.687627,4.04
-54.431877,-1.901776,-0.129798,-24.214159,4.13
-54.430183,-1.950264,-0.130297,-24.831532,4.22
-54.429093,-1.997226,-0.130765,-25.429477,4.31
-54.433353,-2.05422,-0.131467,-26.155147,4.4
-54.434498,-2.076232,-0.131698,-26.435412,4.49
-54.437573,-2.141172,-0.132412,-27.262245,4.58
-54.437782,-2.182227,-0.132858,-27.784982,4.67
-54.437391,-2.229214,-0.133325,-28.383231,4.76
-54.438577,-2.27685,-0.133945,-28.989751,4.85
-54.43607,-2.31083,-0.134284,-29.422406,4.94
-54.439762,-2.36432,-0.135029,-30.103452,5.03
-54.442124,-2.40854,-0.13542,-30.666487,5.12
-54.441334,-2.439684,-0.136082,-31.063017,5.21
-54.441243,-2.488619,-0.136715,-31.686082,5.3
-54.443232,-2.516431,-0.137468,-32.04019,5.39
-54.444427,-2.544546,-0.137947,-32.398168,5.48
-54.446906,-2.579939,-0.139009,-32.848808,5.57
-54.445498,-2.614301,-0.139791,-33.28632,5.66
-54.447388,-2.618402,-0.140513,-33.338533,5.75
-54.446797,-2.645731,-0.141332,-33.686493,5.84
-54.448614,-2.638012,-0.141613,-33.588214,5.93
-54.450136,-2.6806,-0.142585,-34.130455,6.02
-54.452311,-2.696776,-0.143319,-34.336423,6.11
-54.452057,-2.718955,-0.144406,-34.618814,6.2
-54.45282,-2.717668,-0.144926,-34.602421,6.29
-54.452593,-2.742988,-0.145671,-34.924806,6.38
-54.454173,-2.75932,-0.146276,-35.132748,6.47
-54.456295,-2.783734,-0.147046,-35.443597,6.56
-54.457375,-2.817643,-0.148263,-35.875341,6.65
-54.457062,-2.805191,-0.14875,-35.716805,6.74
-54.457911,-2.838933,-0.149444,-36.146424,6.83
-54.45832,-2.85238,-0.150189,-36.317634,6.92
-54.460705,-2.874666,-0.15102,-36.60139,7.01
-54.462971,-2.887291,-0.151571,-36.762127,7.1
-54.463216,-2.917415,-0.152496,-37.14568,7.19
-54.460046,-2.93982,-0.15359,-37.430954,7.28
-54.464061,-2.931029,-0.153834,-37.319015,7.37
-54.464175,-2.960628,-0.154658,-37.69589,7.46
-54.466082,-2.990967,-0.15553,-38.082175,7.55
-54.466636,-3.006876,-0.156407,-38.284728,7.64
-54.467009,-3.032517,-0.157466,-38.611211,7.73
-54.465651,-3.011489,-0.157658,-38.343468,7.82
-54.468553,-3.061175,-0.158729,-38.976095,7.91
-54.469657,-3.068846,-0.159479,-39.073767,8
-54.47369,-3.110874,-0.160467,-39.608874,8.09
-54.472377,-3.101319,-0.160858,-39.487221,8.18
-54.47047,-3.121966,-0.161632,-39.750107,8.27
-54.473322,-3.136718,-0.162207,-39.937937,8.36
-54.47418,-3.154778,-0.163246,-40.167887,8.45
-54.477305,-3.178012,-0.163884,-40.46371,8.54
-54.476683,-3.196126,-0.164515,-40.694343,8.63
-54.476569,-3.218806,-0.165571,-40.983108,8.72
-54.477015,-3.220373,-0.166081,-41.003068,8.81
-54.478731,-3.258491,-0.167118,-41.48839,8.9
-54.48068,-3.264278,-0.167718,-41.562081,8.99
-54.481593,-3.299308,-0.168762,-42.008092,9.08
-54.481911,-3.310788,-0.16939,-42.154258,9.17
-54.482301,-3.328174,-0.170088,-42.375632,9.26
-54.483033,-3.34847,-0.170934,-42.634041,9.35
-54.483859,-3.352022,-0.171463,-42.679272,9.44
-54.485308,-3.388834,-0.172479,-43.147975,9.53
-54.485372,-3.399158,-0.173313,-43.279418,9.62
-54.486539,-3.41652,-0.174145,-43.500488,9.71
-54.48658,-3.426075,-0.174623,-43.622141,9.8
-54.489178,-3.447425,-0.175544,-43.893983,9.89
-54.4893,-3.469682,-0.176462,-44.17736,9.98
-54.490518,-3.478843,-0.176916,-44.294004,10.07
-54.4904,-3.511828,-0.178057,-44.713985,10.16
-54.491939,-3.483248,-0.178173,-44.350088,10.25
-54.49064,-3.469914,-0.178028,-44.18032,10.34
-54.492035,-3.465378,-0.178219,-44.122567,10.43
-54.492725,-3.464276,-0.178221,-44.108527,10.52
-54.492402,-3.459686,-0.178242,-44.050091,10.61
-54.489718,-3.454548,-0.178392,-43.984673,10.7
-54.490141,-3.429317,-0.180009,-43.663426,0.06
-54.490091,-3.39449,-0.179788,-43.219995,0.15
-54.490445,-3.352988,-0.179484,-42.691566,0.24
-54.488169,-3.316879,-0.179223,-42.231819,0.33
-54.487356,-3.276402,-0.178843,-41.716443,0.42
-54.487279,-3.25036,-0.178548,-41.384875,0.51
-54.485948,-3.233469,-0.178382,-41.1698,0.6
-54.486571,-3.194189,-0.178338,-40.669678,0.69
-54.484372,-3.14061,-0.177773,-39.987494,0.78
-54.485594,-3.122836,-0.17771,-39.761187,0.87
-54.48455,-3.09239,-0.177488,-39.373536,0.96
-54.481765,-3.046417,-0.177119,-38.788189,1.05
-54.481388,-2.993184,-0.176754,-38.110407,1.14
-54.479013,-2.918297,-0.176119,-37.156912,1.23
-54.4784,-2.804738,-0.175307,-35.711037,1.32
-54.477296,-2.755016,-0.174844,-35.077954,1.41
-54.477759,-2.674049,-0.17425,-34.047051,1.5
-54.477128,-2.605456,-0.173655,-33.173698,1.59
-54.477083,-2.558368,-0.173241,-32.574159,1.68
-54.474803,-2.502358,-0.172885,-31.861011,1.77
-54.475579,-2.441216,-0.17246,-31.082521,1.86
-54.473731,-2.36761,-0.171793,-30.145343,1.95
-54.471128,-2.301538,-0.171124,-29.304092,2.04
-54.469234,-2.245468,-0.170806,-28.590185,2.13
-54.468567,-2.189177,-0.170141,-27.873471,2.22
-54.467518,-2.148438,-0.169775,-27.354756,2.31
-54.467363,-2.081257,-0.169228,-26.499388,2.4
-54.468621,-2.032989,-0.168894,-25.884823,2.49
-54.466941,-1.97857,-0.168488,-25.191938,2.58
-54.466196,-1.920694,-0.167932,-24.455037,2.67
-54.464606,-1.853192,-0.167341,-23.595572,2.76
-54.463321,-1.811939,-0.166872,-23.07033,2.85
-54.464384,-1.742977,-0.166301,-22.192271,2.94
-54.461227,-1.686966,-0.165619,-21.479124,3.03
-54.457566,-1.628631,-0.165181,-20.736378,3.12
-54.460001,-1.582646,-0.164653,-20.150879,3.21
-54.459274,-1.523644,-0.164173,-19.399635,3.3
-54.459701,-1.454729,-0.163543,-18.522183,3.39
-54.456762,-1.428008,-0.163182,-18.181964,3.48
-54.456122,-1.378095,-0.162705,-17.546452,3.57
-54.456158,-1.325464,-0.16212,-16.876335,3.66
-54.455718,-1.273674,-0.161676,-16.216918,3.75
-54.454564,-1.231992,-0.161187,-15.686212,3.84
-54.453433,-1.171756,-0.160808,-14.919258,3.93
-54.45183,-1.129335,-0.160036,-14.379142,4.02
-54.449577,-1.08217,-0.159473,-13.778617,4.11
-54.448691,-1.040167,-0.158918,-13.243813,4.2
-54.449736,-0.993633,-0.158539,-12.651332,4.29
-54.44876,-0.948632,-0.157931,-12.078355,4.38
-54.447238,-0.916648,-0.157477,-11.671124,4.47
-54.447806,-0.868171,-0.156987,-11.053902,4.56
-54.44504,-0.822657,-0.156357,-10.474399,4.65
-54.444645,-0.768435,-0.155623,-9.784018,4.74
-54.444277,-0.745863,-0.1553,-9.496619,4.83
-54.442237,-0.675952,-0.154379,-8.606494,4.92
-54.442301,-0.624704,-0.153638,-7.953983,5.01
-54.441747,-0.594783,-0.153127,-7.57301,5.1
-54.440393,-0.54673,-0.152494,-6.961177,5.19
-54.439744,-0.527352,-0.151964,-6.714455,5.28
-54.437259,-0.484455,-0.151285,-6.168268,5.37
-54.440657,-0.453508,-0.150756,-5.774242,5.46
-54.43993,-0.416011,-0.150152,-5.296812,5.55
-54.435611,-0.388807,-0.149616,-4.950445,5.64
-54.435865,-0.351709,-0.148883,-4.4781,5.73
-54.433394,-0.311118,-0.148091,-3.961282,5.82
-54.433621,-0.288796,-0.147713,-3.67707,5.91
-54.430578,-0.247604,-0.146786,-3.152588,6
-54.430787,-0.224936,-0.146043,-2.863974,6.09
-54.429652,-0.192791,-0.145447,-2.454694,6.18
-54.429388,-0.172371,-0.144754,-2.194692,6.27
-54.427018,-0.150371,-0.144107,-1.914578,6.36
-54.429166,-0.135165,-0.143615,-1.72098,6.45
-54.425755,-0.109267,-0.142672,-1.391234,6.54
-54.425269,-0.11192,-0.142462,-1.425005,6.63
-54.427758,-0.114202,-0.142564,-1.454071,6.72
-54.425396,-0.112933,-0.142522,-1.437907,6.81
-54.426436,-0.109065,-0.142507,-1.388653,6.9
-54.42645,-0.111401,-0.142583,-1.418403,6.99
-54.425151,-0.111169,-0.142612,-1.415443,7.08
-54.425805,-0.163519,-0.143466,-2.081993,0.03
-54.427508,-0.159144,-0.14361,-2.026289,0.12
-54.427903,-0.179315,-0.143964,-2.283105,0.21
-54.429384,-0.20197,-0.14438,-2.571566,0.3
-54.431569,-0.223732,-0.144806,-2.848644,0.39
-54.431755,-0.242865,-0.145271,-3.092254,0.48
-54.432173,-0.266314,-0.145578,-3.390809,0.57
-54.433444,-0.288552,-0.146039,-3.673959,0.66
-54.432627,-0.324458,-0.146696,-4.131126,0.75
-54.434525,-0.366426,-0.147383,-4.665475,0.84
-54.436356,-0.39869,-0.147885,-5.076272,0.93
-54.43859,-0.471741,-0.149033,-6.006392,1.02
-54.437319,-0.493467,-0.149317,-6.283015,1.11
-54.439612,-0.538421,-0.150052,-6.855385,1.2
-54.44062,-0.587529,-0.150669,-7.480651,1.29
-54.441243,-0.614935,-0.151056,-7.829598,1.38
-54.441938,-0.663793,-0.151713,-8.451676,1.47
-54.442714,-0.723767,-0.15247,-9.215291,1.56
-54.443754,-0.771058,-0.153119,-9.81741,1.65
-54.444345,-0.82072,-0.153782,-10.449734,1.74
-54.445376,-0.878656,-0.154448,-11.187395,1.83
-54.446965,-0.903571,-0.154843,-11.504619,1.92
-54.447233,-0.961012,-0.155362,-12.23598,2.01
-54.448696,-0.993478,-0.155898,-12.649359,2.1
-54.449977,-1.047415,-0.156539,-13.336096,2.19
-54.450149,-1.092768,-0.156955,-13.913551,2.28
-54.452575,-1.152468,-0.157708,-14.673675,2.37
-54.45332,-1.172012,-0.15786,-14.922521,2.46
-54.45381,-1.237923,-0.158581,-15.761724,2.55
-54.455086,-1.292431,-0.159161,-16.455747,2.64
-54.455432,-1.344758,-0.159706,-17.121994,2.73
-54.457176,-1.402563,-0.160386,-17.857985,2.82
-54.456081,-1.432395,-0.160607,-18.237819,2.91
-54.458406,-1.500303,-0.16137,-19.102445,3
-54.457843,-1.529759,-0.161549,-19.477499,3.09
-54.45916,-1.591092,-0.162155,-20.258417,3.18
-54.460191,-1.653069,-0.162734,-21.047531,3.27
-54.460877,-1.701444,-0.163253,-21.663463,3.36
-54.461227,-1.742625,-0.163609,-22.187794,3.45
-54.464179,-1.7802,-0.164075,-22.66621,3.54
-54.464184,-1.859319,-0.164818,-23.673587,3.63
-54.464238,-1.901448,-0.165078,-24.209985,3.72
-54.464593,-1.949459,-0.165495,-24.821287,3.81
-54.467281,-2.003998,-0.166098,-25.515689,3.9
-54.467449,-2.054822,-0.166532,-26.162812,3.99
-54.466441,-2.111238,-0.167105,-26.88112,4.08
-54.469507,-2.167594,-0.167678,-27.598669,4.17
-54.469507,-2.217078,-0.16811,-28.228716,4.26
-54.467695,-2.264994,-0.168524,-28.838804,4.35
-54.47086,-2.324992,-0.169024,-29.602723,4.44
-54.472804,-2.37487,-0.16956,-30.237779,4.53
-54.473377,-2.443379,-0.17031,-31.11007,4.62
-54.47379,-2.484655,-0.170435,-31.635615,4.71
-54.473708,-2.527827,-0.171029,-32.185293,4.8
-54.475261,-2.579331,-0.1714,-32.841067,4.89
-54.475666,-2.620584,-0.171777,-33.366309,4.98
-54.476915,-2.690482,-0.172564,-34.256283,5.07
-54.477723,-2.744734,-0.172929,-34.947042,5.16
-54.477646,-2.829343,-0.173683,-36.024315,5.25
-54.479122,-2.85961,-0.174124,-36.409689,5.34
-54.479958,-2.938199,-0.174668,-37.410312,5.43
-54.480489,-2.995819,-0.175257,-38.14395,5.52
-54.481043,-3.0191,-0.175613,-38.440381,5.61
-54.483682,-3.092593,-0.176252,-39.376116,5.7
-54.485567,-3.126025,-0.176524,-39.801789,5.79
-54.48251,-3.197014,-0.177326,-40.705651,5.88
-54.4844,-3.245455,-0.177698,-41.322417,5.97
-54.486244,-3.293753,-0.17827,-41.937362,6.06
-54.486593,-3.336328,-0.178757,-42.479451,6.15
-54.487588,-3.372031,-0.179148,-42.934038,6.24
-54.489073,-3.421199,-0.179612,-43.560063,6.33
-54.490931,-3.457451,-0.180235,-44.021632,6.42
-54.49218,-3.515863,-0.181226,-44.765363,6.51
-54.493533,-3.544873,-0.181633,-45.134725,6.6
-54.493334,-3.575706,-0.18246,-45.527309,6.69
-54.495173,-3.591096,-0.182945,-45.723259,6.78
-54.496463,-3.640163,-0.184068,-46.347994,6.87
-54.496985,-3.634077,-0.184471,-46.270509,6.96
-54.49748,-3.667974,-0.185405,-46.702101,7.05
-54.497249,-3.670937,-0.185801,-46.739819,7.14
-54.499842,-3.7148,-0.18684,-47.298301,7.23
-54.499724,-3.711432,-0.187412,-47.255423,7.32
-54.502517,-3.73925,-0.188301,-47.609606,7.41
-54.503085,-3.748792,-0.188816,-47.731107,7.5
-54.503239,-3.781235,-0.189584,-48.144182,7.59
-54.503925,-3.791106,-0.190716,-48.269858,7.68
-54.505842,-3.797573,-0.1912,-48.352199,7.77
-54.506546,-3.829193,-0.191969,-48.754801,7.86
-54.507086,-3.843659,-0.192872,-48.938988,7.95
-54.507309,-3.847098,-0.193435,-48.982778,8.04
-54.510084,-3.892022,-0.194602,-49.554768,8.13
-54.508944,-3.880817,-0.195124,-49.412093,8.22
-54.511233,-3.916085,-0.195993,-49.86114,8.31
-54.512341,-3.924561,-0.196847,-49.969057,8.4
-54.512005,-3.948677,-0.197439,-50.276112,8.49
-54.513754,-3.95934,-0.198171,-50.411881,8.58
-54.515321,-3.98286,-0.199169,-50.711347,8.67
-54.51374,-3.995717,-0.19968,-50.875043,8.76
-54.518014,-4.020107,-0.200558,-51.185589,8.85
-54.517578,-4.007638,-0.201018,-51.026825,8.94
-54.517151,-4.043341,-0.201758,-51.481413,9.03
-54.518863,-4.057288,-0.202692,-51.658997,9.12
-54.518827,-4.071766,-0.203451,-51.843337,9.21
-54.520994,-4.07455,-0.204192,-51.878778,9.3
-54.520508,-4.102856,-0.20471,-52.239184,9.39
-54.522111,-4.126972,-0.205732,-52.546239,9.48
-54.523555,-4.151934,-0.206732,-52.86407,9.57
-54.523001,-4.1587,-0.207494,-52.950207,9.66
-54.52425,-4.17763,-0.208406,-53.191237,9.75
-54.524704,-4.201353,-0.209079,-53.493283,9.84
-54.525354,-4.19907,-0.209693,-53.464216,9.93
-54.529037,-4.217297,-0.210369,-53.696291,10.02
-54.527348,-4.239696,-0.210996,-53.981489,10.11
-54.527334,-4.248106,-0.211677,-54.088572,10.2
-54.529287,-4.281116,-0.212734,-54.508856,10.29
-54.529769,-4.281151,-0.213325,-54.509311,10.38
-54.528783,-4.318678,-0.214251,-54.987121,10.47
-54.531395,-4.325181,-0.215026,-55.069918,10.56
-54.533166,-4.354244,-0.215829,-55.439962,10.65
-54.534915,-4.373753,-0.216923,-55.688354,10.74
-54.535051,-4.387289,-0.217523,-55.860702,10.83
-54.536145,-4.390162,-0.218183,-55.897282,10.92
-54.536709,-4.419935,-0.219002,-56.276357,11.01
-54.537758,-4.445249,-0.219823,-56.598666,11.1
-54.539761,-4.451072,-0.220683,-56.672812,11.19
-54.539475,-4.475296,-0.221592,-56.981233,11.28
-54.542122,-4.474384,-0.222011,-56.969621,11.37
-54.544439,-4.5735,-0.225919,-58.231613,11.46
-54.54448,-4.519057,-0.226021,-57.538424,11.55
-54.546832,-4.499501,-0.226026,-57.289426,11.64
-54.543453,-4.48783,-0.225985,-57.140831,11.73
-54.546424,-4.481411,-0.22601,-57.059097,11.82
-54.545515,-4.476792,-0.226126,-57.000281,11.91
-54.464066,-0.075185,-0.183199,-0.957289,0.03
-54.46378,-0.085533,-0.183365,-1.089036,0.12
-54.465869,-0.085276,-0.183462,-1.085772,0.21
-54.464107,-0.093663,-0.183695,-1.192551,0.3
-54.465324,-0.103635,-0.184018,-1.319517,0.39
-54.465306,-0.122243,-0.184391,-1.556448,0.48
-54.468503,-0.141037,-0.185002,-1.795733,0.57
-54.469184,-0.151837,-0.1852,-1.933247,0.66
-54.468653,-0.171363,-0.185693,-2.181866,0.75
-54.470002,-0.207317,-0.186335,-2.63964,0.84
-54.471265,-0.246495,-0.187129,-3.138472,0.93
-54.474367,-0.287616,-0.187833,-3.662044,1.02
-54.475584,-0.320745,-0.188583,-4.083846,1.11
-54.473449,-0.354129,-0.189023,-4.508911,1.2
-54.474757,-0.39953,-0.189739,-5.086973,1.29
-54.477387,-0.45408,-0.190424,-5.781527,1.38
-54.477532,-0.480741,-0.190949,-6.120988,1.47
-54.479249,-0.540417,-0.191735,-6.880808,1.56
-54.478323,-0.590968,-0.192441,-7.52444,1.65
-54.480194,-0.625706,-0.192829,-7.966733,1.74
-54.480934,-0.678605,-0.193559,-8.640265,1.83
-54.482678,-0.723851,-0.194069,-9.216354,1.92
-54.481616,-0.764269,-0.194679,-9.730971,2.01
-54.483841,-0.846016,-0.195602,-10.771815,2.1
-54.486312,-0.854468,-0.195693,-10.879429,2.19
-54.486375,-0.929487,-0.196527,-11.834593,2.28
-54.48574,-0.960928,-0.19706,-12.234918,2.37
-54.485803,-1.010406,-0.197596,-12.864889,2.46
-54.49059,-1.070136,-0.198079,-13.625393,2.55
-54.491444,-1.130629,-0.198763,-14.39561,2.64
-54.488728,-1.143783,-0.198969,-14.563102,2.73
-54.490686,-1.213282,-0.199673,-15.447991,2.82
-54.492298,-1.274103,-0.200304,-16.222382,2.91
-54.493938,-1.325637,-0.200839,-16.878536,3
-54.494492,-1.360655,-0.201093,-17.324395,3.09
-54.494147,-1.411134,-0.201617,-17.967116,3.18
-54.496735,-1.493335,-0.202468,-19.013729,3.27
-54.495854,-1.518947,-0.202687,-19.339832,3.36
-54.497984,-1.571894,-0.203131,-20.013972,3.45
-54.49728,-1.617986,-0.203513,-20.600837,3.54
-54.498956,-1.675957,-0.20418,-21.338953,3.63
-54.499279,-1.738673,-0.204747,-22.137478,3.72
-54.501736,-1.781762,-0.20504,-22.686094,3.81
-54.501532,-1.839715,-0.20551,-23.423982,3.9
-54.502199,-1.880538,-0.205947,-23.943759,3.99
-54.504111,-1.945275,-0.206633,-24.768011,4.08
-54.504261,-1.986641,-0.206874,-25.294695,4.17
-54.505483,-2.057225,-0.207341,-26.193396,4.26
-54.504384,-2.109319,-0.207882,-26.856683,4.35
-54.507168,-2.182168,-0.208639,-27.784223,4.44
-54.508708,-2.216971,-0.20899,-28.22735,4.53
-54.508603,-2.2964,-0.209462,-29.238674,4.62
-54.508644,-2.338254,-0.209875,-29.77158,4.71
-54.510048,-2.424544,-0.210619,-30.870254,4.8
-54.511324,-2.449912,-0.210828,-31.193246,4.89
-54.512028,-2.529424,-0.211412,-32.205632,4.98
-54.511551,-2.584797,-0.211904,-32.910659,5.07
-54.514095,-2.626449,-0.212223,-33.440986,5.16
-54.516356,-2.693284,-0.212695,-34.291951,5.25
-54.515707,-2.74049,-0.213108,-34.893008,5.34
-54.515348,-2.789587,-0.213533,-35.518122,5.43
-54.516624,-2.85815,-0.214031,-36.391096,5.52
-54.517596,-2.90702,-0.214571,-37.013326,5.61
-54.519422,-2.966094,-0.214964,-37.765482,5.7
-54.518968,-3.002101,-0.215131,-38.223939,5.79
-54.520598,-3.106731,-0.216117,-39.55613,5.88
-54.52257,-3.160405,-0.216662,-40.239528,5.97
-54.523315,-3.231549,-0.217112,-41.145363,6.06
-54.523869,-3.281122,-0.217557,-41.776548,6.15
-54.524128,-3.341401,-0.217965,-42.544034,6.24
-54.524291,-3.398257,-0.218478,-43.267958,6.33
-54.527734,-3.46002,-0.219075,-44.054341,6.42
-54.526862,-3.50104,-0.219196,-44.576622,6.51
-54.528438,-3.552377,-0.219749,-45.230272,6.6
-54.527961,-3.618467,-0.220216,-46.071751,6.69
-54.529964,-3.674644,-0.220682,-46.787023,6.78
-54.531031,-3.731328,-0.221143,-47.508747,6.87
-54.529905,-3.780252,-0.221488,-48.13166,6.96
-54.534206,-3.870565,-0.222367,-49.28156,7.05
-54.53496,-3.90439,-0.22249,-49.712242,7.14
-54.53387,-3.9702,-0.223146,-50.550154,7.23
-54.534633,-4.034722,-0.223568,-51.371674,7.32
-54.535718,-4.1013,-0.224236,-52.219376,7.41
-54.538271,-4.15557,-0.224726,-52.910364,7.5
-54.539747,-4.207605,-0.225075,-53.572892,7.59
-54.537272,-4.22399,-0.225305,-53.781517,7.68
-54.539806,-4.291946,-0.225851,-54.64675,7.77
-54.541546,-4.371178,-0.226563,-55.655569,7.86
-54.543562,-4.419488,-0.227197,-56.270665,7.95
-54.542649,-4.44721,-0.227553,-56.623634,8.04
-54.542985,-4.477185,-0.228135,-57.00529,8.13
-54.542858,-4.529673,-0.228846,-57.673586,8.22
-54.546296,-4.577106,-0.229459,-58.277527,8.31
-54.548731,-4.583609,-0.230069,-58.360324,8.4
-54.546569,-4.622656,-0.230578,-58.857486,8.49
-54.548454,-4.669446,-0.231465,-59.45323,8.58
-54.548713,-4.667467,-0.232116,-59.428034,8.67
-54.550748,-4.687077,-0.232607,-59.677715,8.76
-54.55092,-4.725134,-0.233445,-60.162279,8.85
-54.551215,-4.735011,-0.234273,-60.288031,8.94
-54.55221,-4.748213,-0.234922,-60.456129,9.03
-54.554295,-4.778403,-0.235888,-60.840517,9.12
-54.552823,-4.762149,-0.236253,-60.633562,9.21
-54.555144,-4.822022,-0.237692,-61.395887,9.3
-54.556425,-4.806376,-0.238162,-61.196674,9.39
-54.556593,-4.860616,-0.239051,-61.887282,9.48
-54.557429,-4.846364,-0.239907,-61.705826,9.57
-54.55974,-4.880512,-0.240906,-62.140606,9.66
-54.560231,-4.904693,-0.241605,-62.448495,9.75
-54.56208,-4.909658,-0.242433,-62.511713,9.84
-54.561185,-4.913276,-0.243081,-62.557778,9.93
-54.561603,-4.939741,-0.243834,-62.894734,10.02
-54.564537,-4.9591,-0.244486,-63.141228,10.11
-54.564355,-4.97753,-0.2455,-63.375883,10.2
-54.565831,-4.977661,-0.246028,-63.377553,10.29
-54.566953,-4.993325,-0.246718,-63.576995,10.38
-54.56877,-5.038452,-0.247762,-64.151565,10.47
-54.568951,-5.036837,-0.248515,-64.130999,10.56
-54.569633,-5.05532,-0.249478,-64.366337,10.65
-54.569151,-5.045915,-0.249896,-64.246581,10.74
-54.570437,-5.082148,-0.25072,-64.707922,10.83
-54.572571,-5.089921,-0.251308,-64.806884,10.92
-54.57243,-5.115461,-0.252071,-65.132077,11.01
-54.57293,-5.115151,-0.252887,-65.12813,11.1
-54.571845,-5.151081,-0.253793,-65.585601,11.19
-54.576227,-5.15371,-0.254389,-65.619069,11.28
-54.576209,-5.173272,-0.255091,-65.868144,11.37
-54.577822,-5.174804,-0.255775,-65.887648,11.46
-54.579811,-5.206406,-0.256509,-66.290022,11.55
-54.580792,-5.217093,-0.257341,-66.426094,11.64
-54.579956,-5.237204,-0.25794,-66.68215,11.73
-54.582027,-5.244988,-0.258657,-66.781264,11.82
-54.581791,-5.264175,-0.259715,-67.025557,11.91
-54.583236,-5.280066,-0.260219,-67.227882,12
-54.583931,-5.293131,-0.261013,-67.394235,12.09
-54.583758,-5.32313,-0.261978,-67.776195,12.18
-54.584884,-5.323219,-0.26267,-67.777333,12.27
-54.587873,-5.356723,-0.26361,-68.203916,12.36
-54.588881,-5.362403,-0.264169,-68.276241,12.45
-54.586787,-5.376607,-0.265116,-68.457089,12.54
-54.587982,-5.404764,-0.265982,-68.815598,12.63
-54.590598,-5.421984,-0.266866,-69.034847,12.72
-54.589758,-5.419832,-0.267353,-69.00745,12.81
-54.591425,-5.447817,-0.268251,-69.363758,12.9
-54.593323,-5.46211,-0.269097,-69.545745,12.99
-54.593287,-5.472648,-0.269609,-69.67992,13.08
-54.596443,-5.533278,-0.271374,-70.451883,13.17
-54.595362,-5.484861,-0.271826,-69.835421,13.26
-54.595276,-5.469197,-0.271871,-69.635979,13.35
-54.595226,-5.456775,-0.272037,-69.477823,13.44
-54.59479,-5.444962,-0.271988,-69.327407,13.53
-54.594708,-5.435222,-0.272103,-69.203401,13.62
-54.596026,-5.432278,-0.272238,-69.165911,13.71
-54.596607,-5.432397,-0.272186,-69.167428,13.8
-54.594577,-5.299067,-0.273429,-67.469823,0.05
-54.591956,-5.260491,-0.273164,-66.978656,0.14
-54.595244,-5.224061,-0.27295,-66.514811,0.23
-54.590916,-5.168831,-0.272579,-65.811605,0.32
-54.590671,-5.144978,-0.272621,-65.507889,0.41
-54.58974,-5.10475,-0.272337,-64.995701,0.5
-54.588522,-5.054796,-0.271895,-64.359658,0.59
-54.587346,-5.029082,-0.272044,-64.032265,0.68
-54.586996,-4.976511,-0.271505,-63.362906,0.77
-54.584553,-4.932666,-0.271235,-62.804652,0.86
-54.585434,-4.901999,-0.271198,-62.414193,0.95
-54.583967,-4.852325,-0.270827,-61.781717,1.04
-54.583145,-4.770625,-0.270265,-60.741479,1.13
-54.584594,-4.630029,-0.269519,-58.951363,1.22
-54.5818,-4.530472,-0.268897,-57.683756,1.31
-54.579584,-4.42757,-0.268273,-56.373573,1.4
-54.579993,-4.365844,-0.268042,-55.587646,1.49
-54.577785,-4.287869,-0.26742,-54.59484,1.58
-54.577236,-4.227889,-0.267056,-53.831149,1.67
-54.578008,-4.161942,-0.266785,-52.991491,1.76
-54.57511,-4.096198,-0.266219,-52.154414,1.85
-54.575069,-4.01035,-0.265672,-51.061356,1.94
-54.574515,-3.951591,-0.265323,-50.313222,2.03
-54.57219,-3.902006,-0.26509,-49.681885,2.12
-54.571745,-3.838927,-0.264622,-48.878731,2.21
-54.57328,-3.792769,-0.26427,-48.291031,2.3
-54.570123,-3.71415,-0.263771,-47.290029,2.39
-54.568429,-3.660417,-0.263575,-46.605872,2.48
-54.569814,-3.592408,-0.263055,-45.739955,2.57
-54.567389,-3.512698,-0.262433,-44.725065,2.66
-54.566185,-3.466684,-0.262194,-44.139187,2.75
-54.567375,-3.402728,-0.261544,-43.324876,2.84
-54.562166,-3.31561,-0.261149,-42.215654,2.93
-54.563002,-3.273851,-0.261017,-41.683961,3.02
-54.563946,-3.203028,-0.260405,-40.782225,3.11
-54.560444,-3.151691,-0.259846,-40.128576,3.2
-54.56193,-3.067601,-0.259393,-39.057906,3.29
-54.560476,-3.028381,-0.259121,-38.558543,3.38
-54.557519,-2.929956,-0.258332,-37.305355,3.47
-54.55856,-2.896357,-0.258134,-36.877557,3.56
-54.557896,-2.818835,-0.257588,-35.890519,3.65
-54.557538,-2.738017,-0.257193,-34.861513,3.74
-54.557533,-2.691579,-0.256715,-34.270246,3.83
-54.554463,-2.625233,-0.256195,-33.425504,3.92
-54.552841,-2.56142,-0.255768,-32.613015,4.01
-54.553804,-2.516311,-0.255406,-32.038672,4.1
-54.55345,-2.437603,-0.254826,-31.036531,4.19
-54.551452,-2.3817,-0.254429,-30.32475,4.28
-54.552246,-2.348536,-0.254191,-29.902492,4.37
-54.551088,-2.263516,-0.253379,-28.819983,4.46
-54.549598,-2.236617,-0.253379,-28.477487,4.55
-54.547918,-2.159941,-0.252575,-27.501225,4.64
-54.54557,-2.1074,-0.25227,-26.832246,4.73
-54.546919,-2.047837,-0.251816,-26.073868,4.82
-54.546751,-1.979667,-0.251224,-25.205902,4.91
-54.544194,-1.924485,-0.250724,-24.503304,5
-54.54482,-1.902217,-0.250569,-24.219775,5.09
-54.543699,-1.808405,-0.249757,-23.025327,5.18
-54.542109,-1.768851,-0.249486,-22.521714,5.27
-54.541468,-1.711565,-0.248971,-21.792326,5.36
-54.540251,-1.652569,-0.248446,-21.041157,5.45
-54.538089,-1.595998,-0.247802,-20.320875,5.54
-54.539584,-1.55794,-0.247549,-19.836311,5.63
-54.537322,-1.48859,-0.246754,-18.95332,5.72
-54.536268,-1.419461,-0.246264,-18.073136,5.81
-54.535446,-1.385128,-0.245716,-17.636004,5.9
-54.533143,-1.329255,-0.245259,-16.924602,5.99
-54.534111,-1.276726,-0.24492,-16.255774,6.08
-54.532294,-1.230735,-0.244256,-15.670199,6.17
-54.531817,-1.18264,-0.243795,-15.057835,6.26
-54.530159,-1.148772,-0.24341,-14.626622,6.35
-54.531186,-1.09486,-0.242775,-13.940188,6.44
-54.529305,-1.047397,-0.242424,-13.335868,6.53
-54.530123,-0.9942,-0.241798,-12.658541,6.62
-54.528111,-0.945175,-0.241068,-12.034338,6.71
-54.524695,-0.897366,-0.240674,-11.425616,6.8
-54.524586,-0.873274,-0.24034,-11.118865,6.89
-54.524432,-0.80092,-0.23941,-10.197624,6.98
-54.523546,-0.76527,-0.238999,-9.74372,7.07
-54.522847,-0.722271,-0.238387,-9.196243,7.16
-54.521166,-0.691599,-0.238041,-8.805708,7.25
-54.521961,-0.636905,-0.237292,-8.109332,7.34
-54.520549,-0.583684,-0.236503,-7.431701,7.43
-54.517324,-0.541383,-0.235979,-6.893103,7.52
-54.520994,-0.497115,-0.235272,-6.32946,7.61
-54.516175,-0.457203,-0.234589,-5.821294,7.7
-54.516565,-0.432444,-0.23413,-5.506043,7.79
-54.517496,-0.399607,-0.233601,-5.08796,7.88
-54.514326,-0.35376,-0.232776,-4.504206,7.97
-54.513645,-0.319666,-0.232198,-4.07011,8.06
-54.512873,-0.307912,-0.231887,-3.920453,8.15
-54.510965,-0.247937,-0.230901,-3.156838,8.24
-54.510202,-0.232017,-0.230439,-2.954133,8.33
-54.510802,-0.210959,-0.229883,-2.68601,8.42
-54.507191,-0.176764,-0.229069,-2.250623,8.51
-54.50928,-0.162077,-0.228612,-2.063628,8.6
-54.510202,-0.130922,-0.227686,-1.666946,8.69
-54.507114,-0.10317,-0.227055,-1.313597,8.78
-54.506959,-0.097328,-0.226563,-1.239224,8.87
-54.506237,-0.08238,-0.226018,-1.048889,8.96
-54.50442,-0.066346,-0.225267,-0.844743,9.05
-54.505133,-0.055164,-0.22464,-0.702371,9.14
-54.502136,-0.025105,-0.223244,-0.319653,9.23
-54.501295,-0.017893,-0.222485,-0.227825,9.32
-54.502158,-0.016123,-0.222004,-0.205285,9.41
-54.498816,0.005341,-0.220525,0.067998,9.5
-54.497117,-0.005019,-0.218155,-0.0639,9.59
-54.498348,-0.00388,-0.218172,-0.049405,9.68
-54.497517,0.003099,-0.21807,0.039463,9.77
-54.496745,-0.004703,-0.218182,-0.059878,9.86
-54.497921,0.001848,-0.218157,0.023526,9.95
-54.495704,0.004065,-0.2182,0.051758,10.04
-54.498775,-0.005674,-0.21824,-0.072248,10.13
-54.49734,0.003731,-0.217992,0.047508,10.22
-54.498743,-0.002646,-0.218095,-0.033696,10.31
-54.496408,-0.00093,-0.218085,-0.011839,10.4
-54.497367,0.001895,-0.218089,0.024133,10.49
-54.497012,-0.00813,-0.218162,-0.103515,10.58
-54.496145,0.004435,-0.218144,0.056463,10.67
-54.496449,-0.002497,-0.218245,-0.031798,10.76
-54.498271,-0.004733,-0.218186,-0.060257,10.85
-54.496495,0.002348,-0.218055,0.029901,10.94
-54.499533,-0.004578,-0.218278,-0.058284,11.03
-54.49689,0.001097,-0.218177,0.013964,11.12
-54.49669,-0.000846,-0.218225,-0.010777,11.21
-54.497853,-0.00335,-0.218259,-0.042651,11.3
-54.496381,0.00211,-0.218085,0.026865,11.39
-54.49709,-0.004017,-0.218245,-0.051151,11.48
-54.497576,-0.00211,-0.218269,-0.026865,11.57
-54.497894,-0.000328,-0.218265,-0.004174,11.66
-54.49595,-0.007123,-0.218415,-0.09069,11.75
-54.496835,0.001383,-0.218199,0.017607,11.84
-54.497167,0.002217,-0.218147,0.028231,11.93
-54.498366,-0.00447,-0.218182,-0.056918,12.02
-54.496354,0.003839,-0.218094,0.048874,12.11
-54.496517,-0.002843,-0.218262,-0.0362,12.2
-54.497308,-0.004351,-0.218258,-0.0554,12.29
-54.496831,0.003827,-0.218275,0.048722,12.38
-54.497471,-0.002909,-0.218368,-0.037035,12.47
-54.497821,0.000584,-0.218159,0.007437,12.56
-54.496009,0.001705,-0.218302,0.021705,12.65
-54.499388,-0.005382,-0.21831,-0.06853,12.74
-54.496168,0.004733,-0.218175,0.060257,12.83
-54.495591,-0.004083,-0.218281,-0.051985,12.92
-54.497739,0,-0.218177,0,13.01
-54.497026,0.003397,-0.218279,0.043258,13.1
-54.496313,-0.00338,-0.218351,-0.04303,13.19
-54.498661,0.002229,-0.218226,0.028383,13.28
-54.49768,0.000858,-0.218233,0.010928,13.37
-54.498761,-0.005651,-0.218337,-0.071945,13.46
-54.497117,0.004244,-0.218256,0.054034,13.55
-54.497521,-0.002235,-0.21836,-0.028459,13.64
-54.498121,-0.003445,-0.218251,-0.043865,13.73
-54.496731,0.002837,-0.218416,0.036124,13.82
-54.496781,-0.00518,-0.218456,-0.065949,13.91
-54.49842,0.001168,-0.218341,0.014875,14
-54.496831,-0.000668,-0.218506,-0.0085,14.09
-54.49788,-0.00388,-0.218402,-0.049405,14.18
-54.497576,0.001466,-0.218448,0.018669,14.27
-54.497526,-0.005996,-0.218376,-0.076346,14.36
-54.49788,-0.000185,-0.218339,-0.002353,14.45
-54.496181,0.000131,-0.218239,0.00167,14.54
-54.497435,-0.005871,-0.218517,-0.074753,14.63
-54.496967,0.003707,-0.218322,0.047204,14.72
-54.496972,0.000083,-0.218288,0.001062,14.81
-54.497026,-0.006789,-0.218386,-0.08644,14.9
-54.495718,0.002408,-0.21838,0.03066,14.99
-54.498807,-0.006169,-0.218358,-0.078547,15.08
-54.49882,-0.00118,-0.218216,-0.015026,15.17
-54.496449,-0.002491,-0.218363,-0.031722,15.26
-54.497635,-0.007808,-0.218404,-0.099417,15.35
-54.498103,0.001514,-0.218262,0.019276,15.44
-54.498466,-0.003403,-0.218161,-0.043334,15.53
-54.497585,-0.00369,-0.218296,-0.046977,15.62
-54.497385,0.002015,-0.218304,0.025651,15.71
-54.497271,-0.005871,-0.218381,-0.074753,15.8
-54.49833,-0.001186,-0.218242,-0.015102,15.89
-54.497648,0.000215,-0.218438,0.002732,15.98
-54.498729,-0.003725,-0.218574,-0.047432,16.07
-54.496181,0.00546,-0.218454,0.069516,16.16
-54.497748,-0.002891,-0.218415,-0.036807,16.25
-54.497567,-0.003701,-0.218288,-0.047128,16.34
-54.495995,0.001609,-0.218397,0.020491,16.43
-54.499047,-0.0067,-0.218382,-0.085301,16.52
-54.496967,0.001943,-0.218204,0.02474,16.61
-54.496572,0.000703,-0.218391,0.008955,16.7
-54.500764,-0.001889,-0.218416,-0.024057,16.79
-54.49719,0.005209,-0.218243,0.066329,16.88
-54.497521,-0.003582,-0.218551,-0.04561,16.97
-54.498784,-0.001931,-0.21855,-0.024589,17.06
-54.495523,0.001395,-0.218317,0.017758,17.15
-54.497221,-0.006199,-0.218512,-0.078927,17.24
-54.498343,0.001299,-0.218294,0.016544,17.33
-54.497662,-0.001317,-0.218459,-0.016772,17.42
-54.497753,-0.004232,-0.218566,-0.053883,17.51
-54.497208,0.003517,-0.218394,0.044776,17.6
-54.497621,-0.005895,-0.218431,-0.075056,17.69
-54.497644,0.001311,-0.218243,0.016696,17.78
-54.497385,0.00062,-0.218404,0.007893,17.87
-54.498193,-0.006986,-0.21829,-0.088944,17.96
-54.497812,0.001717,-0.21831,0.021857,18.05
-54.495791,-0.005549,-0.218456,-0.070655,18.14
-54.499374,-0.002015,-0.21835,-0.025651,18.23
-54.494937,0.001895,-0.218375,0.024133,18.32
-54.497485,-0.007677,-0.218481,-0.097748,18.41
-54.497412,0.001776,-0.218305,0.022616,18.5
-54.498007,-0.000882,-0.218343,-0.011232,18.59
-54.498775,-0.004196,-0.218406,-0.053427,18.68
-54.497285,0.002491,-0.218313,0.031722,18.77
-54.498407,-0.003755,-0.218418,-0.047811,18.86
-54.498225,0.000846,-0.218297,0.010777,18.95
-54.496395,0.00174,-0.218451,0.02216,19.04
-54.497512,-0.005573,-0.218487,-0.070958,19.13
-54.49619,0.003648,-0.218308,0.046445,19.22
-54.496404,-0.005317,-0.218462,-0.067695,19.31
-54.499738,-0.008523,-0.218549,-0.108524,19.34