File: Chain/Curve fitting/Data_corrected/Dall.csv
POSN mm ,LOAD kn,STRAIN1 mm,STRESS(MPA),TIME(sec)
-54.285433,0.001049,0,-0.013357,1.3
-54.286169,0.007778,0.001247,-0.099038,1.38
-54.286342,0.012308,0.00162,-0.156715,1.46
-54.287146,0.012839,0.002606,-0.163469,1.54
-54.287659,0.019461,0.003364,-0.247784,1.62
-54.290289,0.021493,0.004294,-0.273663,1.7
-54.289476,0.031793,0.005138,-0.404803,1.78
-54.290784,0.03432,0.005544,-0.43698,1.86
-54.292928,0.043994,0.006215,-0.560151,1.94
-54.29414,0.053298,0.007128,-0.678617,2.02
-54.294063,0.056928,0.007562,-0.724835,2.1
-54.294354,0.063169,0.00829,-0.804293,2.18
-54.296602,0.0736,0.009071,-0.937102,2.26
-54.297015,0.082237,0.009907,-1.047068,2.34
-54.296289,0.085294,0.010404,-1.086,2.42
-54.296715,0.091869,0.011113,-1.169708,2.5
-54.299345,0.102371,0.011926,-1.303428,2.58
-54.298678,0.107366,0.012373,-1.367024,2.66
-54.300072,0.120687,0.013552,-1.536641,2.74
-54.301185,0.123942,0.013927,-1.578077,2.82
-54.302238,0.133753,0.014822,-1.702994,2.9
-54.302084,0.14227,0.015447,-1.811442,2.98
-54.30356,0.147766,0.016249,-1.881414,3.06
-54.304882,0.160068,0.016993,-2.038053,3.14
-54.304532,0.164807,0.017637,-2.098386,3.22
-54.306508,0.177693,0.018123,-2.262462,3.3
-54.307148,0.188226,0.01924,-2.396562,3.38
-54.308511,0.198817,0.019943,-2.53142,3.46
-54.30991,0.207233,0.020715,-2.638578,3.54
-54.308938,0.209129,0.021108,-2.662711,3.62
-54.312489,0.229907,0.022079,-2.927267,3.7
-54.311272,0.235099,0.022677,-2.993368,3.78
-54.314274,0.248533,0.02342,-3.164427,3.86
-54.313652,0.256366,0.024162,-3.264147,3.94
-54.314524,0.26446,0.024683,-3.367207,4.02
-54.316041,0.279152,0.025835,-3.554279,4.1
-54.313834,0.287229,0.02625,-3.657111,4.18
-54.316663,0.296301,0.026878,-3.772617,4.26
-54.316423,0.308084,0.02767,-3.922654,4.34
-54.31774,0.316942,0.028444,-4.035428,4.42
-54.317654,0.328493,0.028916,-4.182504,4.5
-54.319161,0.345588,0.02986,-4.40016,4.58
-54.320292,0.352389,0.03042,-4.486751,4.66
-54.319366,0.364703,0.031182,-4.643542,4.74
-54.322132,0.374699,0.031751,-4.770811,4.82
-54.322472,0.39317,0.032896,-5.005997,4.9
-54.321414,0.388724,0.033077,-4.949383,4.98
-54.323871,0.405371,0.033681,-5.161346,5.06
-54.323113,0.425178,0.034856,-5.413532,5.14
-54.324612,0.438541,0.035457,-5.58368,5.22
-54.325516,0.45163,0.036346,-5.750336,5.3
-54.326683,0.463504,0.036809,-5.901511,5.38
-54.326815,0.471711,0.037449,-6.006013,5.46
-54.327496,0.487006,0.038313,-6.200749,5.54
-54.328377,0.499403,0.039005,-6.358603,5.62
-54.328967,0.50928,0.039668,-6.484354,5.7
-54.329104,0.522012,0.040334,-6.646457,5.78
-54.330789,0.534701,0.040986,-6.808029,5.86
-54.332392,0.551677,0.041687,-7.024167,5.94
-54.332265,0.555634,0.042074,-7.074558,6.02
-54.332669,0.573683,0.042972,-7.304356,6.1
-54.333895,0.584662,0.043664,-7.444147,6.18
-54.334245,0.604039,0.044499,-7.690869,6.26
-54.33415,0.606632,0.045044,-7.723881,6.34
-54.336816,0.622541,0.045457,-7.926435,6.42
-54.33618,0.639182,0.04626,-8.138322,6.5
-54.337533,0.648242,0.046946,-8.253676,6.58
-54.339209,0.66765,0.047681,-8.500778,6.66
-54.339559,0.680143,0.048507,-8.659845,6.74
-54.340027,0.692022,0.049007,-8.811096,6.82
-54.342289,0.705659,0.04989,-8.984734,6.9
-54.342679,0.72546,0.050522,-9.236844,6.98
-54.343574,0.730067,0.051157,-9.295508,7.06
-54.345704,0.748622,0.051818,-9.531757,7.14
-54.344473,0.75807,0.052598,-9.652044,7.22
-54.344469,0.775212,0.053309,-9.870306,7.3
-54.347326,0.785297,0.05379,-9.998714,7.38
-54.348897,0.807214,0.054909,-10.277765,7.46
-54.348897,0.810355,0.05517,-10.31776,7.54
-54.348779,0.833797,0.056039,-10.616239,7.62
-54.350746,0.837994,0.056593,-10.669666,7.7
-54.353153,0.860018,0.057328,-10.950083,7.78
-54.351177,0.866103,0.058036,-11.027568,7.86
-54.354874,0.882703,0.058403,-11.238924,7.94
-54.353335,0.90012,0.059438,-11.460678,8.02
-54.3564,0.910622,0.060076,-11.594398,8.1
-54.356468,0.927716,0.060698,-11.812053,8.18
-54.355964,0.94257,0.061592,-12.001174,8.26
-54.358608,0.965732,0.062545,-12.296086,8.34
-54.356655,0.971276,0.062972,-12.366665,8.42
-54.358898,0.992495,0.063553,-12.636837,8.5
-54.361274,1.002026,0.064431,-12.758186,8.58
-54.359784,1.015323,0.064957,-12.927499,8.66
-54.359961,1.027113,0.065521,-13.077611,8.74
-54.36101,1.037824,0.065942,-13.213988,8.82
-54.362209,1.05539,0.066762,-13.437638,8.9
-54.363667,1.067811,0.067398,-13.595795,8.98
-54.363177,1.086646,0.068068,-13.835611,9.06
-54.365121,1.095575,0.068797,-13.949295,9.14
-54.366302,1.114768,0.06959,-14.193664,9.22
-54.365348,1.132596,0.070259,-14.420654,9.3
-54.36711,1.141828,0.070956,-14.538209,9.38
-54.367065,1.166964,0.071786,-14.858242,9.46
-54.367678,1.169074,0.072255,-14.885107,9.54
-54.369363,1.191008,0.073056,-15.164386,9.62
-54.369808,1.204967,0.073605,-15.342123,9.7
-54.369504,1.217616,0.074422,-15.503163,9.78
-54.369872,1.224321,0.074822,-15.588541,9.86
-54.371634,1.242083,0.07558,-15.814696,9.94
-54.371284,1.261014,0.076177,-16.055726,10.02
-54.372415,1.279777,0.077102,-16.294631,10.1
-54.372828,1.288623,0.077611,-16.407253,10.18
-54.37475,1.301265,0.078285,-16.568218,10.26
-54.376389,1.315552,0.078848,-16.750128,10.34
-54.375467,1.337314,0.079463,-17.027206,10.42
-54.376657,1.356775,0.080469,-17.27499,10.5
-54.376784,1.362038,0.08098,-17.342002,10.58
-54.379836,1.374662,0.081368,-17.502739,10.66
-54.379909,1.405424,0.082726,-17.894413,10.74
-54.380213,1.405692,0.082922,-17.897828,10.82
-54.379991,1.427376,0.083648,-18.173919,10.9
-54.381045,1.449865,0.084481,-18.460256,10.98
-54.381917,1.454586,0.08488,-18.520361,11.06
-54.383302,1.476562,0.085718,-18.800172,11.14
-54.384624,1.506686,0.08673,-19.183725,11.22
-54.384042,1.500893,0.087091,-19.109959,11.3
-54.384769,1.498735,0.087093,-19.082486,11.38
-54.384274,1.485926,0.087144,-18.919396,11.46
-54.383202,1.483011,0.087182,-18.882286,11.54
-54.385432,1.481044,0.087278,-18.857242,11.62
-54.38501,1.481563,0.087175,-18.863844,11.7
-54.384624,1.479733,0.087341,-18.840546,11.78
-54.386313,1.479089,0.087367,-18.832349,11.86
-54.385114,1.471072,0.087215,-18.730276,11.94
-54.385241,1.471567,0.087208,-18.736575,12.02
-54.38426,1.469034,0.087311,-18.704321,12.1
-54.386449,1.466078,0.087255,-18.666679,12.18
-54.385096,1.467502,0.087229,-18.684817,12.26
-54.387962,1.301813,0.087526,-16.5752,0.06
-54.385441,1.295465,0.087413,-16.494376,0.14
-54.385641,1.276135,0.087027,-16.248261,0.22
-54.385732,1.243305,0.086737,-15.830254,0.3
-54.384133,1.221329,0.086513,-15.550443,0.38
-54.384705,1.201034,0.086236,-15.292035,0.46
-54.382748,1.174271,0.085836,-14.951284,0.54
-54.38357,1.148981,0.085577,-14.629279,0.62
-54.382003,1.120979,0.085254,-14.272743,0.7
-54.380245,1.104397,0.085052,-14.061614,0.78
-54.380336,1.083636,0.084794,-13.797286,0.86
-54.379696,1.05812,0.084318,-13.472396,0.94
-54.378079,1.031303,0.084071,-13.130963,1.02
-54.377661,0.991678,0.083692,-12.626439,1.1
-54.377397,0.952828,0.083169,-12.131782,1.18
-54.377139,0.90133,0.082529,-11.476084,1.26
-54.376457,0.858998,0.081881,-10.937106,1.34
-54.374436,0.796896,0.080987,-10.146398,1.42
-54.374232,0.78842,0.081007,-10.038481,1.5
-54.373855,0.735766,0.080169,-9.36806,1.58
-54.372638,0.691926,0.079584,-8.809882,1.66
-54.371529,0.663084,0.079031,-8.442645,1.74
-54.369949,0.634754,0.078642,-8.081935,1.82
-54.369722,0.60007,0.07799,-7.640325,1.9
-54.371062,0.561768,0.0775,-7.15265,1.98
-54.367006,0.515741,0.076699,-6.56662,2.06
-54.367478,0.493383,0.07624,-6.281953,2.14
-54.367065,0.452238,0.075581,-5.758077,2.22
-54.365062,0.413519,0.074838,-5.265089,2.3
-54.364989,0.386596,0.074355,-4.92229,2.38
-54.363849,0.350052,0.073722,-4.457002,2.46
-54.362437,0.32624,0.073296,-4.153817,2.54
-54.362823,0.289291,0.072314,-3.683369,2.62
-54.358508,0.25816,0.071649,-3.286991,2.7
-54.35873,0.244731,0.071415,-3.116008,2.78
-54.358939,0.213164,0.07053,-2.71409,2.86
-54.358808,0.190747,0.069963,-2.428663,2.94
-54.356655,0.167084,0.06935,-2.127376,3.02
-54.356582,0.143981,0.068547,-1.833223,3.1
-54.355074,0.124347,0.067767,-1.583238,3.18
-54.356936,0.105059,0.067045,-1.337655,3.26
-54.354942,0.100309,0.066884,-1.277169,3.34
-54.355347,0.098431,0.066648,-1.253264,3.42
-54.355951,0.100189,0.066755,-1.275652,3.5
-54.355833,0.100172,0.066753,-1.275424,3.58
-54.356773,0.102264,0.066821,-1.302062,3.66
-54.356282,0.10249,0.066795,-1.304946,3.74
-54.3564,0.100589,0.066749,-1.280736,3.82
-54.357804,0.103307,0.066783,-1.315343,3.9
-54.355978,0.106835,0.066778,-1.36027,3.98
-54.356814,0.10227,0.066755,-1.302138,4.06
-54.356732,0.102735,0.066797,-1.308057,4.14
-54.356078,0.102156,0.066691,-1.300696,4.22
-54.356005,0.102812,0.066704,-1.309044,4.3
-54.356046,0.106221,0.066729,-1.352453,4.38
-54.357045,0.090253,0.065929,-1.149141,0.01
-54.357654,0.129235,0.066946,-1.645468,0.09
-54.358294,0.132972,0.067192,-1.693052,0.17
-54.359375,0.139642,0.06734,-1.777974,0.25
-54.360393,0.153995,0.067657,-1.96072,0.33
-54.363359,0.172502,0.068189,-2.196361,0.41
-54.36186,0.191206,0.068664,-2.434507,0.49
-54.36439,0.214601,0.069212,-2.732379,0.57
-54.366025,0.241232,0.069868,-3.07146,0.65
-54.364939,0.270832,0.070391,-3.448335,0.73
-54.366551,0.320965,0.071466,-4.086654,0.81
-54.367383,0.345582,0.072133,-4.400084,0.89
-54.367782,0.383043,0.072816,-4.877059,0.97
-54.367601,0.406349,0.07327,-5.173792,1.05
-54.369767,0.441247,0.073792,-5.618134,1.13
-54.369513,0.476414,0.074429,-6.065891,1.21
-54.369667,0.498325,0.074928,-6.344866,1.29
-54.370076,0.533003,0.075413,-6.7864,1.37
-54.371443,0.570238,0.076024,-7.260491,1.45
-54.371379,0.598955,0.076569,-7.626134,1.53
-54.373323,0.639689,0.077196,-8.144773,1.61
-54.374513,0.661516,0.077499,-8.422686,1.69
-54.37435,0.71466,0.078423,-9.09933,1.77
-54.376907,0.747395,0.07886,-9.516123,1.85
-54.377107,0.780886,0.079446,-9.942555,1.93
-54.378687,0.821525,0.079863,-10.459979,2.01
-54.379323,0.84914,0.080445,-10.811582,2.09
-54.379251,0.881356,0.080751,-11.221773,2.17
-54.381254,0.930089,0.08167,-11.842258,2.25
-54.382139,0.966096,0.082085,-12.300715,2.33
-54.382303,0.999647,0.082403,-12.727906,2.41
-54.384088,1.0427,0.083123,-13.276066,2.49
-54.384183,1.078296,0.083528,-13.729287,2.57
-54.38535,1.105094,0.083905,-14.070493,2.65
-54.386331,1.155275,0.084464,-14.70942,2.73
-54.386745,1.189274,0.085002,-15.142302,2.81
-54.387094,1.231873,0.085588,-15.684695,2.89
-54.388916,1.257157,0.086145,-16.006624,2.97
-54.388312,1.298982,0.086627,-16.539151,3.05
-54.390451,1.33251,0.087007,-16.966038,3.13
-54.390578,1.373875,0.087658,-17.492722,3.21
-54.389007,1.399797,0.088088,-17.822772,3.29
-54.389156,1.422465,0.088403,-18.111385,3.37
-54.392218,1.465446,0.089097,-18.658635,3.45
-54.392022,1.499826,0.08978,-19.096374,3.53
-54.39249,1.516855,0.089967,-19.313195,3.61
-54.393912,1.546419,0.090872,-19.689614,3.69
-54.394711,1.572406,0.091642,-20.020499,3.77
-54.396564,1.581687,0.092256,-20.138661,3.85
-54.397513,1.603132,0.092886,-20.411717,3.93
-54.397872,1.622963,0.093494,-20.664206,4.01
-54.398853,1.63359,0.09419,-20.79952,4.09
-54.399121,1.650882,0.094793,-21.019679,4.17
-54.399966,1.667327,0.095311,-21.229063,4.25
-54.402573,1.695633,0.096476,-21.589469,4.33
-54.401678,1.69884,0.097117,-21.630298,4.41
-54.402723,1.719368,0.097714,-21.891667,4.49
-54.405653,1.746231,0.098508,-22.233708,4.57
-54.406075,1.746923,0.098981,-22.242511,4.65
-54.40548,1.764613,0.099702,-22.467755,4.73
-54.406075,1.781523,0.100317,-22.683058,4.81
-54.407124,1.792604,0.10103,-22.82414,4.89
-54.409077,1.81365,0.101656,-23.092111,4.97
-54.407819,1.81666,0.102203,-23.130436,5.05
-54.40999,1.848084,0.103128,-23.530533,5.13
-54.410285,1.855409,0.1037,-23.623803,5.21
-54.411325,1.869106,0.104109,-23.7982,5.29
-54.412674,1.894468,0.105408,-24.121117,5.37
-54.410094,1.895404,0.105562,-24.133032,5.45
-54.411643,1.919168,0.10625,-24.435609,5.53
-54.413269,1.945943,0.107096,-24.776511,5.61
-54.413996,1.949662,0.107452,-24.823867,5.69
-54.416162,1.958966,0.108019,-24.942333,5.77
-54.415413,1.988679,0.108974,-25.32065,5.85
-54.416948,2.004254,0.109599,-25.518953,5.93
-54.418729,2.022552,0.110534,-25.751938,6.01
-54.418992,2.038467,0.111121,-25.954567,6.09
-54.421031,2.055311,0.11166,-26.169035,6.17
-54.418529,2.069992,0.112193,-26.355955,6.25
-54.422271,2.094209,0.11299,-26.6643,6.33
-54.422626,2.105594,0.113903,-26.809251,6.41
-54.424956,2.119213,0.114353,-26.982662,6.49
-54.423507,2.133578,0.115009,-27.16556,6.57
-54.424842,2.153891,0.11569,-27.424196,6.65
-54.425164,2.16338,0.116253,-27.545015,6.73
-54.426718,2.183074,0.117169,-27.795758,6.81
-54.427563,2.208555,0.117896,-28.120192,6.89
-54.427985,2.213341,0.118542,-28.181133,6.97
-54.427644,2.236015,0.119133,-28.469822,7.05
-54.429874,2.237594,0.119612,-28.489933,7.13
-54.429438,2.271444,0.1207,-28.920918,7.21
-54.430283,2.278376,0.121389,-29.009179,7.29
-54.431441,2.297288,0.121983,-29.249982,7.37
-54.431591,2.320033,0.122817,-29.539582,7.45
-54.433771,2.334398,0.123391,-29.722479,7.53
-54.432386,2.353609,0.124057,-29.967076,7.61
-54.43408,2.368146,0.124657,-30.152174,7.69
-54.434671,2.382207,0.125266,-30.331201,7.77
-54.436751,2.396178,0.126075,-30.509089,7.85
-54.436537,2.414846,0.126532,-30.74678,7.93
-54.437328,2.427018,0.127321,-30.901749,8.01
-54.439331,2.453458,0.127991,-31.238401,8.09
-54.440094,2.465403,0.128606,-31.390487,8.17
-54.440852,2.480769,0.129261,-31.586134,8.25
-54.442573,2.491504,0.130034,-31.722814,8.33
-54.442128,2.47705,0.129917,-31.538778,8.41
-54.441574,2.462929,0.129965,-31.358992,8.49
-54.442065,2.457142,0.130087,-31.285302,8.57
-54.441661,2.463269,0.130066,-31.363318,8.65
-54.442019,2.455056,0.130051,-31.25874,8.73
-54.440307,2.448505,0.130015,-31.175336,8.81
-54.441933,2.443713,0.130016,-31.11432,8.89
-54.440375,2.442861,0.129968,-31.103467,8.97
-54.440689,2.441782,0.130006,-31.089731,9.05
-54.439976,2.441919,0.130145,-31.091476,9.13
-54.439912,2.441698,0.130046,-31.088668,9.21
-54.440829,2.437586,0.130112,-31.036304,9.29
-54.44117,2.435112,0.130175,-31.004809,9.37
-54.439485,2.441221,0.130207,-31.082597,9.45
-54.440838,2.446282,0.130166,-31.147029,9.53
-54.441574,2.442008,0.130174,-31.092615,9.61
-54.440157,2.441674,0.130133,-31.088365,9.69
-54.442864,2.442348,0.130263,-31.096941,9.77
-54.440893,2.44472,0.130164,-31.127145,9.85
-54.440979,2.43687,0.130201,-31.027197,9.93
-54.441302,2.438962,0.13019,-31.053835,10.01
-54.440035,2.440923,0.130232,-31.078803,10.09
-54.442069,2.434087,0.12999,-30.991756,10.17
-54.442669,2.431679,0.130151,-30.961096,10.25
-54.442973,2.430409,0.131764,-30.944931,0.05
-54.44142,2.415794,0.131493,-30.758846,0.13
-54.442128,2.386367,0.131365,-30.384172,0.21
-54.439926,2.360517,0.131108,-30.055033,0.29
-54.439049,2.344978,0.130973,-29.857185,0.37
-54.438786,2.304912,0.130814,-29.347046,0.45
-54.439508,2.290767,0.1305,-29.166957,0.53
-54.438245,2.256584,0.130269,-28.731722,0.61
-54.436619,2.235663,0.13002,-28.465345,0.69
-54.434298,2.19875,0.129615,-27.995352,0.77
-54.434507,2.176845,0.129504,-27.716452,0.85
-54.433017,2.143466,0.12912,-27.291463,0.93
-54.432454,2.12211,0.129072,-27.019545,1.01
-54.431055,2.08776,0.128661,-26.582186,1.09
-54.431564,2.056265,0.128455,-26.181178,1.17
-54.431968,1.995921,0.127829,-25.412857,1.25
-54.430715,1.914394,0.127114,-24.37482,1.33
-54.430515,1.851159,0.126449,-23.569693,1.41
-54.429861,1.811135,0.126011,-23.060085,1.49
-54.426568,1.749462,0.125383,-22.274841,1.57
-54.427027,1.709127,0.125087,-21.761286,1.65
-54.423938,1.633507,0.124253,-20.798457,1.73
-54.424147,1.590532,0.123852,-20.251283,1.81
-54.425637,1.558584,0.123499,-19.844508,1.89
-54.423684,1.508039,0.123076,-19.200952,1.97
-54.42402,1.456678,0.122538,-18.546999,2.05
-54.42263,1.400059,0.121941,-17.826111,2.13
-54.422335,1.346749,0.121311,-17.147342,2.21
-54.418892,1.311386,0.120801,-16.69708,2.29
-54.419019,1.269078,0.120356,-16.158406,2.37
-54.417461,1.209956,0.119862,-15.405643,2.45
-54.417366,1.183242,0.119593,-15.0655,2.53
-54.416112,1.135343,0.118953,-14.45564,2.61
-54.416058,1.088738,0.118397,-13.862248,2.69
-54.415299,1.069856,0.11814,-13.621826,2.77
-54.415536,1.040936,0.117915,-13.253603,2.85
-54.414096,0.969923,0.116969,-12.349437,2.93
-54.413519,0.934637,0.116494,-11.900163,3.01
-54.411898,0.890446,0.115916,-11.337507,3.09
-54.413001,0.860202,0.115558,-10.952436,3.17
-54.409749,0.813842,0.114986,-10.362156,3.25
-54.409336,0.778759,0.114495,-9.915462,3.33
-54.409218,0.750387,0.113979,-9.55422,3.41
-54.407451,0.711566,0.113458,-9.059942,3.49
-54.409132,0.690705,0.113001,-8.794324,3.57
-54.409145,0.629109,0.112209,-8.010066,3.65
-54.406774,0.59334,0.111659,-7.554645,3.73
-54.406066,0.55815,0.111074,-7.106584,3.81
-54.403382,0.51958,0.110488,-6.615494,3.89
-54.403522,0.49178,0.110048,-6.261538,3.97
-54.401628,0.460196,0.109522,-5.859392,4.05
-54.400316,0.414962,0.108624,-5.283455,4.13
-54.401342,0.406796,0.108471,-5.179484,4.21
-54.401097,0.370944,0.107758,-4.723,4.29
-54.402137,0.348246,0.107317,-4.434007,4.37
-54.401102,0.316703,0.10647,-4.032392,4.45
-54.400284,0.28547,0.106084,-3.634723,4.53
-54.398004,0.253987,0.105431,-3.233867,4.61
-54.394747,0.237274,0.105029,-3.021069,4.69
-54.394961,0.204277,0.104127,-2.600936,4.77
-54.39329,0.186503,0.103665,-2.374629,4.85
-54.394134,0.167638,0.103062,-2.134434,4.93
-54.39309,0.151169,0.10247,-1.924747,5.01
-54.393353,0.130796,0.101745,-1.665352,5.09
-54.390365,0.111353,0.100885,-1.417795,5.17
-54.390805,0.086957,0.100054,-1.107174,5.25
-54.390769,0.090569,0.100117,-1.153164,5.33
-54.388793,0.089848,0.100303,-1.143981,5.41
-54.389225,0.088173,0.100021,-1.122655,5.49
-54.390346,0.093746,0.100189,-1.193614,5.57
-54.389043,0.096816,0.100329,-1.232697,5.65
-54.39135,0.101906,0.100197,-1.297508,5.73
-54.391773,0.099832,0.100125,-1.271098,5.81
-54.391237,0.094908,0.100084,-1.208412,5.89
-54.391332,0.115407,0.100437,-1.469401,0.03
-54.390941,0.115824,0.100555,-1.474714,0.11
-54.391182,0.118423,0.100699,-1.507802,0.19
-54.391954,0.138336,0.10128,-1.761354,0.27
-54.391918,0.155091,0.101607,-1.974684,0.35
-54.392059,0.174981,0.102059,-2.227932,0.43
-54.394965,0.189877,0.102458,-2.417583,0.51
-54.394866,0.20622,0.102777,-2.625676,0.59
-54.397622,0.213021,0.102984,-2.712268,0.67
-54.395924,0.234747,0.103442,-2.988891,0.75
-54.398676,0.254583,0.103842,-3.241456,0.83
-54.398127,0.273693,0.104168,-3.484763,0.91
-54.399189,0.306255,0.104875,-3.899355,0.99
-54.401624,0.344425,0.105505,-4.385361,1.07
-54.400997,0.385237,0.106241,-4.904987,1.15
-54.402741,0.415075,0.106718,-5.284897,1.23
-54.403377,0.466919,0.107599,-5.944997,1.31
-54.402918,0.493878,0.107948,-6.288252,1.39
-54.407487,0.548893,0.108894,-6.988725,1.47
-54.405902,0.586259,0.109474,-7.464486,1.55
-54.404576,0.606787,0.109783,-7.725855,1.63
-54.406783,0.645506,0.11023,-8.218843,1.71
-54.408028,0.685412,0.110911,-8.726933,1.79
-54.408796,0.749189,0.111665,-9.538966,1.87
-54.409232,0.773942,0.112161,-9.854142,1.95
-54.41009,0.803667,0.112425,-10.23261,2.03
-54.410412,0.835645,0.113031,-10.639765,2.11
-54.411344,0.876874,0.113548,-11.164703,2.19
-54.410867,0.937933,0.114385,-11.94213,2.27
-54.413265,0.954741,0.114563,-12.156143,2.35
-54.413365,0.989312,0.114951,-12.596311,2.43
-54.41718,1.044095,0.115593,-13.293825,2.51
-54.414718,1.066083,0.115914,-13.573787,2.59
-54.416031,1.104689,0.116506,-14.065333,2.67
-54.416866,1.154822,0.117041,-14.703652,2.75
-54.418906,1.192445,0.117622,-15.182676,2.83
-54.420368,1.248389,0.118079,-15.894989,2.91
-54.420414,1.276994,0.118446,-16.259189,2.99
-54.419578,1.315224,0.118907,-16.745954,3.07
-54.420791,1.357418,0.119316,-17.283187,3.15
-54.420323,1.418149,0.120134,-18.05644,3.23
-54.424356,1.444757,0.120426,-18.395217,3.31
-54.424969,1.501894,0.121016,-19.122708,3.39
-54.423961,1.54084,0.121547,-19.61858,3.47
-54.424165,1.589763,0.122044,-20.241493,3.55
-54.42526,1.635367,0.122477,-20.822135,3.63
-54.426377,1.674592,0.122894,-21.321574,3.71
-54.427036,1.711792,0.123388,-21.79521,3.79
-54.428839,1.778316,0.123997,-22.642229,3.87
-54.428444,1.800036,0.124297,-22.918776,3.95
-54.428312,1.857013,0.124895,-23.644218,4.03
-54.42907,1.872987,0.125069,-23.847605,4.11
-54.431137,1.928729,0.125829,-24.557338,4.19
-54.433944,1.986575,0.126396,-25.29386,4.27
-54.432995,2.037954,0.12684,-25.94804,4.35
-54.433181,2.059293,0.127132,-26.21973,4.43
-54.433022,2.096343,0.127522,-26.691469,4.51
-54.434657,2.141607,0.128028,-27.267785,4.59
-54.437782,2.182227,0.128511,-27.784982,4.67
-54.437328,2.230042,0.128971,-28.393779,4.75
-54.438822,2.265805,0.129481,-28.849125,4.83
-54.4376,2.304107,0.129838,-29.336801,4.91
-54.437823,2.339751,0.130318,-29.790629,4.99
-54.440389,2.381742,0.130803,-30.325281,5.07
-54.443432,2.429485,0.131285,-30.933168,5.15
-54.442006,2.446198,0.131692,-31.145966,5.23
-54.441334,2.492589,0.132355,-31.736626,5.31
-54.443232,2.516431,0.133121,-32.04019,5.39
-54.44325,2.545261,0.133707,-32.407274,5.47
-54.445149,2.57954,0.13448,-32.843724,5.55
-54.445571,2.58922,0.134936,-32.966971,5.63
-54.448691,2.615052,0.13582,-33.295882,5.71
-54.448196,2.620488,0.136318,-33.365095,5.79
-54.448314,2.635866,0.137143,-33.560893,5.87
-54.447856,2.645928,0.137532,-33.688997,5.95
-54.451703,2.68696,0.138462,-34.211431,6.03
-54.452311,2.696776,0.138972,-34.336423,6.11
-54.452634,2.717817,0.139799,-34.604319,6.19
-54.452952,2.714819,0.140312,-34.566145,6.27
-54.453256,2.750069,0.14126,-35.014965,6.35
-54.451771,2.746654,0.141711,-34.971479,6.43
-54.45579,2.778238,0.142469,-35.373626,6.51
-54.455836,2.791309,0.143092,-35.540055,6.59
-54.455936,2.805412,0.14392,-35.719613,6.67
-54.455286,2.803159,0.144282,-35.690926,6.75
-54.457911,2.838933,0.145097,-36.146424,6.83
-54.458538,2.853709,0.145759,-36.334557,6.91
-54.460446,2.878046,0.146735,-36.64442,6.99
-54.459805,2.880979,0.147023,-36.681759,7.07
-54.462408,2.901268,0.147612,-36.940092,7.15
-54.461904,2.915722,0.148503,-37.124127,7.23
-54.462081,2.933812,0.14928,-37.354456,7.31
-54.461586,2.941847,0.149853,-37.456757,7.39
-54.464116,2.965999,0.150587,-37.764268,7.47
-54.466082,2.990967,0.151183,-38.082175,7.55
-54.465564,2.995288,0.15181,-38.137196,7.63
-54.466532,3.020859,0.152809,-38.462768,7.71
-54.465978,3.013217,0.153317,-38.365476,7.79
-54.466636,3.04848,0.153975,-38.814447,7.87
-54.468717,3.066963,0.154748,-39.049785,7.95
-54.470915,3.082615,0.155461,-39.249075,8.03
-54.46992,3.093922,0.15624,-39.39304,8.11
-54.471237,3.093368,0.156618,-39.385982,8.19
-54.47047,3.121966,0.157285,-39.750107,8.27
-54.471969,3.142077,0.157901,-40.006163,8.35
-54.475688,3.161597,0.158792,-40.254706,8.43
-54.475816,3.172153,0.159224,-40.389109,8.51
-54.476279,3.17753,0.159751,-40.457563,8.59
-54.474598,3.207207,0.160529,-40.835424,8.67
-54.476978,3.217274,0.161304,-40.963604,8.75
-54.478404,3.235453,0.162004,-41.195072,8.83
-54.480834,3.268242,0.162946,-41.612548,8.91
-54.48068,3.264278,0.163371,-41.562081,8.99
-54.480562,3.287965,0.16415,-41.863671,9.07
-54.480185,3.293937,0.164898,-41.939714,9.15
-54.481034,3.321415,0.165574,-42.289572,9.23
-54.483014,3.341621,0.166351,-42.546842,9.31
-54.484291,3.35269,0.166929,-42.687772,9.39
-54.483891,3.360045,0.167444,-42.781421,9.47
-54.484668,3.377879,0.168269,-43.008487,9.55
-54.484327,3.395671,0.168835,-43.235022,9.63
-54.486539,3.41652,0.169798,-43.500488,9.71
-54.48871,3.429025,0.17024,-43.659708,9.79
-54.489155,3.450978,0.171112,-43.939214,9.87
-54.488397,3.476584,0.171939,-44.265242,9.95
-54.489028,3.45754,0.172344,-44.02277,10.03
-54.490895,3.495121,0.172935,-44.501263,10.11
-54.49119,3.496987,0.173724,-44.525017,10.19
-54.492375,3.487408,0.173947,-44.40306,10.27
-54.49258,3.476369,0.173968,-44.26251,10.35
-54.492035,3.465378,0.173872,-44.122567,10.43
-54.490568,3.459847,0.173922,-44.05214,10.51
-54.489845,3.45757,0.174056,-44.023149,10.59
-54.492207,3.455192,0.174017,-43.992869,10.67
-54.492543,3.431666,0.17559,-43.693327,0.02
-54.491349,3.410655,0.175438,-43.425812,0.1
-54.489414,3.382337,0.175348,-43.065253,0.18
-54.491076,3.349102,0.175039,-42.642085,0.26
-54.48846,3.316981,0.174719,-42.233109,0.34
-54.487356,3.276402,0.174496,-41.716443,0.42
-54.485517,3.258157,0.174435,-41.484141,0.5
-54.487502,3.242415,0.174178,-41.283712,0.58
-54.486748,3.209448,0.173958,-40.863959,0.66
-54.485272,3.160977,0.173661,-40.246814,0.74
-54.481665,3.129721,0.173455,-39.848841,0.82
-54.484286,3.113323,0.173393,-39.640065,0.9
-54.483959,3.080976,0.172966,-39.228205,0.98
-54.481457,3.033996,0.172654,-38.630032,1.06
-54.481388,2.993184,0.172407,-38.110407,1.14
-54.482374,2.934581,0.171912,-37.364246,1.22
-54.479831,2.826166,0.171054,-35.983865,1.3
-54.477887,2.77704,0.170676,-35.358372,1.38
-54.477105,2.705359,0.170069,-34.445706,1.46
-54.478023,2.652746,0.169712,-33.775817,1.54
-54.477369,2.588546,0.169163,-32.958395,1.62
-54.475189,2.541232,0.168925,-32.355972,1.7
-54.473713,2.489382,0.168409,-31.695796,1.78
-54.475579,2.441216,0.168113,-31.082521,1.86
-54.473772,2.378732,0.167407,-30.286956,1.94
-54.47171,2.312571,0.166825,-29.444566,2.02
-54.469952,2.271885,0.166518,-28.926534,2.1
-54.469566,2.232021,0.166249,-28.418975,2.18
-54.469057,2.183729,0.165814,-27.804106,2.26
-54.467563,2.108479,0.165091,-26.845983,2.34
-54.4665,2.07293,0.164946,-26.393369,2.42
-54.467113,2.027708,0.164577,-25.817584,2.5
-54.466941,1.97857,0.164141,-25.191938,2.58
-54.463271,1.921117,0.163497,-24.460425,2.66
-54.464329,1.861161,0.162963,-23.697038,2.74
-54.464747,1.840764,0.162832,-23.437339,2.82
-54.465024,1.772499,0.162222,-22.568159,2.9
-54.461895,1.72258,0.161648,-21.932572,2.98
-54.460514,1.664633,0.161152,-21.19476,3.06
-54.460578,1.630974,0.16097,-20.766204,3.14
-54.461581,1.584774,0.160457,-20.177973,3.22
-54.459274,1.523644,0.159826,-19.399635,3.3
-54.456794,1.458359,0.159187,-18.5684,3.38
-54.457117,1.437122,0.158953,-18.298001,3.46
-54.45832,1.397067,0.158514,-17.788013,3.54
-54.455454,1.339918,0.158032,-17.060371,3.62
-54.454051,1.297003,0.157618,-16.513955,3.7
-54.455036,1.264226,0.157323,-16.096631,3.78
-54.455023,1.223123,0.156815,-15.573287,3.86
-54.451962,1.16179,0.156161,-14.792368,3.94
-54.45183,1.129335,0.155689,-14.379142,4.02
-54.452279,1.098311,0.155297,-13.984129,4.1
-54.450944,1.053011,0.154853,-13.407358,4.18
-54.44821,1.017886,0.154495,-12.960132,4.26
-54.448632,0.963461,0.153948,-12.267172,4.34
-54.449554,0.923592,0.153418,-11.759537,4.42
-54.449386,0.91002,0.153087,-11.586733,4.5
-54.447769,0.849056,0.152284,-10.81052,4.58
-54.443309,0.813204,0.151841,-10.354036,4.66
-54.444645,0.768435,0.151276,-9.784018,4.74
-54.445385,0.748432,0.15098,-9.529328,4.82
-54.443786,0.695056,0.150174,-8.849724,4.9
-54.440675,0.647998,0.149565,-8.250565,4.98
-54.443059,0.61931,0.149056,-7.885302,5.06
-54.441874,0.582057,0.148599,-7.410983,5.14
-54.440861,0.536203,0.147803,-6.827154,5.22
-54.438509,0.524497,0.147601,-6.678104,5.3
-54.439163,0.482351,0.146908,-6.141478,5.38
-54.440657,0.453508,0.146409,-5.774242,5.46
-54.436038,0.411546,0.145842,-5.239969,5.54
-54.43398,0.38901,0.145248,-4.953026,5.62
-54.43423,0.361919,0.144803,-4.608101,5.7
-54.434789,0.334448,0.144052,-4.258319,5.78
-54.432282,0.296968,0.143433,-3.781117,5.86
-54.431269,0.276679,0.143018,-3.522784,5.94
-54.433385,0.247115,0.142319,-3.146365,6.02
-54.4319,0.231278,0.141765,-2.944722,6.1
-54.429652,0.192791,0.1411,-2.454694,6.18
-54.429298,0.175107,0.140582,-2.229526,6.26
-54.428757,0.162321,0.14004,-2.066739,6.34
-54.428712,0.146127,0.139458,-1.860544,6.42
-54.427567,0.1086,0.138588,-1.382734,6.5
-54.42674,0.106001,0.138159,-1.349645,6.58
-54.427254,0.113153,0.138268,-1.440715,6.66
-54.427753,0.115138,0.138228,-1.465986,6.74
-54.428076,0.105184,0.137977,-1.339248,6.82
-54.426436,0.109065,0.13816,-1.388653,6.9
-54.425587,0.118369,0.13839,-1.507119,6.98
-54.428553,0.117296,0.138218,-1.493459,7.06
-54.42709,0.174069,0.139451,-2.21632,0
-54.428834,0.160801,0.139241,-2.047387,0.08
-54.427876,0.163084,0.139302,-2.076453,0.16
-54.429997,0.186479,0.13967,-2.374326,0.24
-54.430315,0.208336,0.139999,-2.652618,0.32
-54.430206,0.217593,0.140464,-2.770477,0.4
-54.431755,0.242865,0.140924,-3.092254,0.48
-54.432695,0.268036,0.141311,-3.412742,0.56
-54.43418,0.27793,0.141695,-3.538721,0.64
-54.432718,0.31547,0.142153,-4.016682,0.72
-54.434226,0.349045,0.142802,-4.444176,0.8
-54.435148,0.375026,0.143186,-4.774985,0.88
-54.435261,0.420362,0.143844,-5.352212,0.96
-54.438686,0.471133,0.144601,-5.998652,1.04
-54.436578,0.491869,0.145002,-6.262676,1.12
-54.439612,0.538421,0.145705,-6.855385,1.2
-54.44072,0.577575,0.146227,-7.353913,1.28
-54.440407,0.60553,0.146525,-7.709842,1.36
-54.44221,0.649691,0.147205,-8.272118,1.44
-54.442237,0.689584,0.147692,-8.780056,1.52
-54.443446,0.727654,0.148296,-9.264772,1.6
-54.446352,0.7967,0.149003,-10.143893,1.68
-54.445262,0.834113,0.14957,-10.620261,1.76
-54.445308,0.880104,0.150025,-11.205836,1.84
-54.446965,0.903571,0.150496,-11.504619,1.92
-54.447247,0.952685,0.150969,-12.129961,2
-54.446502,0.973856,0.151381,-12.399525,2.08
-54.450363,1.039928,0.152004,-13.240777,2.16
-54.44876,1.064849,0.152209,-13.558077,2.24
-54.449568,1.112288,0.152817,-14.162094,2.32
-54.451258,1.154774,0.15323,-14.703045,2.4
-54.451657,1.187539,0.153717,-15.120217,2.48
-54.452334,1.238662,0.15411,-15.771134,2.56
-54.455086,1.292431,0.154814,-16.455747,2.64
-54.45351,1.325226,0.155185,-16.873299,2.72
-54.45505,1.385516,0.15584,-17.640937,2.8
-54.455881,1.429111,0.156232,-18.196003,2.88
-54.456281,1.46994,0.156594,-18.715857,2.96
-54.45827,1.516348,0.157145,-19.306744,3.04
-54.460051,1.539993,0.157403,-19.607804,3.12
-54.457703,1.589799,0.157805,-20.241949,3.2
-54.460637,1.668519,0.158539,-21.244241,3.28
-54.460877,1.701444,0.158906,-21.663463,3.36
-54.459746,1.734018,0.159287,-22.078207,3.44
-54.460796,1.772785,0.159698,-22.571802,3.52
-54.463294,1.850277,0.160334,-23.558461,3.6
-54.462658,1.870453,0.160633,-23.815352,3.68
-54.464384,1.927596,0.161057,-24.542919,3.76
-54.466409,1.962364,0.161339,-24.985591,3.84
-54.465973,2.013695,0.161877,-25.639164,3.92
-54.467749,2.067077,0.162353,-26.318844,4
-54.466441,2.111238,0.162758,-26.88112,4.08
-54.466655,2.156126,0.163228,-27.452655,4.16
-54.47086,2.212971,0.163759,-28.176428,4.24
-54.470134,2.253497,0.164144,-28.69241,4.32
-54.471392,2.305657,0.16455,-29.356533,4.4
-54.472818,2.366495,0.16516,-30.131152,4.48
-54.472268,2.387249,0.165318,-30.395404,4.56
-54.473254,2.453172,0.166007,-31.234759,4.64
-54.475234,2.508456,0.166411,-31.938648,4.72
-54.473708,2.527827,0.166682,-32.185293,4.8
-54.474639,2.580249,0.167169,-32.852755,4.88
-54.478304,2.619594,0.167424,-33.353711,4.96
-54.476034,2.678382,0.168004,-34.102224,5.04
-54.477283,2.720821,0.168418,-34.642568,5.12
-54.480076,2.800351,0.169086,-35.655181,5.2
-54.47989,2.842182,0.169517,-36.187784,5.28
-54.480952,2.893877,0.170027,-36.845987,5.36
-54.481416,2.946013,0.170404,-37.509805,5.44
-54.480489,2.995819,0.17091,-38.14395,5.52
-54.484849,3.028721,0.171204,-38.562869,5.6
-54.485499,3.078705,0.171701,-39.19929,5.68
-54.483092,3.114152,0.171973,-39.650614,5.76
-54.483469,3.163248,0.172466,-40.275728,5.84
-54.486993,3.219092,0.173022,-40.986751,5.92
-54.486562,3.255999,0.173487,-41.456668,6
-54.488814,3.314865,0.174007,-42.206167,6.08
-54.488169,3.339201,0.174327,-42.51603,6.16
-54.487588,3.372031,0.174801,-42.934038,6.24
-54.491099,3.419799,0.175271,-43.542228,6.32
-54.488465,3.442192,0.175727,-43.827351,6.4
-54.491399,3.512442,0.176713,-44.721802,6.48
-54.493906,3.530228,0.177129,-44.948261,6.56
-54.493393,3.570348,0.177886,-45.459083,6.64
-54.495073,3.576106,0.178291,-45.532394,6.72
-54.49624,3.604966,0.1787,-45.899858,6.8
-54.495246,3.629762,0.179661,-46.215564,6.88
-54.496985,3.634077,0.180124,-46.270509,6.96
-54.498207,3.664887,0.180854,-46.66279,7.04
-54.496794,3.663325,0.181391,-46.642906,7.12
-54.499588,3.698605,0.182037,-47.092105,7.2
-54.502372,3.713667,0.182866,-47.283882,7.28
-54.498634,3.710485,0.183353,-47.243356,7.36
-54.501109,3.741121,0.184133,-47.633436,7.44
-54.502336,3.750074,0.184568,-47.747424,7.52
-54.500982,3.775775,0.185389,-48.074666,7.6
-54.503925,3.791106,0.186369,-48.269858,7.68
-54.504729,3.787363,0.186786,-48.222198,7.76
-54.503539,3.804195,0.187319,-48.436514,7.84
-54.506619,3.835809,0.188114,-48.83904,7.92
-54.507277,3.841639,0.188926,-48.913261,8
-54.505919,3.859919,0.189471,-49.146019,8.08
-54.509071,3.881794,0.190427,-49.424539,8.16
-54.50888,3.888768,0.190805,-49.513331,8.24
-54.51121,3.917336,0.191701,-49.877077,8.32
-54.512341,3.924561,0.1925,-49.969057,8.4
-54.510307,3.935975,0.192825,-50.114388,8.48
-54.511596,3.949964,0.193782,-50.292504,8.56
-54.515975,3.98047,0.194465,-50.680914,8.64
-54.512478,3.972983,0.195026,-50.585595,8.72
-54.513999,4.004431,0.195758,-50.985996,8.8
-54.51647,4.011095,0.196512,-51.070842,8.88
-54.515698,4.002964,0.196682,-50.967327,8.96
-54.517406,4.05125,0.197589,-51.58212,9.04
-54.518863,4.057288,0.198345,-51.658997,9.12
-54.518682,4.070395,0.199013,-51.825882,9.2
-54.519754,4.086906,0.199756,-52.0361,9.28
-54.520122,4.084557,0.200127,-52.006199,9.36
-54.520617,4.125738,0.201062,-52.53053,9.44
-54.523392,4.13363,0.201713,-52.631009,9.52
-54.522997,4.161578,0.202728,-52.986862,9.6
-54.524695,4.170704,0.203453,-53.103051,9.68
-54.525531,4.187596,0.204129,-53.318126,9.76
-54.524704,4.201353,0.204732,-53.493283,9.84
-54.525967,4.208517,0.205471,-53.584504,9.92
-54.526912,4.221386,0.206004,-53.748352,10
-54.526812,4.220718,0.206398,-53.739852,10.08
-54.529046,4.257387,0.207241,-54.206734,10.16
-54.528451,4.275966,0.207808,-54.443286,10.24
-54.530813,4.276878,0.208575,-54.454897,10.32
-54.531336,4.301083,0.209235,-54.763091,10.4
-54.532548,4.315132,0.21008,-54.941966,10.48
-54.531395,4.325181,0.210679,-55.069918,10.56
-54.534878,4.357606,0.211519,-55.482765,10.64
-54.53387,4.363292,0.212184,-55.555165,10.72
-54.534251,4.374552,0.213073,-55.698523,10.8
-54.536522,4.392254,0.213595,-55.923919,10.88
-54.537049,4.40684,0.214189,-56.109625,10.96
-54.537953,4.416394,0.214878,-56.231278,11.04
-54.539438,4.459774,0.215701,-56.783612,11.12
-54.538366,4.445469,0.216406,-56.601474,11.2
-54.539475,4.475296,0.217245,-56.981233,11.28
-54.539343,4.458314,0.217447,-56.765019,11.36
-54.54517,4.586494,0.221306,-58.397055,11.44
-54.544752,4.534674,0.221627,-57.737259,11.52
-54.545906,4.501176,0.221649,-57.310751,11.6
-54.543176,4.487568,0.221669,-57.137492,11.68
-54.542881,4.482698,0.22172,-57.075489,11.76
-54.545306,4.473037,0.221644,-56.95247,11.84
-54.545161,4.476839,0.221918,-57.000888,11.92
-54.464066,0.075185,0.178852,-0.957289,0.03
-54.463171,0.073838,0.178969,-0.940138,0.11
-54.464079,0.084668,0.179204,-1.078032,0.19
-54.464742,0.091481,0.179247,-1.164775,0.27
-54.466418,0.102711,0.179549,-1.307754,0.35
-54.465923,0.104433,0.179755,-1.329686,0.43
-54.465564,0.130957,0.180282,-1.667401,0.51
-54.465746,0.138623,0.180595,-1.764997,0.59
-54.470111,0.163949,0.181072,-2.087458,0.67
-54.468653,0.171363,0.181346,-2.181866,0.75
-54.470506,0.204694,0.181961,-2.606248,0.83
-54.469716,0.226408,0.182528,-2.882719,0.91
-54.474021,0.268877,0.183103,-3.423443,0.99
-54.472736,0.315875,0.184069,-4.021843,1.07
-54.47572,0.344145,0.184457,-4.381794,1.15
-54.474821,0.363874,0.18492,-4.632993,1.23
-54.477228,0.408512,0.185462,-5.201341,1.31
-54.474848,0.451547,0.186266,-5.749274,1.39
-54.477532,0.480741,0.186602,-6.120988,1.47
-54.479031,0.547218,0.187422,-6.9674,1.55
-54.477105,0.569284,0.187812,-7.248349,1.63
-54.479826,0.619674,0.18839,-7.889931,1.71
-54.480117,0.640994,0.188638,-8.161393,1.79
-54.480948,0.710756,0.189562,-9.049621,1.87
-54.480907,0.740826,0.190052,-9.432491,1.95
-54.484427,0.779009,0.190473,-9.918649,2.03
-54.484136,0.838482,0.191228,-10.675889,2.11
-54.486312,0.854468,0.191346,-10.879429,2.19
-54.484572,0.927758,0.192184,-11.812584,2.27
-54.487275,0.957459,0.192527,-12.190749,2.35
-54.485644,0.999135,0.192925,-12.721379,2.43
-54.489101,1.037502,0.193391,-13.209889,2.51
-54.487988,1.081139,0.193966,-13.765487,2.59
-54.489046,1.140422,0.194453,-14.520299,2.67
-54.489369,1.160389,0.194827,-14.774534,2.75
-54.489514,1.214653,0.19533,-15.465446,2.83
-54.492298,1.274103,0.195957,-16.222382,2.91
-54.493374,1.313549,0.19631,-16.724629,2.99
-54.493538,1.358229,0.196777,-17.293508,3.07
-54.495073,1.399535,0.197205,-17.819432,3.15
-54.494914,1.447558,0.197559,-18.430886,3.23
-54.494969,1.505625,0.198145,-19.170216,3.31
-54.498511,1.524043,0.198294,-19.404719,3.39
-54.496717,1.596856,0.199005,-20.331804,3.47
-54.498829,1.625025,0.199288,-20.690464,3.55
-54.498956,1.675957,0.199833,-21.338953,3.63
-54.499147,1.726359,0.200201,-21.980687,3.71
-54.50145,1.781458,0.200762,-22.682223,3.79
-54.499847,1.80589,0.200991,-22.993301,3.87
-54.503103,1.876944,0.20158,-23.897997,3.95
-54.502585,1.909101,0.201864,-24.307429,4.03
-54.504216,1.951945,0.202275,-24.852933,4.11
-54.503112,2.002382,0.202612,-25.495123,4.19
-54.506051,2.066135,0.203227,-26.306853,4.27
-54.504384,2.109319,0.203535,-26.856683,4.35
-54.507041,2.177161,0.204286,-27.720475,4.43
-54.507404,2.216798,0.204542,-28.22515,4.51
-54.50938,2.275503,0.204944,-28.9726,4.59
-54.508549,2.322304,0.205402,-29.568496,4.67
-54.509634,2.383947,0.205797,-30.353361,4.75
-54.510783,2.431625,0.206226,-30.960413,4.83
-54.511737,2.45865,0.206561,-31.304502,4.91
-54.512664,2.541286,0.207078,-32.356655,4.99
-54.511551,2.584797,0.207557,-32.910659,5.07
-54.514794,2.62717,0.20799,-33.450168,5.15
-54.511365,2.671844,0.208168,-34.018971,5.23
-54.517151,2.723914,0.208617,-34.681955,5.31
-54.515552,2.765471,0.208935,-35.211067,5.39
-54.517079,2.830625,0.209474,-36.040632,5.47
-54.51741,2.870178,0.20976,-36.544244,5.55
-54.51939,2.916968,0.210205,-37.139988,5.63
-54.51964,2.972746,0.210749,-37.850176,5.71
-54.518968,3.002101,0.210784,-38.223939,5.79
-54.521716,3.107268,0.211808,-39.56296,5.87
-54.520862,3.134197,0.211932,-39.905836,5.95
-54.522515,3.203267,0.212496,-40.78526,6.03
-54.523514,3.248489,0.212847,-41.361045,6.11
-54.525885,3.312331,0.213438,-42.173914,6.19
-54.525645,3.367138,0.213973,-42.871731,6.27
-54.524509,3.39883,0.213977,-43.275244,6.35
-54.526998,3.46933,0.214689,-44.172882,6.43
-54.526862,3.50104,0.214849,-44.576622,6.51
-54.528501,3.554589,0.215319,-45.258427,6.59
-54.528969,3.590423,0.215629,-45.714684,6.67
-54.529251,3.663325,0.216196,-46.642906,6.75
-54.529687,3.70152,0.216571,-47.129216,6.83
-54.533348,3.765666,0.217097,-47.945955,6.91
-54.531649,3.816479,0.217495,-48.592926,6.99
-54.533261,3.868997,0.217821,-49.261601,7.07
-54.533774,3.913152,0.218268,-49.823801,7.15
-54.53387,3.9702,0.218799,-50.550154,7.23
-54.534465,4.033363,0.219207,-51.354371,7.31
-54.536168,4.083437,0.219534,-51.991931,7.39
-54.537017,4.134637,0.220058,-52.643835,7.47
-54.538098,4.171121,0.220333,-53.108364,7.55
-54.539102,4.230285,0.220931,-53.861658,7.63
-54.540342,4.244757,0.221121,-54.045921,7.71
-54.541714,4.317194,0.221709,-54.968224,7.79
-54.540542,4.37007,0.222338,-55.641453,7.87
-54.543562,4.419488,0.22285,-56.270665,7.95
-54.543008,4.440308,0.223203,-56.535752,8.03
-54.545252,4.47073,0.223608,-56.9231,8.11
-54.545016,4.519898,0.224333,-57.549125,8.19
-54.544571,4.540855,0.224621,-57.815958,8.27
-54.546378,4.587048,0.225601,-58.404113,8.35
-54.547845,4.592937,0.225725,-58.479093,8.43
-54.549308,4.639339,0.226455,-59.069904,8.51
-54.546696,4.668325,0.227157,-59.438962,8.59
-54.548713,4.667467,0.227769,-59.428034,8.67
-54.5481,4.684842,0.22831,-59.649256,8.75
-54.551342,4.711789,0.228712,-59.992359,8.83
-54.551406,4.7337,0.229775,-60.271335,8.91
-54.552405,4.730999,0.230266,-60.236956,8.99
-54.553414,4.769397,0.230868,-60.725846,9.07
-54.554781,4.771835,0.231529,-60.756885,9.15
-54.552596,4.783267,0.232194,-60.902444,9.23
-54.555448,4.817402,0.23336,-61.337072,9.31
-54.556425,4.806376,0.233815,-61.196674,9.39
-54.556575,4.855847,0.234545,-61.826569,9.47
-54.55945,4.860294,0.235594,-61.883183,9.55
-54.5586,4.863662,0.236027,-61.926062,9.63
-54.560899,4.891723,0.236837,-62.283357,9.71
-54.562302,4.914349,0.237818,-62.571439,9.79
-54.562061,4.904568,0.238156,-62.446902,9.87
-54.561762,4.922718,0.238979,-62.67799,9.95
-54.560567,4.945099,0.239601,-62.96296,10.03
-54.564537,4.9591,0.240139,-63.141228,10.11
-54.56351,4.973048,0.240998,-63.318813,10.19
-54.565495,4.985213,0.241774,-63.473707,10.27
-54.563151,4.974037,0.242067,-63.331411,10.35
-54.569074,5.01644,0.242935,-63.8713,10.43
-54.565699,5.027711,0.243789,-64.01481,10.51
-54.568879,5.048954,0.244391,-64.285285,10.59
-54.568538,5.053306,0.245452,-64.340686,10.67
-54.569269,5.04626,0.245561,-64.250982,10.75
-54.570437,5.082148,0.246373,-64.707922,10.83
-54.570814,5.080926,0.246841,-64.692364,10.91
-54.572653,5.114317,0.24754,-65.117506,10.99
-54.572067,5.116725,0.248417,-65.148166,11.07
-54.574724,5.143756,0.249018,-65.492331,11.15
-54.573748,5.138963,0.24969,-65.431315,11.23
-54.576486,5.163133,0.250168,-65.739053,11.31
-54.575946,5.179894,0.250966,-65.952458,11.39
-54.578112,5.178124,0.251384,-65.929919,11.47
-54.579811,5.206406,0.252162,-66.290022,11.55
-54.579489,5.206257,0.252819,-66.288124,11.63
-54.581115,5.235821,0.253515,-66.664544,11.71
-54.580442,5.226833,0.254106,-66.5501,11.79
-54.581759,5.275851,0.255052,-67.174227,11.87
-54.582046,5.26374,0.255591,-67.020017,11.95
-54.582827,5.288875,0.256157,-67.340049,12.03
-54.584971,5.299646,0.256833,-67.477184,12.11
-54.585652,5.3271,0.257754,-67.826738,12.19
-54.584884,5.323219,0.258323,-67.777333,12.27
-54.58488,5.346721,0.259005,-68.076571,12.35
-54.58691,5.364656,0.259807,-68.304927,12.43
-54.587069,5.374205,0.260438,-68.426505,12.51
-54.589067,5.402201,0.2613,-68.782965,12.59
-54.587818,5.400163,0.261916,-68.75701,12.67
-54.592587,5.425143,0.262795,-69.075069,12.75
-54.589394,5.423421,0.263274,-69.053137,12.83
-54.59385,5.454803,0.263989,-69.452703,12.91
-54.593323,5.46211,0.26475,-69.545745,12.99
-54.592542,5.460429,0.265123,-69.524344,13.07
-54.595817,5.547053,0.266666,-70.627268,13.15
-54.592474,5.489999,0.267282,-69.900839,13.23
-54.596911,5.481172,0.267563,-69.788444,13.31
-54.594327,5.454648,0.267597,-69.45073,13.39
-54.596062,5.452091,0.26766,-69.418172,13.47
-54.595976,5.442572,0.26779,-69.296974,13.55
-54.595917,5.437428,0.267781,-69.23148,13.63
-54.596026,5.432278,0.267891,-69.165911,13.71
-54.5936,5.424726,0.2678,-69.069757,13.79
-54.59439,5.314142,0.269111,-67.661751,0.03
-54.594331,5.270046,0.268828,-67.10031,0.11
-54.591002,5.224025,0.268605,-66.514355,0.19
-54.59206,5.209219,0.268605,-66.325842,0.27
-54.589653,5.162787,0.268282,-65.734651,0.35
-54.589794,5.129063,0.26813,-65.30526,0.43
-54.590407,5.09758,0.267893,-64.904404,0.51
-54.588522,5.054796,0.267548,-64.359658,0.59
-54.587905,5.031526,0.267509,-64.06338,0.67
-54.58602,4.994369,0.267281,-63.590275,0.75
-54.586697,4.950488,0.267038,-63.031566,0.83
-54.586429,4.92624,0.26691,-62.722841,0.91
-54.583376,4.879272,0.266541,-62.12482,0.99
-54.582604,4.82915,0.266365,-61.486653,1.07
-54.584734,4.750395,0.265913,-60.483905,1.15
-54.583254,4.602998,0.264945,-58.607197,1.23
-54.5818,4.530472,0.26455,-57.683756,1.31
-54.581859,4.451466,0.264161,-56.67782,1.39
-54.580006,4.3733,0.263514,-55.682586,1.47
-54.580465,4.304683,0.263092,-54.808929,1.55
-54.577604,4.280424,0.263008,-54.500053,1.63
-54.577109,4.199737,0.262641,-53.472716,1.71
-54.57586,4.128784,0.26224,-52.56931,1.79
-54.575814,4.077733,0.261796,-51.919304,1.87
-54.576523,4.002011,0.261244,-50.955184,1.95
-54.574515,3.951591,0.260976,-50.313222,2.03
-54.574302,3.910565,0.260757,-49.790865,2.11
-54.572948,3.854883,0.260426,-49.081891,2.19
-54.572771,3.805047,0.26007,-48.447367,2.27
-54.571536,3.747511,0.25957,-47.714791,2.35
-54.569092,3.690696,0.259401,-46.991398,2.43
-54.569265,3.630018,0.25896,-46.218828,2.51
-54.566767,3.569829,0.258523,-45.45248,2.59
-54.568742,3.514194,0.258192,-44.744114,2.67
-54.566185,3.466684,0.257847,-44.139187,2.75
-54.566889,3.406805,0.257432,-43.376786,2.83
-54.567121,3.341073,0.257028,-42.53986,2.91
-54.5649,3.280222,0.256463,-41.765089,2.99
-54.563274,3.23593,0.256344,-41.201143,3.07
-54.564855,3.189391,0.256032,-40.608586,3.15
-54.562829,3.12317,0.255477,-39.765437,3.23
-54.559949,3.057259,0.25505,-38.926235,3.31
-54.561448,3.023261,0.254768,-38.493352,3.39
-54.557519,2.929956,0.253985,-37.305355,3.47
-54.559159,2.898717,0.253835,-36.90761,3.55
-54.556638,2.83637,0.253447,-36.11379,3.63
-54.55806,2.769226,0.252958,-35.258878,3.71
-54.558287,2.718568,0.252573,-34.613881,3.79
-54.556825,2.671391,0.252253,-34.013204,3.87
-54.553959,2.603233,0.251735,-33.14539,3.95
-54.555053,2.554566,0.251324,-32.52574,4.03
-54.554118,2.504623,0.250991,-31.88985,4.11
-54.55345,2.437603,0.250479,-31.036531,4.19
-54.552233,2.39265,0.250131,-30.464162,4.27
-54.549158,2.355915,0.249774,-29.996445,4.35
-54.549994,2.269322,0.249164,-28.893901,4.43
-54.550075,2.265781,0.249215,-28.848822,4.51
-54.5478,2.179307,0.248549,-27.747795,4.59
-54.548667,2.143854,0.248067,-27.296396,4.67
-54.548885,2.100664,0.247847,-26.74649,4.75
-54.54581,2.032226,0.247254,-25.875109,4.83
-54.546751,1.979667,0.246877,-25.205902,4.91
-54.545297,1.939088,0.246682,-24.689237,4.99
-54.543758,1.895589,0.246154,-24.135384,5.07
-54.544961,1.847237,0.245754,-23.519756,5.15
-54.541359,1.788425,0.245207,-22.77094,5.23
-54.541196,1.730567,0.244802,-22.034266,5.31
-54.541836,1.703829,0.244497,-21.693819,5.39
-54.539075,1.644564,0.24408,-20.939235,5.47
-54.539597,1.5885,0.243423,-20.225404,5.55
-54.539584,1.55794,0.243202,-19.836311,5.63
-54.537562,1.49402,0.242568,-19.022456,5.71
-54.53778,1.446897,0.242076,-18.422462,5.79
-54.535387,1.393563,0.24164,-17.74339,5.87
-54.53268,1.364881,0.241364,-17.378202,5.95
-54.534987,1.305491,0.240691,-16.622024,6.03
-54.533952,1.264644,0.240336,-16.101943,6.11
-54.531526,1.218289,0.239817,-15.511739,6.19
-54.53293,1.183492,0.239446,-15.068687,6.27
-54.530159,1.148772,0.239063,-14.626622,6.35
-54.530277,1.098293,0.23842,-13.983902,6.43
-54.527743,1.062596,0.238125,-13.52939,6.51
-54.526662,1.017958,0.237665,-12.961043,6.59
-54.526685,0.967312,0.237057,-12.316197,6.67
-54.527834,0.925785,0.236459,-11.787465,6.75
-54.525676,0.888795,0.236184,-11.316485,6.83
-54.525476,0.853068,0.235719,-10.861594,6.91
-54.524023,0.807905,0.23501,-10.286568,6.99
-54.523546,0.76527,0.234652,-9.74372,7.07
-54.522874,0.721037,0.234009,-9.180533,7.15
-54.523424,0.700742,0.233667,-8.922124,7.23
-54.522629,0.663006,0.233351,-8.441658,7.31
-54.520971,0.597572,0.232382,-7.608527,7.39
-54.520113,0.573695,0.232022,-7.304508,7.47
-54.518346,0.532568,0.231398,-6.78086,7.55
-54.518677,0.484782,0.230658,-6.172442,7.63
-54.518169,0.46159,0.230185,-5.87715,7.71
-54.516565,0.432444,0.229783,-5.506043,7.79
-54.516343,0.397718,0.229179,-5.063902,7.87
-54.516234,0.369847,0.228807,-4.709036,7.95
-54.512341,0.327796,0.2281,-4.173625,8.03
-54.512959,0.309199,0.227596,-3.936845,8.11
-54.512732,0.287044,0.227161,-3.654758,8.19
-54.511138,0.240314,0.226113,-3.059773,8.27
-54.512328,0.225157,0.22589,-2.866782,8.35
-54.511824,0.206065,0.225359,-2.623703,8.43
-54.507191,0.176764,0.224722,-2.250623,8.51
-54.509875,0.162166,0.224343,-2.064766,8.59
-54.506314,0.132412,0.223563,-1.685918,8.67
-54.507672,0.115615,0.222988,-1.472058,8.75
-54.507041,0.101894,0.222334,-1.297356,8.83
-54.50581,0.089312,0.222016,-1.137151,8.91
-54.505011,0.079876,0.221573,-1.017015,8.99
-54.505374,0.066471,0.220888,-0.846336,9.07
-54.503317,0.04313,0.220008,-0.549147,9.15
-54.502136,0.025105,0.218897,-0.319653,9.23
-54.502799,0.026774,0.2184,-0.340902,9.31
-54.501105,0.01381,0.217604,-0.175839,9.39
-54.498643,0.003111,0.216815,-0.039615,9.47